Workbook

Sheet Сводный бюджет СПб 2
A1: ПланФакт | B1: Создано с помощью сервиса ПланФакт | I1: =HYPERLINK("https://app.planfact.io/?from=Pf_BDR", "Перейти в сервис")
B2: Итого | C2: июнь` 26 | D2: июль` 26 | E2: август` 26 | F2: сентябрь` 26 | G2: октябрь` 26 | H2: ноябрь` 26 | I2: декабрь` 26
A3: Сводный бюджет СПб 2 | B3: план | C3: план | D3: план | E3: план | F3: план | G3: план | H3: план | I3: план
A4: Выручка | B4: =SUM(B5,B6) | C4: =SUM(C5,C6) | D4: =SUM(D5,D6) | E4: =SUM(E5,E6) | F4: =SUM(F5,F6) | G4: =SUM(G5,G6) | H4: - | I4: =SUM(I5,I6)
A5: Нераспределенный доход | B5: =SUM(C5,D5,E5,F5) | C5: =SUM('Астрид'!C5,'Курортный'!C5,'Новое Колпино'!C5,'Таллинский парк'!C5) | D5: =SUM('Астрид'!D5,'Курортный'!D5,'Новое Колпино'!D5,'Таллинский парк'!D5) | E5: =SUM('Астрид'!E5,'Курортный'!E5,'Новое Колпино'!E5,'Таллинский парк'!E5) | F5: =SUM('Астрид'!F5,'Курортный'!F5,'Новое Колпино'!F5,'Таллинский парк'!F5) | G5: =SUM('Астрид'!G5,'Курортный'!G5,'Новое Колпино'!G5,'Таллинский парк'!G5) | H5: - | I5: =SUM('Астрид'!I5,'Курортный'!I5,'Новое Колпино'!I5,'Таллинский парк'!I5)
A6: Выручка | B6: =SUM(B7,B8,B9) | C6: =SUM(C7,C8,C9) | D6: =SUM(D7,D8,D9) | E6: =SUM(E7,E8,E9) | F6: =SUM(F7,F8,F9) | G6: =SUM(G7,G8,G9) | H6: - | I6: =SUM(I7,I8,I9)
A7: Реализация услуг Клининг (ОД) | B7: =SUM(C7,D7,E7,F7) | C7: =SUM('Астрид'!C7,'Курортный'!C7,'Новое Колпино'!C7,'Таллинский парк'!C7) | D7: =SUM('Астрид'!D7,'Курортный'!D7,'Новое Колпино'!D7,'Таллинский парк'!D7) | E7: =SUM('Астрид'!E7,'Курортный'!E7,'Новое Колпино'!E7,'Таллинский парк'!E7) | F7: =SUM('Астрид'!F7,'Курортный'!F7,'Новое Колпино'!F7,'Таллинский парк'!F7) | G7: =SUM('Астрид'!G7,'Курортный'!G7,'Новое Колпино'!G7,'Таллинский парк'!G7) | H7: - | I7: =SUM('Астрид'!I7,'Курортный'!I7,'Новое Колпино'!I7,'Таллинский парк'!I7)
A8: Реализация услуг Клининг (Доп.услуги) | B8: =SUM(C8,D8,E8,F8) | C8: =SUM('Астрид'!C8,'Курортный'!C8,'Новое Колпино'!C8,'Таллинский парк'!C8) | D8: =SUM('Астрид'!D8,'Курортный'!D8,'Новое Колпино'!D8,'Таллинский парк'!D8) | E8: =SUM('Астрид'!E8,'Курортный'!E8,'Новое Колпино'!E8,'Таллинский парк'!E8) | F8: =SUM('Астрид'!F8,'Курортный'!F8,'Новое Колпино'!F8,'Таллинский парк'!F8) | G8: =SUM('Астрид'!G8,'Курортный'!G8,'Новое Колпино'!G8,'Таллинский парк'!G8) | H8: - | I8: =SUM('Астрид'!I8,'Курортный'!I8,'Новое Колпино'!I8,'Таллинский парк'!I8)
A9: Реализация услуг Клининг (снег) | B9: =SUM(C9,D9,E9,F9) | C9: =SUM('Астрид'!C9,'Курортный'!C9,'Новое Колпино'!C9,'Таллинский парк'!C9) | D9: =SUM('Астрид'!D9,'Курортный'!D9,'Новое Колпино'!D9,'Таллинский парк'!D9) | E9: =SUM('Астрид'!E9,'Курортный'!E9,'Новое Колпино'!E9,'Таллинский парк'!E9) | F9: =SUM('Астрид'!F9,'Курортный'!F9,'Новое Колпино'!F9,'Таллинский парк'!F9) | G9: =SUM('Астрид'!G9,'Курортный'!G9,'Новое Колпино'!G9,'Таллинский парк'!G9) | H9: - | I9: =SUM('Астрид'!I9,'Курортный'!I9,'Новое Колпино'!I9,'Таллинский парк'!I9)
A10: Прямые расходы | B10: =SUM(B11,B12,B13,B21,B22,B23,B24,B25,B26,B27,B28,B29,B30,B31,B32,B33,B34) | C10: =SUM(C11,C12,C13,C21,C22,C23,C24,C25,C26,C27,C28,C29,C30,C31,C32,C33,C34) | D10: =SUM(D11,D12,D13,D21,D22,D23,D24,D25,D26,D27,D28,D29,D30,D31,D32,D33,D34) | E10: =SUM(E11,E12,E13,E21,E22,E23,E24,E25,E26,E27,E28,E29,E30,E31,E32,E33,E34) | F10: =SUM(F11,F12,F13,F21,F22,F23,F24,F25,F26,F27,F28,F29,F30,F31,F32,F33,F34) | G10: =SUM(G11,G12,G13,G21,G22,G23,G24,G25,G26,G27,G28,G29,G30,G31,G32,G33,G34) | H10: - | I10: =SUM(I11,I12,I13,I21,I22,I23,I24,I25,I26,I27,I28,I29,I30,I31,I32,I33,I34)
A11: Нераспределенный расход | B11: =SUM(C11,D11,E11,F11) | C11: =SUM('Астрид'!C11,'Курортный'!C11,'Новое Колпино'!C11,'Таллинский парк'!C11) | D11: =SUM('Астрид'!D11,'Курортный'!D11,'Новое Колпино'!D11,'Таллинский парк'!D11) | E11: =SUM('Астрид'!E11,'Курортный'!E11,'Новое Колпино'!E11,'Таллинский парк'!E11) | F11: =SUM('Астрид'!F11,'Курортный'!F11,'Новое Колпино'!F11,'Таллинский парк'!F11) | G11: =SUM('Астрид'!G11,'Курортный'!G11,'Новое Колпино'!G11,'Таллинский парк'!G11) | H11: - | I11: =SUM('Астрид'!I11,'Курортный'!I11,'Новое Колпино'!I11,'Таллинский парк'!I11)
A12: Транспортные расходы | B12: =SUM(C12,D12,E12,F12) | C12: =SUM('Астрид'!C12,'Курортный'!C12,'Новое Колпино'!C12,'Таллинский парк'!C12) | D12: =SUM('Астрид'!D12,'Курортный'!D12,'Новое Колпино'!D12,'Таллинский парк'!D12) | E12: =SUM('Астрид'!E12,'Курортный'!E12,'Новое Колпино'!E12,'Таллинский парк'!E12) | F12: =SUM('Астрид'!F12,'Курортный'!F12,'Новое Колпино'!F12,'Таллинский парк'!F12) | G12: =SUM('Астрид'!G12,'Курортный'!G12,'Новое Колпино'!G12,'Таллинский парк'!G12) | H12: - | I12: =SUM('Астрид'!I12,'Курортный'!I12,'Новое Колпино'!I12,'Таллинский парк'!I12)
A13: Переменные | B13: =SUM(B14,B15,B16,B17,B18,B19,B20) | C13: =SUM(C14,C15,C16,C17,C18,C19,C20) | D13: =SUM(D14,D15,D16,D17,D18,D19,D20) | E13: =SUM(E14,E15,E16,E17,E18,E19,E20) | F13: =SUM(F14,F15,F16,F17,F18,F19,F20) | G13: =SUM(G14,G15,G16,G17,G18,G19,G20) | H13: - | I13: =SUM(I14,I15,I16,I17,I18,I19,I20)
A14: Услуги техниги для уборки снега (ПТ) | B14: =SUM(C14,D14,E14,F14) | C14: =SUM('Астрид'!C14,'Курортный'!C14,'Новое Колпино'!C14,'Таллинский парк'!C14) | D14: =SUM('Астрид'!D14,'Курортный'!D14,'Новое Колпино'!D14,'Таллинский парк'!D14) | E14: =SUM('Астрид'!E14,'Курортный'!E14,'Новое Колпино'!E14,'Таллинский парк'!E14) | F14: =SUM('Астрид'!F14,'Курортный'!F14,'Новое Колпино'!F14,'Таллинский парк'!F14) | G14: =SUM('Астрид'!G14,'Курортный'!G14,'Новое Колпино'!G14,'Таллинский парк'!G14) | H14: - | I14: =SUM('Астрид'!I14,'Курортный'!I14,'Новое Колпино'!I14,'Таллинский парк'!I14)
A15: Услуги садовника (ПТ) | B15: =SUM(C15,D15,E15,F15) | C15: =SUM('Астрид'!C15,'Курортный'!C15,'Новое Колпино'!C15,'Таллинский парк'!C15) | D15: =SUM('Астрид'!D15,'Курортный'!D15,'Новое Колпино'!D15,'Таллинский парк'!D15) | E15: =SUM('Астрид'!E15,'Курортный'!E15,'Новое Колпино'!E15,'Таллинский парк'!E15) | F15: =SUM('Астрид'!F15,'Курортный'!F15,'Новое Колпино'!F15,'Таллинский парк'!F15) | G15: =SUM('Астрид'!G15,'Курортный'!G15,'Новое Колпино'!G15,'Таллинский парк'!G15) | H15: - | I15: =SUM('Астрид'!I15,'Курортный'!I15,'Новое Колпино'!I15,'Таллинский парк'!I15)
A16: Сыпучие материалы (ПТ) | B16: =SUM(C16,D16,E16,F16) | C16: =SUM('Астрид'!C16,'Курортный'!C16,'Новое Колпино'!C16,'Таллинский парк'!C16) | D16: =SUM('Астрид'!D16,'Курортный'!D16,'Новое Колпино'!D16,'Таллинский парк'!D16) | E16: =SUM('Астрид'!E16,'Курортный'!E16,'Новое Колпино'!E16,'Таллинский парк'!E16) | F16: =SUM('Астрид'!F16,'Курортный'!F16,'Новое Колпино'!F16,'Таллинский парк'!F16) | G16: =SUM('Астрид'!G16,'Курортный'!G16,'Новое Колпино'!G16,'Таллинский парк'!G16) | H16: - | I16: =SUM('Астрид'!I16,'Курортный'!I16,'Новое Колпино'!I16,'Таллинский парк'!I16)
A17: Расходные материалы и инстументы (МОП) | B17: =SUM(C17,D17,E17,F17) | C17: =SUM('Астрид'!C17,'Курортный'!C17,'Новое Колпино'!C17,'Таллинский парк'!C17) | D17: =SUM('Астрид'!D17,'Курортный'!D17,'Новое Колпино'!D17,'Таллинский парк'!D17) | E17: =SUM('Астрид'!E17,'Курортный'!E17,'Новое Колпино'!E17,'Таллинский парк'!E17) | F17: =SUM('Астрид'!F17,'Курортный'!F17,'Новое Колпино'!F17,'Таллинский парк'!F17) | G17: =SUM('Астрид'!G17,'Курортный'!G17,'Новое Колпино'!G17,'Таллинский парк'!G17) | H17: - | I17: =SUM('Астрид'!I17,'Курортный'!I17,'Новое Колпино'!I17,'Таллинский парк'!I17)
A18: Расходные материалы и инстументы (ПТ) | B18: =SUM(C18,D18,E18,F18) | C18: =SUM('Астрид'!C18,'Курортный'!C18,'Новое Колпино'!C18,'Таллинский парк'!C18) | D18: =SUM('Астрид'!D18,'Курортный'!D18,'Новое Колпино'!D18,'Таллинский парк'!D18) | E18: =SUM('Астрид'!E18,'Курортный'!E18,'Новое Колпино'!E18,'Таллинский парк'!E18) | F18: =SUM('Астрид'!F18,'Курортный'!F18,'Новое Колпино'!F18,'Таллинский парк'!F18) | G18: =SUM('Астрид'!G18,'Курортный'!G18,'Новое Колпино'!G18,'Таллинский парк'!G18) | H18: - | I18: =SUM('Астрид'!I18,'Курортный'!I18,'Новое Колпино'!I18,'Таллинский парк'!I18)
A19: Арена оборудования (ПТ) | B19: =SUM(C19,D19,E19,F19) | C19: =SUM('Астрид'!C19,'Курортный'!C19,'Новое Колпино'!C19,'Таллинский парк'!C19) | D19: =SUM('Астрид'!D19,'Курортный'!D19,'Новое Колпино'!D19,'Таллинский парк'!D19) | E19: =SUM('Астрид'!E19,'Курортный'!E19,'Новое Колпино'!E19,'Таллинский парк'!E19) | F19: =SUM('Астрид'!F19,'Курортный'!F19,'Новое Колпино'!F19,'Таллинский парк'!F19) | G19: =SUM('Астрид'!G19,'Курортный'!G19,'Новое Колпино'!G19,'Таллинский парк'!G19) | H19: - | I19: =SUM('Астрид'!I19,'Курортный'!I19,'Новое Колпино'!I19,'Таллинский парк'!I19)
A20: Арена оборудования (МОП) | B20: =SUM(C20,D20,E20,F20) | C20: =SUM('Астрид'!C20,'Курортный'!C20,'Новое Колпино'!C20,'Таллинский парк'!C20) | D20: =SUM('Астрид'!D20,'Курортный'!D20,'Новое Колпино'!D20,'Таллинский парк'!D20) | E20: =SUM('Астрид'!E20,'Курортный'!E20,'Новое Колпино'!E20,'Таллинский парк'!E20) | F20: =SUM('Астрид'!F20,'Курортный'!F20,'Новое Колпино'!F20,'Таллинский парк'!F20) | G20: =SUM('Астрид'!G20,'Курортный'!G20,'Новое Колпино'!G20,'Таллинский парк'!G20) | H20: - | I20: =SUM('Астрид'!I20,'Курортный'!I20,'Новое Колпино'!I20,'Таллинский парк'!I20)
A21: Заработная плата (МОП) | B21: =SUM(C21,D21,E21,F21) | C21: =SUM('Астрид'!C21,'Курортный'!C21,'Новое Колпино'!C21,'Таллинский парк'!C21) | D21: =SUM('Астрид'!D21,'Курортный'!D21,'Новое Колпино'!D21,'Таллинский парк'!D21) | E21: =SUM('Астрид'!E21,'Курортный'!E21,'Новое Колпино'!E21,'Таллинский парк'!E21) | F21: =SUM('Астрид'!F21,'Курортный'!F21,'Новое Колпино'!F21,'Таллинский парк'!F21) | G21: =SUM('Астрид'!G21,'Курортный'!G21,'Новое Колпино'!G21,'Таллинский парк'!G21) | H21: - | I21: =SUM('Астрид'!I21,'Курортный'!I21,'Новое Колпино'!I21,'Таллинский парк'!I21)
A22: Заработная плата (ПТ) | B22: =SUM(C22,D22,E22,F22) | C22: =SUM('Астрид'!C22,'Курортный'!C22,'Новое Колпино'!C22,'Таллинский парк'!C22) | D22: =SUM('Астрид'!D22,'Курортный'!D22,'Новое Колпино'!D22,'Таллинский парк'!D22) | E22: =SUM('Астрид'!E22,'Курортный'!E22,'Новое Колпино'!E22,'Таллинский парк'!E22) | F22: =SUM('Астрид'!F22,'Курортный'!F22,'Новое Колпино'!F22,'Таллинский парк'!F22) | G22: =SUM('Астрид'!G22,'Курортный'!G22,'Новое Колпино'!G22,'Таллинский парк'!G22) | H22: - | I22: =SUM('Астрид'!I22,'Курортный'!I22,'Новое Колпино'!I22,'Таллинский парк'!I22)
A23: Налоги с ФОТ (МОП) | B23: =SUM(C23,D23,E23,F23) | C23: =SUM('Астрид'!C23,'Курортный'!C23,'Новое Колпино'!C23,'Таллинский парк'!C23) | D23: =SUM('Астрид'!D23,'Курортный'!D23,'Новое Колпино'!D23,'Таллинский парк'!D23) | E23: =SUM('Астрид'!E23,'Курортный'!E23,'Новое Колпино'!E23,'Таллинский парк'!E23) | F23: =SUM('Астрид'!F23,'Курортный'!F23,'Новое Колпино'!F23,'Таллинский парк'!F23) | G23: =SUM('Астрид'!G23,'Курортный'!G23,'Новое Колпино'!G23,'Таллинский парк'!G23) | H23: - | I23: =SUM('Астрид'!I23,'Курортный'!I23,'Новое Колпино'!I23,'Таллинский парк'!I23)
A24: Налоги с ФОТ (ПТ) | B24: =SUM(C24,D24,E24,F24) | C24: =SUM('Астрид'!C24,'Курортный'!C24,'Новое Колпино'!C24,'Таллинский парк'!C24) | D24: =SUM('Астрид'!D24,'Курортный'!D24,'Новое Колпино'!D24,'Таллинский парк'!D24) | E24: =SUM('Астрид'!E24,'Курортный'!E24,'Новое Колпино'!E24,'Таллинский парк'!E24) | F24: =SUM('Астрид'!F24,'Курортный'!F24,'Новое Колпино'!F24,'Таллинский парк'!F24) | G24: =SUM('Астрид'!G24,'Курортный'!G24,'Новое Колпино'!G24,'Таллинский парк'!G24) | H24: - | I24: =SUM('Астрид'!I24,'Курортный'!I24,'Новое Колпино'!I24,'Таллинский парк'!I24)
A25: Премми (МОП) | B25: =SUM(C25,D25,E25,F25) | C25: =SUM('Астрид'!C25,'Курортный'!C25,'Новое Колпино'!C25,'Таллинский парк'!C25) | D25: =SUM('Астрид'!D25,'Курортный'!D25,'Новое Колпино'!D25,'Таллинский парк'!D25) | E25: =SUM('Астрид'!E25,'Курортный'!E25,'Новое Колпино'!E25,'Таллинский парк'!E25) | F25: =SUM('Астрид'!F25,'Курортный'!F25,'Новое Колпино'!F25,'Таллинский парк'!F25) | G25: =SUM('Астрид'!G25,'Курортный'!G25,'Новое Колпино'!G25,'Таллинский парк'!G25) | H25: - | I25: =SUM('Астрид'!I25,'Курортный'!I25,'Новое Колпино'!I25,'Таллинский парк'!I25)
... A33: Расходы к удержанию | B33: =SUM(C33,D33,E33,F33) | C33: =SUM('Астрид'!C33,'Курортный'!C33,'Новое Колпино'!C33,'Таллинский парк'!C33) | D33: =SUM('Астрид'!D33,'Курортный'!D33,'Новое Колпино'!D33,'Таллинский парк'!D33) | E33: =SUM('Астрид'!E33,'Курортный'!E33,'Новое Колпино'!E33,'Таллинский парк'!E33) | F33: =SUM('Астрид'!F33,'Курортный'!F33,'Новое Колпино'!F33,'Таллинский парк'!F33) | G33: =SUM('Астрид'!G33,'Курортный'!G33,'Новое Колпино'!G33,'Таллинский парк'!G33) | H33: - | I33: =SUM('Астрид'!I33,'Курортный'!I33,'Новое Колпино'!I33,'Таллинский парк'!I33)
A34: Общехозяйственные | B34: =SUM(B35,B36,B37,B38,B39,B40,B41,B42) | C34: =SUM(C35,C36,C37,C38,C39,C40,C41,C42) | D34: =SUM(D35,D36,D37,D38,D39,D40,D41,D42) | E34: =SUM(E35,E36,E37,E38,E39,E40,E41,E42) | F34: =SUM(F35,F36,F37,F38,F39,F40,F41,F42) | G34: =SUM(G35,G36,G37,G38,G39,G40,G41,G42) | H34: - | I34: =SUM(I35,I36,I37,I38,I39,I40,I41,I42)
A35: Аутсорс (направления) | B35: =SUM(C35,D35,E35,F35) | C35: =SUM('Астрид'!C35,'Курортный'!C35,'Новое Колпино'!C35,'Таллинский парк'!C35) | D35: =SUM('Астрид'!D35,'Курортный'!D35,'Новое Колпино'!D35,'Таллинский парк'!D35) | E35: =SUM('Астрид'!E35,'Курортный'!E35,'Новое Колпино'!E35,'Таллинский парк'!E35) | F35: =SUM('Астрид'!F35,'Курортный'!F35,'Новое Колпино'!F35,'Таллинский парк'!F35) | G35: =SUM('Астрид'!G35,'Курортный'!G35,'Новое Колпино'!G35,'Таллинский парк'!G35) | H35: - | I35: =SUM('Астрид'!I35,'Курортный'!I35,'Новое Колпино'!I35,'Таллинский парк'!I35)
A36: Заработная плата МО АУП | B36: =SUM(C36,D36,E36,F36) | C36: =SUM('Астрид'!C36,'Курортный'!C36,'Новое Колпино'!C36,'Таллинский парк'!C36) | D36: =SUM('Астрид'!D36,'Курортный'!D36,'Новое Колпино'!D36,'Таллинский парк'!D36) | E36: =SUM('Астрид'!E36,'Курортный'!E36,'Новое Колпино'!E36,'Таллинский парк'!E36) | F36: =SUM('Астрид'!F36,'Курортный'!F36,'Новое Колпино'!F36,'Таллинский парк'!F36) | G36: =SUM('Астрид'!G36,'Курортный'!G36,'Новое Колпино'!G36,'Таллинский парк'!G36) | H36: - | I36: =SUM('Астрид'!I36,'Курортный'!I36,'Новое Колпино'!I36,'Таллинский парк'!I36)
A37: Инструменты: ГСМ | B37: =SUM(C37,D37,E37,F37) | C37: =SUM('Астрид'!C37,'Курортный'!C37,'Новое Колпино'!C37,'Таллинский парк'!C37) | D37: =SUM('Астрид'!D37,'Курортный'!D37,'Новое Колпино'!D37,'Таллинский парк'!D37) | E37: =SUM('Астрид'!E37,'Курортный'!E37,'Новое Колпино'!E37,'Таллинский парк'!E37) | F37: =SUM('Астрид'!F37,'Курортный'!F37,'Новое Колпино'!F37,'Таллинский парк'!F37) | G37: =SUM('Астрид'!G37,'Курортный'!G37,'Новое Колпино'!G37,'Таллинский парк'!G37) | H37: - | I37: =SUM('Астрид'!I37,'Курортный'!I37,'Новое Колпино'!I37,'Таллинский парк'!I37)
A38: Медосмотры | B38: =SUM(C38,D38,E38,F38) | C38: =SUM('Астрид'!C38,'Курортный'!C38,'Новое Колпино'!C38,'Таллинский парк'!C38) | D38: =SUM('Астрид'!D38,'Курортный'!D38,'Новое Колпино'!D38,'Таллинский парк'!D38) | E38: =SUM('Астрид'!E38,'Курортный'!E38,'Новое Колпино'!E38,'Таллинский парк'!E38) | F38: =SUM('Астрид'!F38,'Курортный'!F38,'Новое Колпино'!F38,'Таллинский парк'!F38) | G38: =SUM('Астрид'!G38,'Курортный'!G38,'Новое Колпино'!G38,'Таллинский парк'!G38) | H38: - | I38: =SUM('Астрид'!I38,'Курортный'!I38,'Новое Колпино'!I38,'Таллинский парк'!I38)
A39: Налоги с ФОТ (ИП) | B39: =SUM(C39,D39,E39,F39) | C39: =SUM('Астрид'!C39,'Курортный'!C39,'Новое Колпино'!C39,'Таллинский парк'!C39) | D39: =SUM('Астрид'!D39,'Курортный'!D39,'Новое Колпино'!D39,'Таллинский парк'!D39) | E39: =SUM('Астрид'!E39,'Курортный'!E39,'Новое Колпино'!E39,'Таллинский парк'!E39) | F39: =SUM('Астрид'!F39,'Курортный'!F39,'Новое Колпино'!F39,'Таллинский парк'!F39) | G39: =SUM('Астрид'!G39,'Курортный'!G39,'Новое Колпино'!G39,'Таллинский парк'!G39) | H39: - | I39: =SUM('Астрид'!I39,'Курортный'!I39,'Новое Колпино'!I39,'Таллинский парк'!I39)
A40: Приобритение мебели, бытовой техники | B40: =SUM(C40,D40,E40,F40) | C40: =SUM('Астрид'!C40,'Курортный'!C40,'Новое Колпино'!C40,'Таллинский парк'!C40) | D40: =SUM('Астрид'!D40,'Курортный'!D40,'Новое Колпино'!D40,'Таллинский парк'!D40) | E40: =SUM('Астрид'!E40,'Курортный'!E40,'Новое Колпино'!E40,'Таллинский парк'!E40) | F40: =SUM('Астрид'!F40,'Курортный'!F40,'Новое Колпино'!F40,'Таллинский парк'!F40) | G40: =SUM('Астрид'!G40,'Курортный'!G40,'Новое Колпино'!G40,'Таллинский парк'!G40) | H40: - | I40: =SUM('Астрид'!I40,'Курортный'!I40,'Новое Колпино'!I40,'Таллинский парк'!I40)
A41: Комиссия за перевод ЗП | B41: =SUM(C41,D41,E41,F41) | C41: =SUM('Астрид'!C41,'Курортный'!C41,'Новое Колпино'!C41,'Таллинский парк'!C41) | D41: =SUM('Астрид'!D41,'Курортный'!D41,'Новое Колпино'!D41,'Таллинский парк'!D41) | E41: =SUM('Астрид'!E41,'Курортный'!E41,'Новое Колпино'!E41,'Таллинский парк'!E41) | F41: =SUM('Астрид'!F41,'Курортный'!F41,'Новое Колпино'!F41,'Таллинский парк'!F41) | G41: =SUM('Астрид'!G41,'Курортный'!G41,'Новое Колпино'!G41,'Таллинский парк'!G41) | H41: - | I41: =SUM('Астрид'!I41,'Курортный'!I41,'Новое Колпино'!I41,'Таллинский парк'!I41)
A42: Аренда квартиры (включая коммуналку) | B42: =SUM(C42,D42,E42,F42) | C42: =SUM('Астрид'!C42,'Курортный'!C42,'Новое Колпино'!C42,'Таллинский парк'!C42) | D42: =SUM('Астрид'!D42,'Курортный'!D42,'Новое Колпино'!D42,'Таллинский парк'!D42) | E42: =SUM('Астрид'!E42,'Курортный'!E42,'Новое Колпино'!E42,'Таллинский парк'!E42) | F42: =SUM('Астрид'!F42,'Курортный'!F42,'Новое Колпино'!F42,'Таллинский парк'!F42) | G42: =SUM('Астрид'!G42,'Курортный'!G42,'Новое Колпино'!G42,'Таллинский парк'!G42) | H42: - | I42: =SUM('Астрид'!I42,'Курортный'!I42,'Новое Колпино'!I42,'Таллинский парк'!I42)
A43: Валовая прибыль | B43: =B4-B10 | C43: =C4-C10 | D43: =D4-D10 | E43: =E4-E10 | F43: =F4-F10 | G43: =G4-G10 | H43: - | I43: =I4-I10
A44: Валовая рентабельность | B44: =IFERROR(IF(B4=0,"-",B43/B4),"-") | C44: =IFERROR(IF(C4=0,"-",C43/C4),"-") | D44: =IFERROR(IF(D4=0,"-",D43/D4),"-") | E44: =IFERROR(IF(E4=0,"-",E43/E4),"-") | F44: =IFERROR(IF(F4=0,"-",F43/F4),"-") | G44: =IFERROR(IF(G4=0,"-",G43/G4),"-") | H44: - | I44: =IFERROR(IF(I4=0,"-",I43/I4),"-")
A45: Косвенные расходы | B45: =SUM(B46,B47,B48,B52,B56,B57,B58,B59,B60,B63,B64,B65,B66,B67,B68,B69,B70,B71,B72,B73,B74,B75,B76,B77,B78,B79) | C45: =SUM(C46,C47,C48,C52,C56,C57,C58,C59,C60,C63,C64,C65,C66,C67,C68,C69,C70,C71,C72,C73,C74,C75,C76,C77,C78,C79) | D45: =SUM(D46,D47,D48,D52,D56,D57,D58,D59,D60,D63,D64,D65,D66,D67,D68,D69,D70,D71,D72,D73,D74,D75,D76,D77,D78,D79) | E45: =SUM(E46,E47,E48,E52,E56,E57,E58,E59,E60,E63,E64,E65,E66,E67,E68,E69,E70,E71,E72,E73,E74,E75,E76,E77,E78,E79) | F45: =SUM(F46,F47,F48,F52,F56,F57,F58,F59,F60,F63,F64,F65,F66,F67,F68,F69,F70,F71,F72,F73,F74,F75,F76,F77,F78,F79) | G45: =SUM(G46,G47,G48,G52,G56,G57,G58,G59,G60,G63,G64,G65,G66,G67,G68,G69,G70,G71,G72,G73,G74,G75,G76,G77,G78,G79) | H45: - | I45: =SUM(I46,I47,I48,I52,I56,I57,I58,I59,I60,I63,I64,I65,I66,I67,I68,I69,I70,I71,I72,I73,I74,I75,I76,I77,I78,I79)
A46: Расход БЭК-ОФИС | B46: =SUM(C46,D46,E46,F46) | C46: =SUM('Астрид'!C46,'Курортный'!C46,'Новое Колпино'!C46,'Таллинский парк'!C46) | D46: =SUM('Астрид'!D46,'Курортный'!D46,'Новое Колпино'!D46,'Таллинский парк'!D46) | E46: =SUM('Астрид'!E46,'Курортный'!E46,'Новое Колпино'!E46,'Таллинский парк'!E46) | F46: =SUM('Астрид'!F46,'Курортный'!F46,'Новое Колпино'!F46,'Таллинский парк'!F46) | G46: =SUM('Астрид'!G46,'Курортный'!G46,'Новое Колпино'!G46,'Таллинский парк'!G46) | H46: - | I46: =SUM('Астрид'!I46,'Курортный'!I46,'Новое Колпино'!I46,'Таллинский парк'!I46)
A47: Расходы на бэк-офис | B47: =SUM(C47,D47,E47,F47) | C47: =SUM('Астрид'!C47,'Курортный'!C47,'Новое Колпино'!C47,'Таллинский парк'!C47) | D47: =SUM('Астрид'!D47,'Курортный'!D47,'Новое Колпино'!D47,'Таллинский парк'!D47) | E47: =SUM('Астрид'!E47,'Курортный'!E47,'Новое Колпино'!E47,'Таллинский парк'!E47) | F47: =SUM('Астрид'!F47,'Курортный'!F47,'Новое Колпино'!F47,'Таллинский парк'!F47) | G47: =SUM('Астрид'!G47,'Курортный'!G47,'Новое Колпино'!G47,'Таллинский парк'!G47) | H47: - | I47: =SUM('Астрид'!I47,'Курортный'!I47,'Новое Колпино'!I47,'Таллинский парк'!I47)
...

Sheet Астрид
A1: ПланФакт | B1: Создано с помощью сервиса ПланФакт | I1: =HYPERLINK("https://app.planfact.io/?from=Pf_BDR", "Перейти в сервис")
B2: Итого | C2: июнь` 26 | D2: июль` 26 | E2: август` 26 | F2: сентябрь` 26 | G2: октябрь` 26 | H2: ноябрь` 26 | I2: декабрь` 26
A3: Астрид | B3: план | C3: план | D3: план | E3: план | F3: план | G3: план | H3: план | I3: план
A4: Выручка | B4: =SUM(B5,B6) | C4: =SUM(C5,C6) | D4: =SUM(D5,D6) | E4: =SUM(E5,E6) | F4: =SUM(F5,F6) | G4: =SUM(G5,G6) | H4: - | I4: =SUM(I5,I6)
A5: Нераспределенный доход | B5: =SUM(C5,D5,E5,F5) | C5: - | D5: - | E5: - | F5: - | G5: - | H5: - | I5: -
A6: Выручка | B6: =SUM(B7,B8,B9) | C6: =SUM(C7,C8,C9) | D6: =SUM(D7,D8,D9) | E6: =SUM(E7,E8,E9) | F6: =SUM(F7,F8,F9) | G6: =SUM(G7,G8,G9) | H6: - | I6: =SUM(I7,I8,I9)
A7: Реализация услуг Клининг (ОД) | B7: =SUM(C7,D7,E7,F7) | C7: 228370.58 | D7: 653960.57 | E7: 228370.58 | F7: 653960.57 | G7: - | H7: - | I7: -
A8: Реализация услуг Клининг (Доп.услуги) | B8: =SUM(C8,D8,E8,F8) | C8: - | D8: 470000 | E8: - | F8: - | G8: - | H8: - | I8: -
A9: Реализация услуг Клининг (снег) | B9: =SUM(C9,D9,E9,F9) | C9: - | D9: - | E9: - | F9: - | G9: - | H9: - | I9: -
A10: Прямые расходы | B10: =SUM(B11,B12,B13,B21,B22,B23,B24,B25,B26,B27,B28,B29,B30,B31,B32,B33,B34) | C10: =SUM(C11,C12,C13,C21,C22,C23,C24,C25,C26,C27,C28,C29,C30,C31,C32,C33,C34) | D10: =SUM(D11,D12,D13,D21,D22,D23,D24,D25,D26,D27,D28,D29,D30,D31,D32,D33,D34) | E10: =SUM(E11,E12,E13,E21,E22,E23,E24,E25,E26,E27,E28,E29,E30,E31,E32,E33,E34) | F10: =SUM(F11,F12,F13,F21,F22,F23,F24,F25,F26,F27,F28,F29,F30,F31,F32,F33,F34) | G10: =SUM(G11,G12,G13,G21,G22,G23,G24,G25,G26,G27,G28,G29,G30,G31,G32,G33,G34) | H10: - | I10: =SUM(I11,I12,I13,I21,I22,I23,I24,I25,I26,I27,I28,I29,I30,I31,I32,I33,I34)
A11: Нераспределенный расход | B11: =SUM(C11,D11,E11,F11) | C11: - | D11: - | E11: - | F11: - | G11: - | H11: - | I11: -
A12: Транспортные расходы | B12: =SUM(C12,D12,E12,F12) | C12: - | D12: - | E12: - | F12: - | G12: - | H12: - | I12: -
A13: Переменные | B13: =SUM(B14,B15,B16,B17,B18,B19,B20) | C13: =SUM(C14,C15,C16,C17,C18,C19,C20) | D13: =SUM(D14,D15,D16,D17,D18,D19,D20) | E13: =SUM(E14,E15,E16,E17,E18,E19,E20) | F13: =SUM(F14,F15,F16,F17,F18,F19,F20) | G13: =SUM(G14,G15,G16,G17,G18,G19,G20) | H13: - | I13: =SUM(I14,I15,I16,I17,I18,I19,I20)
A14: Услуги техниги для уборки снега (ПТ) | B14: =SUM(C14,D14,E14,F14) | C14: - | D14: - | E14: - | F14: - | G14: - | H14: - | I14: -
A15: Услуги садовника (ПТ) | B15: =SUM(C15,D15,E15,F15) | C15: - | D15: - | E15: - | F15: - | G15: - | H15: - | I15: -
A16: Сыпучие материалы (ПТ) | B16: =SUM(C16,D16,E16,F16) | C16: - | D16: - | E16: - | F16: - | G16: - | H16: - | I16: -
A17: Расходные материалы и инстументы (МОП) | B17: =SUM(C17,D17,E17,F17) | C17: 10587.92 | D17: 21587.92 | E17: 10587.92 | F17: 10000 | G17: - | H17: - | I17: -
A18: Расходные материалы и инстументы (ПТ) | B18: =SUM(C18,D18,E18,F18) | C18: - | D18: 5000 | E18: - | F18: 5000 | G18: - | H18: - | I18: -
A19: Арена оборудования (ПТ) | B19: =SUM(C19,D19,E19,F19) | C19: - | D19: - | E19: - | F19: - | G19: - | H19: - | I19: -
A20: Арена оборудования (МОП) | B20: =SUM(C20,D20,E20,F20) | C20: - | D20: - | E20: - | F20: - | G20: - | H20: - | I20: -
A21: Заработная плата (МОП) | B21: =SUM(C21,D21,E21,F21) | C21: 209688.53 | D21: 210030 | E21: 209688.53 | F21: 210030 | G21: - | H21: - | I21: -
A22: Заработная плата (ПТ) | B22: =SUM(C22,D22,E22,F22) | C22: 294494.09 | D22: 258000 | E22: 294494.09 | F22: 258000 | G22: - | H22: - | I22: -
A23: Налоги с ФОТ (МОП) | B23: =SUM(C23,D23,E23,F23) | C23: 19188.5 | D23: 64800 | E23: 19188.5 | F23: 42000 | G23: - | H23: - | I23: -
A24: Налоги с ФОТ (ПТ) | B24: =SUM(C24,D24,E24,F24) | C24: 13380.59 | D24: 5012.59 | E24: 13380.59 | F24: - | G24: - | H24: - | I24: -
A25: Премми (МОП) | B25: =SUM(C25,D25,E25,F25) | C25: - | D25: - | E25: - | F25: - | G25: - | H25: - | I25: -
A26: Премми (ПТ) | B26: =SUM(C26,D26,E26,F26) | C26: - | D26: - | E26: - | F26: - | G26: - | H26: - | I26: -
A27: Униформа (МОП) | B27: =SUM(C27,D27,E27,F27) | C27: - | D27: - | E27: - | F27: - | G27: - | H27: - | I27: -
A28: Униформа (ПТ) | B28: =SUM(C28,D28,E28,F28) | C28: - | D28: - | E28: - | F28: - | G28: - | H28: - | I28: -
A29: Ремонт оборудования (МОП) | B29: =SUM(C29,D29,E29,F29) | C29: - | D29: - | E29: - | F29: - | G29: - | H29: - | I29: -
A30: Ремонт оборудования (ПТ) | B30: =SUM(C30,D30,E30,F30) | C30: 1019 | D30: - | E30: 1019 | F30: - | G30: - | H30: - | I30: -
A31: Вывоз мусора | B31: =SUM(C31,D31,E31,F31) | C31: - | D31: - | E31: - | F31: - | G31: - | H31: - | I31: -
A32: Штрафы, пени, неустойки | B32: =SUM(C32,D32,E32,F32) | C32: - | D32: - | E32: - | F32: - | G32: - | H32: - | I32: -
A33: Расходы к удержанию | B33: =SUM(C33,D33,E33,F33) | C33: - | D33: - | E33: - | F33: - | G33: - | H33: - | I33: -
A34: Общехозяйственные | B34: =SUM(B35,B36,B37,B38,B39,B40,B41,B42) | C34: =SUM(C35,C36,C37,C38,C39,C40,C41,C42) | D34: =SUM(D35,D36,D37,D38,D39,D40,D41,D42) | E34: =SUM(E35,E36,E37,E38,E39,E40,E41,E42) | F34: =SUM(F35,F36,F37,F38,F39,F40,F41,F42) | G34: =SUM(G35,G36,G37,G38,G39,G40,G41,G42) | H34: - | I34: =SUM(I35,I36,I37,I38,I39,I40,I41,I42)
A35: Аутсорс (направления) | B35: =SUM(C35,D35,E35,F35) | C35: 10000 | D35: 7500 | E35: 10000 | F35: 2500 | G35: - | H35: - | I35: -
A36: Заработная плата МО АУП | B36: =SUM(C36,D36,E36,F36) | C36: 60000 | D36: 60000 | E36: 60000 | F36: 60000 | G36: - | H36: - | I36: -
A37: Инструменты: ГСМ | B37: =SUM(C37,D37,E37,F37) | C37: 2000 | D37: 1000 | E37: 2000 | F37: 1000 | G37: - | H37: - | I37: -
A38: Медосмотры | B38: =SUM(C38,D38,E38,F38) | C38: - | D38: - | E38: - | F38: - | G38: - | H38: - | I38: -
A39: Налоги с ФОТ (ИП) | B39: =SUM(C39,D39,E39,F39) | C39: 26500 | D39: 36960 | E39: 26500 | F39: 36960 | G39: - | H39: - | I39: -
A40: Приобритение мебели, бытовой техники | B40: =SUM(C40,D40,E40,F40) | C40: - | D40: - | E40: - | F40: - | G40: - | H40: - | I40: -
...

Sheet Курортный
A1: ПланФакт | B1: Создано с помощью сервиса ПланФакт | I1: =HYPERLINK("https://app.planfact.io/?from=Pf_BDR", "Перейти в сервис")
B2: Итого | C2: июнь` 26 | D2: июль` 26 | E2: август` 26 | F2: сентябрь` 26 | G2: октябрь` 26 | H2: ноябрь` 26 | I2: декабрь` 26
A3: Курортный | B3: план | C3: план | D3: план | E3: план | F3: план | G3: план | H3: план | I3: план
A4: Выручка | B4: =SUM(B5,B6) | C4: =SUM(C5,C6) | D4: =SUM(D5,D6) | E4: =SUM(E5,E6) | F4: =SUM(F5,F6) | G4: =SUM(G5,G6) | H4: - | I4: =SUM(I5,I6)
A5: Нераспределенный доход | B5: =SUM(C5,D5,E5,F5) | C5: - | D5: - | E5: - | F5: - | G5: - | H5: - | I5: -
A6: Выручка | B6: =SUM(B7,B8,B9) | C6: =SUM(C7,C8,C9) | D6: =SUM(D7,D8,D9) | E6: =SUM(E7,E8,E9) | F6: =SUM(F7,F8,F9) | G6: =SUM(G7,G8,G9) | H6: - | I6: =SUM(I7,I8,I9)
A7: Реализация услуг Клининг (ОД) | B7: =SUM(C7,D7,E7,F7) | C7: 1299347.8 | D7: 1299347.8 | E7: 1299347.8 | F7: 1299347.8 | G7: - | H7: - | I7: -
A8: Реализация услуг Клининг (Доп.услуги) | B8: =SUM(C8,D8,E8,F8) | C8: 772382 | D8: 661260 | E8: 661260.69 | F8: 661260.69 | G8: - | H8: - | I8: -
A9: Реализация услуг Клининг (снег) | B9: =SUM(C9,D9,E9,F9) | C9: - | D9: - | E9: - | F9: - | G9: - | H9: - | I9: -
A10: Прямые расходы | B10: =SUM(B11,B12,B13,B21,B22,B23,B24,B25,B26,B27,B28,B29,B30,B31,B32,B33,B34) | C10: =SUM(C11,C12,C13,C21,C22,C23,C24,C25,C26,C27,C28,C29,C30,C31,C32,C33,C34) | D10: =SUM(D11,D12,D13,D21,D22,D23,D24,D25,D26,D27,D28,D29,D30,D31,D32,D33,D34) | E10: =SUM(E11,E12,E13,E21,E22,E23,E24,E25,E26,E27,E28,E29,E30,E31,E32,E33,E34) | F10: =SUM(F11,F12,F13,F21,F22,F23,F24,F25,F26,F27,F28,F29,F30,F31,F32,F33,F34) | G10: =SUM(G11,G12,G13,G21,G22,G23,G24,G25,G26,G27,G28,G29,G30,G31,G32,G33,G34) | H10: - | I10: =SUM(I11,I12,I13,I21,I22,I23,I24,I25,I26,I27,I28,I29,I30,I31,I32,I33,I34)
A11: Нераспределенный расход | B11: =SUM(C11,D11,E11,F11) | C11: - | D11: - | E11: - | F11: - | G11: - | H11: - | I11: -
A12: Транспортные расходы | B12: =SUM(C12,D12,E12,F12) | C12: - | D12: - | E12: - | F12: - | G12: - | H12: - | I12: -
A13: Переменные | B13: =SUM(B14,B15,B16,B17,B18,B19,B20) | C13: =SUM(C14,C15,C16,C17,C18,C19,C20) | D13: =SUM(D14,D15,D16,D17,D18,D19,D20) | E13: =SUM(E14,E15,E16,E17,E18,E19,E20) | F13: =SUM(F14,F15,F16,F17,F18,F19,F20) | G13: =SUM(G14,G15,G16,G17,G18,G19,G20) | H13: - | I13: =SUM(I14,I15,I16,I17,I18,I19,I20)
A14: Услуги техниги для уборки снега (ПТ) | B14: =SUM(C14,D14,E14,F14) | C14: - | D14: - | E14: - | F14: - | G14: - | H14: - | I14: -
A15: Услуги садовника (ПТ) | B15: =SUM(C15,D15,E15,F15) | C15: - | D15: - | E15: - | F15: - | G15: - | H15: - | I15: -
A16: Сыпучие материалы (ПТ) | B16: =SUM(C16,D16,E16,F16) | C16: - | D16: - | E16: - | F16: - | G16: - | H16: - | I16: -
A17: Расходные материалы и инстументы (МОП) | B17: =SUM(C17,D17,E17,F17) | C17: 10000 | D17: 10000 | E17: 10000 | F17: 10000 | G17: - | H17: - | I17: -
A18: Расходные материалы и инстументы (ПТ) | B18: =SUM(C18,D18,E18,F18) | C18: 7999 | D18: 5000 | E18: 5000 | F18: 5000 | G18: - | H18: - | I18: -
A19: Арена оборудования (ПТ) | B19: =SUM(C19,D19,E19,F19) | C19: - | D19: - | E19: - | F19: - | G19: - | H19: - | I19: -
A20: Арена оборудования (МОП) | B20: =SUM(C20,D20,E20,F20) | C20: - | D20: - | E20: - | F20: - | G20: - | H20: - | I20: -
A21: Заработная плата (МОП) | B21: =SUM(C21,D21,E21,F21) | C21: 695034.97 | D21: 665000 | E21: 665000 | F21: 665000 | G21: - | H21: - | I21: -
A22: Заработная плата (ПТ) | B22: =SUM(C22,D22,E22,F22) | C22: 600000 | D22: 600000 | E22: 600000 | F22: 600000 | G22: - | H22: - | I22: -
A23: Налоги с ФОТ (МОП) | B23: =SUM(C23,D23,E23,F23) | C23: 60061 | D23: 79913 | E23: 79913 | F23: 79913 | G23: - | H23: - | I23: -
A24: Налоги с ФОТ (ПТ) | B24: =SUM(C24,D24,E24,F24) | C24: 28000 | D24: 28000 | E24: 28000 | F24: 28000 | G24: - | H24: - | I24: -
A25: Премми (МОП) | B25: =SUM(C25,D25,E25,F25) | C25: - | D25: - | E25: - | F25: - | G25: - | H25: - | I25: -
A26: Премми (ПТ) | B26: =SUM(C26,D26,E26,F26) | C26: - | D26: - | E26: - | F26: - | G26: - | H26: - | I26: -
A27: Униформа (МОП) | B27: =SUM(C27,D27,E27,F27) | C27: - | D27: - | E27: - | F27: - | G27: - | H27: - | I27: -
A28: Униформа (ПТ) | B28: =SUM(C28,D28,E28,F28) | C28: 7069 | D28: - | E28: - | F28: - | G28: - | H28: - | I28: -
A29: Ремонт оборудования (МОП) | B29: =SUM(C29,D29,E29,F29) | C29: - | D29: - | E29: - | F29: - | G29: - | H29: - | I29: -
A30: Ремонт оборудования (ПТ) | B30: =SUM(C30,D30,E30,F30) | C30: 3000 | D30: 3000 | E30: 3000 | F30: 3000 | G30: - | H30: - | I30: -
A31: Вывоз мусора | B31: =SUM(C31,D31,E31,F31) | C31: - | D31: - | E31: - | F31: - | G31: - | H31: - | I31: -
A32: Штрафы, пени, неустойки | B32: =SUM(C32,D32,E32,F32) | C32: - | D32: - | E32: - | F32: - | G32: - | H32: - | I32: -
A33: Расходы к удержанию | B33: =SUM(C33,D33,E33,F33) | C33: - | D33: - | E33: - | F33: - | G33: - | H33: - | I33: -
A34: Общехозяйственные | B34: =SUM(B35,B36,B37,B38,B39,B40,B41,B42) | C34: =SUM(C35,C36,C37,C38,C39,C40,C41,C42) | D34: =SUM(D35,D36,D37,D38,D39,D40,D41,D42) | E34: =SUM(E35,E36,E37,E38,E39,E40,E41,E42) | F34: =SUM(F35,F36,F37,F38,F39,F40,F41,F42) | G34: =SUM(G35,G36,G37,G38,G39,G40,G41,G42) | H34: - | I34: =SUM(I35,I36,I37,I38,I39,I40,I41,I42)
A35: Аутсорс (направления) | B35: =SUM(C35,D35,E35,F35) | C35: 2500 | D35: 2500 | E35: 2500 | F35: 2500 | G35: - | H35: - | I35: -
A36: Заработная плата МО АУП | B36: =SUM(C36,D36,E36,F36) | C36: 110000 | D36: 110000 | E36: 110000 | F36: 110000 | G36: - | H36: - | I36: -
A37: Инструменты: ГСМ | B37: =SUM(C37,D37,E37,F37) | C37: 3504.04 | D37: 3500 | E37: 3500 | F37: 3500 | G37: - | H37: - | I37: -
A38: Медосмотры | B38: =SUM(C38,D38,E38,F38) | C38: - | D38: - | E38: - | F38: - | G38: - | H38: - | I38: -
A39: Налоги с ФОТ (ИП) | B39: =SUM(C39,D39,E39,F39) | C39: 95550 | D39: 95550 | E39: 95550 | F39: 95550 | G39: - | H39: - | I39: -
A40: Приобритение мебели, бытовой техники | B40: =SUM(C40,D40,E40,F40) | C40: - | D40: - | E40: - | F40: - | G40: - | H40: - | I40: -
...

Sheet Новое Колпино
A1: ПланФакт | B1: Создано с помощью сервиса ПланФакт | I1: =HYPERLINK("https://app.planfact.io/?from=Pf_BDR", "Перейти в сервис")
B2: Итого | C2: июнь` 26 | D2: июль` 26 | E2: август` 26 | F2: сентябрь` 26 | G2: октябрь` 26 | H2: ноябрь` 26 | I2: декабрь` 26
A3: Новое Колпино | B3: план | C3: план | D3: план | E3: план | F3: план | G3: план | H3: план | I3: план
A4: Выручка | B4: =SUM(B5,B6) | C4: =SUM(C5,C6) | D4: =SUM(D5,D6) | E4: =SUM(E5,E6) | F4: =SUM(F5,F6) | G4: =SUM(G5,G6) | H4: - | I4: =SUM(I5,I6)
A5: Нераспределенный доход | B5: =SUM(C5,D5,E5,F5) | C5: - | D5: - | E5: - | F5: - | G5: - | H5: - | I5: -
A6: Выручка | B6: =SUM(B7,B8,B9) | C6: =SUM(C7,C8,C9) | D6: =SUM(D7,D8,D9) | E6: =SUM(E7,E8,E9) | F6: =SUM(F7,F8,F9) | G6: =SUM(G7,G8,G9) | H6: - | I6: =SUM(I7,I8,I9)
A7: Реализация услуг Клининг (ОД) | B7: =SUM(C7,D7,E7,F7) | C7: 2759092 | D7: 2472043.9 | E7: 2472043.9 | F7: 2472043.9 | G7: - | H7: - | I7: -
A8: Реализация услуг Клининг (Доп.услуги) | B8: =SUM(C8,D8,E8,F8) | C8: - | D8: - | E8: - | F8: - | G8: - | H8: - | I8: -
A9: Реализация услуг Клининг (снег) | B9: =SUM(C9,D9,E9,F9) | C9: - | D9: - | E9: - | F9: - | G9: - | H9: - | I9: -
A10: Прямые расходы | B10: =SUM(B11,B12,B13,B21,B22,B23,B24,B25,B26,B27,B28,B29,B30,B31,B32,B33,B34) | C10: =SUM(C11,C12,C13,C21,C22,C23,C24,C25,C26,C27,C28,C29,C30,C31,C32,C33,C34) | D10: =SUM(D11,D12,D13,D21,D22,D23,D24,D25,D26,D27,D28,D29,D30,D31,D32,D33,D34) | E10: =SUM(E11,E12,E13,E21,E22,E23,E24,E25,E26,E27,E28,E29,E30,E31,E32,E33,E34) | F10: =SUM(F11,F12,F13,F21,F22,F23,F24,F25,F26,F27,F28,F29,F30,F31,F32,F33,F34) | G10: =SUM(G11,G12,G13,G21,G22,G23,G24,G25,G26,G27,G28,G29,G30,G31,G32,G33,G34) | H10: - | I10: =SUM(I11,I12,I13,I21,I22,I23,I24,I25,I26,I27,I28,I29,I30,I31,I32,I33,I34)
A11: Нераспределенный расход | B11: =SUM(C11,D11,E11,F11) | C11: - | D11: - | E11: - | F11: - | G11: - | H11: - | I11: -
A12: Транспортные расходы | B12: =SUM(C12,D12,E12,F12) | C12: - | D12: - | E12: - | F12: - | G12: - | H12: - | I12: -
A13: Переменные | B13: =SUM(B14,B15,B16,B17,B18,B19,B20) | C13: =SUM(C14,C15,C16,C17,C18,C19,C20) | D13: =SUM(D14,D15,D16,D17,D18,D19,D20) | E13: =SUM(E14,E15,E16,E17,E18,E19,E20) | F13: =SUM(F14,F15,F16,F17,F18,F19,F20) | G13: =SUM(G14,G15,G16,G17,G18,G19,G20) | H13: - | I13: =SUM(I14,I15,I16,I17,I18,I19,I20)
A14: Услуги техниги для уборки снега (ПТ) | B14: =SUM(C14,D14,E14,F14) | C14: - | D14: - | E14: - | F14: - | G14: - | H14: - | I14: -
A15: Услуги садовника (ПТ) | B15: =SUM(C15,D15,E15,F15) | C15: 88000 | D15: 88000 | E15: 88000 | F15: 88000 | G15: - | H15: - | I15: -
A16: Сыпучие материалы (ПТ) | B16: =SUM(C16,D16,E16,F16) | C16: - | D16: - | E16: - | F16: - | G16: - | H16: - | I16: -
A17: Расходные материалы и инстументы (МОП) | B17: =SUM(C17,D17,E17,F17) | C17: 43810.13 | D17: 30000 | E17: 30000 | F17: 30000 | G17: - | H17: - | I17: -
A18: Расходные материалы и инстументы (ПТ) | B18: =SUM(C18,D18,E18,F18) | C18: 5901.4 | D18: 60000 | E18: 10000 | F18: 10000 | G18: - | H18: - | I18: -
A19: Арена оборудования (ПТ) | B19: =SUM(C19,D19,E19,F19) | C19: - | D19: - | E19: - | F19: - | G19: - | H19: - | I19: -
A20: Арена оборудования (МОП) | B20: =SUM(C20,D20,E20,F20) | C20: - | D20: 30000 | E20: - | F20: - | G20: - | H20: - | I20: -
A21: Заработная плата (МОП) | B21: =SUM(C21,D21,E21,F21) | C21: 685000 | D21: 685000 | E21: 685000 | F21: 685000 | G21: - | H21: - | I21: -
A22: Заработная плата (ПТ) | B22: =SUM(C22,D22,E22,F22) | C22: 958084.67 | D22: 920000 | E22: 920000 | F22: 920000 | G22: - | H22: - | I22: -
A23: Налоги с ФОТ (МОП) | B23: =SUM(C23,D23,E23,F23) | C23: 28000 | D23: 28000 | E23: 28000 | F23: 28000 | G23: - | H23: - | I23: -
A24: Налоги с ФОТ (ПТ) | B24: =SUM(C24,D24,E24,F24) | C24: 143705 | D24: 143705 | E24: 143705 | F24: 143705 | G24: - | H24: - | I24: -
A25: Премми (МОП) | B25: =SUM(C25,D25,E25,F25) | C25: - | D25: - | E25: - | F25: - | G25: - | H25: - | I25: -
A26: Премми (ПТ) | B26: =SUM(C26,D26,E26,F26) | C26: - | D26: - | E26: - | F26: - | G26: - | H26: - | I26: -
A27: Униформа (МОП) | B27: =SUM(C27,D27,E27,F27) | C27: - | D27: - | E27: - | F27: - | G27: - | H27: - | I27: -
A28: Униформа (ПТ) | B28: =SUM(C28,D28,E28,F28) | C28: - | D28: - | E28: - | F28: - | G28: - | H28: - | I28: -
A29: Ремонт оборудования (МОП) | B29: =SUM(C29,D29,E29,F29) | C29: - | D29: - | E29: - | F29: - | G29: - | H29: - | I29: -
A30: Ремонт оборудования (ПТ) | B30: =SUM(C30,D30,E30,F30) | C30: 3000 | D30: 3000 | E30: 3000 | F30: 3000 | G30: - | H30: - | I30: -
A31: Вывоз мусора | B31: =SUM(C31,D31,E31,F31) | C31: - | D31: - | E31: - | F31: - | G31: - | H31: - | I31: -
A32: Штрафы, пени, неустойки | B32: =SUM(C32,D32,E32,F32) | C32: - | D32: - | E32: - | F32: - | G32: - | H32: - | I32: -
A33: Расходы к удержанию | B33: =SUM(C33,D33,E33,F33) | C33: - | D33: - | E33: - | F33: - | G33: - | H33: - | I33: -
A34: Общехозяйственные | B34: =SUM(B35,B36,B37,B38,B39,B40,B41,B42) | C34: =SUM(C35,C36,C37,C38,C39,C40,C41,C42) | D34: =SUM(D35,D36,D37,D38,D39,D40,D41,D42) | E34: =SUM(E35,E36,E37,E38,E39,E40,E41,E42) | F34: =SUM(F35,F36,F37,F38,F39,F40,F41,F42) | G34: =SUM(G35,G36,G37,G38,G39,G40,G41,G42) | H34: - | I34: =SUM(I35,I36,I37,I38,I39,I40,I41,I42)
A35: Аутсорс (направления) | B35: =SUM(C35,D35,E35,F35) | C35: 5000 | D35: 5000 | E35: 5000 | F35: 5000 | G35: - | H35: - | I35: -
A36: Заработная плата МО АУП | B36: =SUM(C36,D36,E36,F36) | C36: 100000 | D36: 100000 | E36: 100000 | F36: 100000 | G36: - | H36: - | I36: -
A37: Инструменты: ГСМ | B37: =SUM(C37,D37,E37,F37) | C37: 5000 | D37: 5000 | E37: 5000 | F37: 5000 | G37: - | H37: - | I37: -
A38: Медосмотры | B38: =SUM(C38,D38,E38,F38) | C38: - | D38: - | E38: - | F38: - | G38: - | H38: - | I38: -
A39: Налоги с ФОТ (ИП) | B39: =SUM(C39,D39,E39,F39) | C39: 119350 | D39: 119350 | E39: 119350 | F39: 119350 | G39: - | H39: - | I39: -
A40: Приобритение мебели, бытовой техники | B40: =SUM(C40,D40,E40,F40) | C40: - | D40: - | E40: - | F40: - | G40: - | H40: - | I40: -
...

Sheet Таллинский парк
A1: ПланФакт | B1: Создано с помощью сервиса ПланФакт | I1: =HYPERLINK("https://app.planfact.io/?from=Pf_BDR", "Перейти в сервис")
B2: Итого | C2: июнь` 26 | D2: июль` 26 | E2: август` 26 | F2: сентябрь` 26 | G2: октябрь` 26 | H2: ноябрь` 26 | I2: декабрь` 26
A3: Таллинский парк | B3: план | C3: план | D3: план | E3: план | F3: план | G3: план | H3: план | I3: план
A4: Выручка | B4: =SUM(B5,B6) | C4: =SUM(C5,C6) | D4: =SUM(D5,D6) | E4: =SUM(E5,E6) | F4: =SUM(F5,F6) | G4: =SUM(G5,G6) | H4: - | I4: =SUM(I5,I6)
A5: Нераспределенный доход | B5: =SUM(C5,D5,E5,F5) | C5: - | D5: - | E5: - | F5: - | G5: - | H5: - | I5: -
A6: Выручка | B6: =SUM(B7,B8,B9) | C6: =SUM(C7,C8,C9) | D6: =SUM(D7,D8,D9) | E6: =SUM(E7,E8,E9) | F6: =SUM(F7,F8,F9) | G6: =SUM(G7,G8,G9) | H6: - | I6: =SUM(I7,I8,I9)
A7: Реализация услуг Клининг (ОД) | B7: =SUM(C7,D7,E7,F7) | C7: 1599464.2 | D7: 1599464.2 | E7: 1599464.2 | F7: 1599464.2 | G7: - | H7: - | I7: -
A8: Реализация услуг Клининг (Доп.услуги) | B8: =SUM(C8,D8,E8,F8) | C8: - | D8: - | E8: - | F8: - | G8: - | H8: - | I8: -
A9: Реализация услуг Клининг (снег) | B9: =SUM(C9,D9,E9,F9) | C9: - | D9: - | E9: - | F9: - | G9: - | H9: - | I9: -
A10: Прямые расходы | B10: =SUM(B11,B12,B13,B21,B22,B23,B24,B25,B26,B27,B28,B29,B30,B31,B32,B33,B34) | C10: =SUM(C11,C12,C13,C21,C22,C23,C24,C25,C26,C27,C28,C29,C30,C31,C32,C33,C34) | D10: =SUM(D11,D12,D13,D21,D22,D23,D24,D25,D26,D27,D28,D29,D30,D31,D32,D33,D34) | E10: =SUM(E11,E12,E13,E21,E22,E23,E24,E25,E26,E27,E28,E29,E30,E31,E32,E33,E34) | F10: =SUM(F11,F12,F13,F21,F22,F23,F24,F25,F26,F27,F28,F29,F30,F31,F32,F33,F34) | G10: =SUM(G11,G12,G13,G21,G22,G23,G24,G25,G26,G27,G28,G29,G30,G31,G32,G33,G34) | H10: - | I10: =SUM(I11,I12,I13,I21,I22,I23,I24,I25,I26,I27,I28,I29,I30,I31,I32,I33,I34)
A11: Нераспределенный расход | B11: =SUM(C11,D11,E11,F11) | C11: - | D11: - | E11: - | F11: - | G11: - | H11: - | I11: -
A12: Транспортные расходы | B12: =SUM(C12,D12,E12,F12) | C12: 15000 | D12: - | E12: - | F12: - | G12: - | H12: - | I12: -
A13: Переменные | B13: =SUM(B14,B15,B16,B17,B18,B19,B20) | C13: =SUM(C14,C15,C16,C17,C18,C19,C20) | D13: =SUM(D14,D15,D16,D17,D18,D19,D20) | E13: =SUM(E14,E15,E16,E17,E18,E19,E20) | F13: =SUM(F14,F15,F16,F17,F18,F19,F20) | G13: =SUM(G14,G15,G16,G17,G18,G19,G20) | H13: - | I13: =SUM(I14,I15,I16,I17,I18,I19,I20)
A14: Услуги техниги для уборки снега (ПТ) | B14: =SUM(C14,D14,E14,F14) | C14: - | D14: - | E14: - | F14: - | G14: - | H14: - | I14: -
A15: Услуги садовника (ПТ) | B15: =SUM(C15,D15,E15,F15) | C15: - | D15: - | E15: - | F15: - | G15: - | H15: - | I15: -
A16: Сыпучие материалы (ПТ) | B16: =SUM(C16,D16,E16,F16) | C16: - | D16: - | E16: - | F16: - | G16: - | H16: - | I16: -
A17: Расходные материалы и инстументы (МОП) | B17: =SUM(C17,D17,E17,F17) | C17: 525 | D17: 3000 | E17: 3000 | F17: 3000 | G17: - | H17: - | I17: -
A18: Расходные материалы и инстументы (ПТ) | B18: =SUM(C18,D18,E18,F18) | C18: 33381 | D18: 5000 | E18: 5000 | F18: 5000 | G18: - | H18: - | I18: -
A19: Арена оборудования (ПТ) | B19: =SUM(C19,D19,E19,F19) | C19: 18000 | D19: - | E19: - | F19: - | G19: - | H19: - | I19: -
A20: Арена оборудования (МОП) | B20: =SUM(C20,D20,E20,F20) | C20: - | D20: - | E20: - | F20: - | G20: - | H20: - | I20: -
A21: Заработная плата (МОП) | B21: =SUM(C21,D21,E21,F21) | C21: 264000 | D21: 264000 | E21: 264000 | F21: 264000 | G21: - | H21: - | I21: -
A22: Заработная плата (ПТ) | B22: =SUM(C22,D22,E22,F22) | C22: 532778 | D22: 350000 | E22: 350000 | F22: 350000 | G22: - | H22: - | I22: -
A23: Налоги с ФОТ (МОП) | B23: =SUM(C23,D23,E23,F23) | C23: 11052.57 | D23: 14000 | E23: 14000 | F23: 14000 | G23: - | H23: - | I23: -
A24: Налоги с ФОТ (ПТ) | B24: =SUM(C24,D24,E24,F24) | C24: - | D24: - | E24: - | F24: - | G24: - | H24: - | I24: -
A25: Премми (МОП) | B25: =SUM(C25,D25,E25,F25) | C25: - | D25: - | E25: - | F25: - | G25: - | H25: - | I25: -
A26: Премми (ПТ) | B26: =SUM(C26,D26,E26,F26) | C26: - | D26: - | E26: - | F26: - | G26: - | H26: - | I26: -
A27: Униформа (МОП) | B27: =SUM(C27,D27,E27,F27) | C27: - | D27: - | E27: - | F27: - | G27: - | H27: - | I27: -
A28: Униформа (ПТ) | B28: =SUM(C28,D28,E28,F28) | C28: - | D28: - | E28: - | F28: - | G28: - | H28: - | I28: -
A29: Ремонт оборудования (МОП) | B29: =SUM(C29,D29,E29,F29) | C29: - | D29: - | E29: - | F29: - | G29: - | H29: - | I29: -
A30: Ремонт оборудования (ПТ) | B30: =SUM(C30,D30,E30,F30) | C30: - | D30: - | E30: - | F30: - | G30: - | H30: - | I30: -
A31: Вывоз мусора | B31: =SUM(C31,D31,E31,F31) | C31: - | D31: - | E31: - | F31: - | G31: - | H31: - | I31: -
A32: Штрафы, пени, неустойки | B32: =SUM(C32,D32,E32,F32) | C32: - | D32: - | E32: - | F32: - | G32: - | H32: - | I32: -
A33: Расходы к удержанию | B33: =SUM(C33,D33,E33,F33) | C33: - | D33: - | E33: - | F33: - | G33: - | H33: - | I33: -
A34: Общехозяйственные | B34: =SUM(B35,B36,B37,B38,B39,B40,B41,B42) | C34: =SUM(C35,C36,C37,C38,C39,C40,C41,C42) | D34: =SUM(D35,D36,D37,D38,D39,D40,D41,D42) | E34: =SUM(E35,E36,E37,E38,E39,E40,E41,E42) | F34: =SUM(F35,F36,F37,F38,F39,F40,F41,F42) | G34: =SUM(G35,G36,G37,G38,G39,G40,G41,G42) | H34: - | I34: =SUM(I35,I36,I37,I38,I39,I40,I41,I42)
A35: Аутсорс (направления) | B35: =SUM(C35,D35,E35,F35) | C35: 12500 | D35: 10000 | E35: 5000 | F35: 5000 | G35: - | H35: - | I35: -
A36: Заработная плата МО АУП | B36: =SUM(C36,D36,E36,F36) | C36: 120000 | D36: 120000 | E36: 120000 | F36: 120000 | G36: - | H36: - | I36: -
A37: Инструменты: ГСМ | B37: =SUM(C37,D37,E37,F37) | C37: 2000 | D37: 2000 | E37: 2000 | F37: 2000 | G37: - | H37: - | I37: -
A38: Медосмотры | B38: =SUM(C38,D38,E38,F38) | C38: - | D38: - | E38: - | F38: - | G38: - | H38: - | I38: -
A39: Налоги с ФОТ (ИП) | B39: =SUM(C39,D39,E39,F39) | C39: 51450 | D39: 51450 | E39: 51450 | F39: 51450 | G39: - | H39: - | I39: -
A40: Приобритение мебели, бытовой техники | B40: =SUM(C40,D40,E40,F40) | C40: - | D40: - | E40: - | F40: - | G40: - | H40: - | I40: -
...
