Workbook

Sheet Группа 1
A1: ПланФакт | B1: Создано с помощью сервиса ПланФакт | I1: =HYPERLINK("https://app.planfact.io/?from=Pf_BDR", "Перейти в сервис")
B2: Итого | C2: июнь` 26 | D2: июль` 26 | E2: август` 26 | F2: сентябрь` 26 | G2: октябрь` 26 | H2: ноябрь` 26 | I2: декабрь` 26
A3: Сводный бюджет — Астон.Движение, Астон.Реформа, Милый дом, River Park | B3: план | C3: план | D3: план | E3: план | F3: план | G3: план | H3: план | I3: план
A4: Выручка | B4: =SUM(B5,B6) | C4: =SUM(C5,C6) | D4: =SUM(D5,D6) | E4: =SUM(E5,E6) | F4: =SUM(F5,F6) | G4: =SUM(G5,G6) | H4: - | I4: =SUM(I5,I6)
A5: Нераспределенный доход | B5: =SUM('Астон.Движение'!B5,'Астон.Реформа'!B5,'Милый дом'!B5,'River Park'!B5) | C5: =SUM('Астон.Движение'!C5,'Астон.Реформа'!C5,'Милый дом'!C5,'River Park'!C5) | D5: =SUM('Астон.Движение'!D5,'Астон.Реформа'!D5,'Милый дом'!D5,'River Park'!D5) | E5: =SUM('Астон.Движение'!E5,'Астон.Реформа'!E5,'Милый дом'!E5,'River Park'!E5) | F5: =SUM('Астон.Движение'!F5,'Астон.Реформа'!F5,'Милый дом'!F5,'River Park'!F5) | G5: =SUM('Астон.Движение'!G5,'Астон.Реформа'!G5,'Милый дом'!G5,'River Park'!G5) | H5: - | I5: =SUM('Астон.Движение'!I5,'Астон.Реформа'!I5,'Милый дом'!I5,'River Park'!I5)
A6: Выручка | B6: =SUM(B7,B8,B9) | C6: =SUM(C7,C8,C9) | D6: =SUM(D7,D8,D9) | E6: =SUM(E7,E8,E9) | F6: =SUM(F7,F8,F9) | G6: =SUM(G7,G8,G9) | H6: - | I6: =SUM(I7,I8,I9)
A7: Реализация услуг Клининг (ОД) | B7: =SUM('Астон.Движение'!B7,'Астон.Реформа'!B7,'Милый дом'!B7,'River Park'!B7) | C7: =SUM('Астон.Движение'!C7,'Астон.Реформа'!C7,'Милый дом'!C7,'River Park'!C7) | D7: =SUM('Астон.Движение'!D7,'Астон.Реформа'!D7,'Милый дом'!D7,'River Park'!D7) | E7: =SUM('Астон.Движение'!E7,'Астон.Реформа'!E7,'Милый дом'!E7,'River Park'!E7) | F7: =SUM('Астон.Движение'!F7,'Астон.Реформа'!F7,'Милый дом'!F7,'River Park'!F7) | G7: =SUM('Астон.Движение'!G7,'Астон.Реформа'!G7,'Милый дом'!G7,'River Park'!G7) | H7: - | I7: =SUM('Астон.Движение'!I7,'Астон.Реформа'!I7,'Милый дом'!I7,'River Park'!I7)
A8: Реализация услуг Клининг (Доп.услуги) | B8: =SUM('Астон.Движение'!B8,'Астон.Реформа'!B8,'Милый дом'!B8,'River Park'!B8) | C8: =SUM('Астон.Движение'!C8,'Астон.Реформа'!C8,'Милый дом'!C8,'River Park'!C8) | D8: =SUM('Астон.Движение'!D8,'Астон.Реформа'!D8,'Милый дом'!D8,'River Park'!D8) | E8: =SUM('Астон.Движение'!E8,'Астон.Реформа'!E8,'Милый дом'!E8,'River Park'!E8) | F8: =SUM('Астон.Движение'!F8,'Астон.Реформа'!F8,'Милый дом'!F8,'River Park'!F8) | G8: =SUM('Астон.Движение'!G8,'Астон.Реформа'!G8,'Милый дом'!G8,'River Park'!G8) | H8: - | I8: =SUM('Астон.Движение'!I8,'Астон.Реформа'!I8,'Милый дом'!I8,'River Park'!I8)
A9: Реализация услуг Клининг (снег) | B9: =SUM('Астон.Движение'!B9,'Астон.Реформа'!B9,'Милый дом'!B9,'River Park'!B9) | C9: =SUM('Астон.Движение'!C9,'Астон.Реформа'!C9,'Милый дом'!C9,'River Park'!C9) | D9: =SUM('Астон.Движение'!D9,'Астон.Реформа'!D9,'Милый дом'!D9,'River Park'!D9) | E9: =SUM('Астон.Движение'!E9,'Астон.Реформа'!E9,'Милый дом'!E9,'River Park'!E9) | F9: =SUM('Астон.Движение'!F9,'Астон.Реформа'!F9,'Милый дом'!F9,'River Park'!F9) | G9: =SUM('Астон.Движение'!G9,'Астон.Реформа'!G9,'Милый дом'!G9,'River Park'!G9) | H9: - | I9: =SUM('Астон.Движение'!I9,'Астон.Реформа'!I9,'Милый дом'!I9,'River Park'!I9)
A10: Прямые расходы | B10: =SUM(B11,B12,B13,B21,B22,B23,B24,B25,B26,B27,B28,B29,B30,B31,B32,B33,B34) | C10: =SUM(C11,C12,C13,C21,C22,C23,C24,C25,C26,C27,C28,C29,C30,C31,C32,C33,C34) | D10: =SUM(D11,D12,D13,D21,D22,D23,D24,D25,D26,D27,D28,D29,D30,D31,D32,D33,D34) | E10: =SUM(E11,E12,E13,E21,E22,E23,E24,E25,E26,E27,E28,E29,E30,E31,E32,E33,E34) | F10: =SUM(F11,F12,F13,F21,F22,F23,F24,F25,F26,F27,F28,F29,F30,F31,F32,F33,F34) | G10: =SUM(G11,G12,G13,G21,G22,G23,G24,G25,G26,G27,G28,G29,G30,G31,G32,G33,G34) | H10: - | I10: =SUM(I11,I12,I13,I21,I22,I23,I24,I25,I26,I27,I28,I29,I30,I31,I32,I33,I34)
A11: Нераспределенный расход | B11: =SUM('Астон.Движение'!B11,'Астон.Реформа'!B11,'Милый дом'!B11,'River Park'!B11) | C11: =SUM('Астон.Движение'!C11,'Астон.Реформа'!C11,'Милый дом'!C11,'River Park'!C11) | D11: =SUM('Астон.Движение'!D11,'Астон.Реформа'!D11,'Милый дом'!D11,'River Park'!D11) | E11: =SUM('Астон.Движение'!E11,'Астон.Реформа'!E11,'Милый дом'!E11,'River Park'!E11) | F11: =SUM('Астон.Движение'!F11,'Астон.Реформа'!F11,'Милый дом'!F11,'River Park'!F11) | G11: =SUM('Астон.Движение'!G11,'Астон.Реформа'!G11,'Милый дом'!G11,'River Park'!G11) | H11: - | I11: =SUM('Астон.Движение'!I11,'Астон.Реформа'!I11,'Милый дом'!I11,'River Park'!I11)
A12: Транспортные расходы | B12: =SUM('Астон.Движение'!B12,'Астон.Реформа'!B12,'Милый дом'!B12,'River Park'!B12) | C12: =SUM('Астон.Движение'!C12,'Астон.Реформа'!C12,'Милый дом'!C12,'River Park'!C12) | D12: =SUM('Астон.Движение'!D12,'Астон.Реформа'!D12,'Милый дом'!D12,'River Park'!D12) | E12: =SUM('Астон.Движение'!E12,'Астон.Реформа'!E12,'Милый дом'!E12,'River Park'!E12) | F12: =SUM('Астон.Движение'!F12,'Астон.Реформа'!F12,'Милый дом'!F12,'River Park'!F12) | G12: =SUM('Астон.Движение'!G12,'Астон.Реформа'!G12,'Милый дом'!G12,'River Park'!G12) | H12: - | I12: =SUM('Астон.Движение'!I12,'Астон.Реформа'!I12,'Милый дом'!I12,'River Park'!I12)
A13: Переменные | B13: =SUM(B14,B15,B16,B17,B18,B19,B20) | C13: =SUM(C14,C15,C16,C17,C18,C19,C20) | D13: =SUM(D14,D15,D16,D17,D18,D19,D20) | E13: =SUM(E14,E15,E16,E17,E18,E19,E20) | F13: =SUM(F14,F15,F16,F17,F18,F19,F20) | G13: =SUM(G14,G15,G16,G17,G18,G19,G20) | H13: - | I13: =SUM(I14,I15,I16,I17,I18,I19,I20)
A14: Услуги техниги для уборки снега (ПТ) | B14: =SUM('Астон.Движение'!B14,'Астон.Реформа'!B14,'Милый дом'!B14,'River Park'!B14) | C14: =SUM('Астон.Движение'!C14,'Астон.Реформа'!C14,'Милый дом'!C14,'River Park'!C14) | D14: =SUM('Астон.Движение'!D14,'Астон.Реформа'!D14,'Милый дом'!D14,'River Park'!D14) | E14: =SUM('Астон.Движение'!E14,'Астон.Реформа'!E14,'Милый дом'!E14,'River Park'!E14) | F14: =SUM('Астон.Движение'!F14,'Астон.Реформа'!F14,'Милый дом'!F14,'River Park'!F14) | G14: =SUM('Астон.Движение'!G14,'Астон.Реформа'!G14,'Милый дом'!G14,'River Park'!G14) | H14: - | I14: =SUM('Астон.Движение'!I14,'Астон.Реформа'!I14,'Милый дом'!I14,'River Park'!I14)
A15: Услуги садовника (ПТ) | B15: =SUM('Астон.Движение'!B15,'Астон.Реформа'!B15,'Милый дом'!B15,'River Park'!B15) | C15: =SUM('Астон.Движение'!C15,'Астон.Реформа'!C15,'Милый дом'!C15,'River Park'!C15) | D15: =SUM('Астон.Движение'!D15,'Астон.Реформа'!D15,'Милый дом'!D15,'River Park'!D15) | E15: =SUM('Астон.Движение'!E15,'Астон.Реформа'!E15,'Милый дом'!E15,'River Park'!E15) | F15: =SUM('Астон.Движение'!F15,'Астон.Реформа'!F15,'Милый дом'!F15,'River Park'!F15) | G15: =SUM('Астон.Движение'!G15,'Астон.Реформа'!G15,'Милый дом'!G15,'River Park'!G15) | H15: - | I15: =SUM('Астон.Движение'!I15,'Астон.Реформа'!I15,'Милый дом'!I15,'River Park'!I15)
A16: Сыпучие материалы (ПТ) | B16: =SUM('Астон.Движение'!B16,'Астон.Реформа'!B16,'Милый дом'!B16,'River Park'!B16) | C16: =SUM('Астон.Движение'!C16,'Астон.Реформа'!C16,'Милый дом'!C16,'River Park'!C16) | D16: =SUM('Астон.Движение'!D16,'Астон.Реформа'!D16,'Милый дом'!D16,'River Park'!D16) | E16: =SUM('Астон.Движение'!E16,'Астон.Реформа'!E16,'Милый дом'!E16,'River Park'!E16) | F16: =SUM('Астон.Движение'!F16,'Астон.Реформа'!F16,'Милый дом'!F16,'River Park'!F16) | G16: =SUM('Астон.Движение'!G16,'Астон.Реформа'!G16,'Милый дом'!G16,'River Park'!G16) | H16: - | I16: =SUM('Астон.Движение'!I16,'Астон.Реформа'!I16,'Милый дом'!I16,'River Park'!I16)
A17: Расходные материалы и инстументы (МОП) | B17: =SUM('Астон.Движение'!B17,'Астон.Реформа'!B17,'Милый дом'!B17,'River Park'!B17) | C17: =SUM('Астон.Движение'!C17,'Астон.Реформа'!C17,'Милый дом'!C17,'River Park'!C17) | D17: =SUM('Астон.Движение'!D17,'Астон.Реформа'!D17,'Милый дом'!D17,'River Park'!D17) | E17: =SUM('Астон.Движение'!E17,'Астон.Реформа'!E17,'Милый дом'!E17,'River Park'!E17) | F17: =SUM('Астон.Движение'!F17,'Астон.Реформа'!F17,'Милый дом'!F17,'River Park'!F17) | G17: =SUM('Астон.Движение'!G17,'Астон.Реформа'!G17,'Милый дом'!G17,'River Park'!G17) | H17: - | I17: =SUM('Астон.Движение'!I17,'Астон.Реформа'!I17,'Милый дом'!I17,'River Park'!I17)
A18: Расходные материалы и инстументы (ПТ) | B18: =SUM('Астон.Движение'!B18,'Астон.Реформа'!B18,'Милый дом'!B18,'River Park'!B18) | C18: =SUM('Астон.Движение'!C18,'Астон.Реформа'!C18,'Милый дом'!C18,'River Park'!C18) | D18: =SUM('Астон.Движение'!D18,'Астон.Реформа'!D18,'Милый дом'!D18,'River Park'!D18) | E18: =SUM('Астон.Движение'!E18,'Астон.Реформа'!E18,'Милый дом'!E18,'River Park'!E18) | F18: =SUM('Астон.Движение'!F18,'Астон.Реформа'!F18,'Милый дом'!F18,'River Park'!F18) | G18: =SUM('Астон.Движение'!G18,'Астон.Реформа'!G18,'Милый дом'!G18,'River Park'!G18) | H18: - | I18: =SUM('Астон.Движение'!I18,'Астон.Реформа'!I18,'Милый дом'!I18,'River Park'!I18)
A19: Арена оборудования (ПТ) | B19: =SUM('Астон.Движение'!B19,'Астон.Реформа'!B19,'Милый дом'!B19,'River Park'!B19) | C19: =SUM('Астон.Движение'!C19,'Астон.Реформа'!C19,'Милый дом'!C19,'River Park'!C19) | D19: =SUM('Астон.Движение'!D19,'Астон.Реформа'!D19,'Милый дом'!D19,'River Park'!D19) | E19: =SUM('Астон.Движение'!E19,'Астон.Реформа'!E19,'Милый дом'!E19,'River Park'!E19) | F19: =SUM('Астон.Движение'!F19,'Астон.Реформа'!F19,'Милый дом'!F19,'River Park'!F19) | G19: =SUM('Астон.Движение'!G19,'Астон.Реформа'!G19,'Милый дом'!G19,'River Park'!G19) | H19: - | I19: =SUM('Астон.Движение'!I19,'Астон.Реформа'!I19,'Милый дом'!I19,'River Park'!I19)
A20: Арена оборудования (МОП) | B20: =SUM('Астон.Движение'!B20,'Астон.Реформа'!B20,'Милый дом'!B20,'River Park'!B20) | C20: =SUM('Астон.Движение'!C20,'Астон.Реформа'!C20,'Милый дом'!C20,'River Park'!C20) | D20: =SUM('Астон.Движение'!D20,'Астон.Реформа'!D20,'Милый дом'!D20,'River Park'!D20) | E20: =SUM('Астон.Движение'!E20,'Астон.Реформа'!E20,'Милый дом'!E20,'River Park'!E20) | F20: =SUM('Астон.Движение'!F20,'Астон.Реформа'!F20,'Милый дом'!F20,'River Park'!F20) | G20: =SUM('Астон.Движение'!G20,'Астон.Реформа'!G20,'Милый дом'!G20,'River Park'!G20) | H20: - | I20: =SUM('Астон.Движение'!I20,'Астон.Реформа'!I20,'Милый дом'!I20,'River Park'!I20)
A21: Заработная плата (МОП) | B21: =SUM('Астон.Движение'!B21,'Астон.Реформа'!B21,'Милый дом'!B21,'River Park'!B21) | C21: =SUM('Астон.Движение'!C21,'Астон.Реформа'!C21,'Милый дом'!C21,'River Park'!C21) | D21: =SUM('Астон.Движение'!D21,'Астон.Реформа'!D21,'Милый дом'!D21,'River Park'!D21) | E21: =SUM('Астон.Движение'!E21,'Астон.Реформа'!E21,'Милый дом'!E21,'River Park'!E21) | F21: =SUM('Астон.Движение'!F21,'Астон.Реформа'!F21,'Милый дом'!F21,'River Park'!F21) | G21: =SUM('Астон.Движение'!G21,'Астон.Реформа'!G21,'Милый дом'!G21,'River Park'!G21) | H21: - | I21: =SUM('Астон.Движение'!I21,'Астон.Реформа'!I21,'Милый дом'!I21,'River Park'!I21)
A22: Заработная плата (ПТ) | B22: =SUM('Астон.Движение'!B22,'Астон.Реформа'!B22,'Милый дом'!B22,'River Park'!B22) | C22: =SUM('Астон.Движение'!C22,'Астон.Реформа'!C22,'Милый дом'!C22,'River Park'!C22) | D22: =SUM('Астон.Движение'!D22,'Астон.Реформа'!D22,'Милый дом'!D22,'River Park'!D22) | E22: =SUM('Астон.Движение'!E22,'Астон.Реформа'!E22,'Милый дом'!E22,'River Park'!E22) | F22: =SUM('Астон.Движение'!F22,'Астон.Реформа'!F22,'Милый дом'!F22,'River Park'!F22) | G22: =SUM('Астон.Движение'!G22,'Астон.Реформа'!G22,'Милый дом'!G22,'River Park'!G22) | H22: - | I22: =SUM('Астон.Движение'!I22,'Астон.Реформа'!I22,'Милый дом'!I22,'River Park'!I22)
A23: Налоги с ФОТ (МОП) | B23: =SUM('Астон.Движение'!B23,'Астон.Реформа'!B23,'Милый дом'!B23,'River Park'!B23) | C23: =SUM('Астон.Движение'!C23,'Астон.Реформа'!C23,'Милый дом'!C23,'River Park'!C23) | D23: =SUM('Астон.Движение'!D23,'Астон.Реформа'!D23,'Милый дом'!D23,'River Park'!D23) | E23: =SUM('Астон.Движение'!E23,'Астон.Реформа'!E23,'Милый дом'!E23,'River Park'!E23) | F23: =SUM('Астон.Движение'!F23,'Астон.Реформа'!F23,'Милый дом'!F23,'River Park'!F23) | G23: =SUM('Астон.Движение'!G23,'Астон.Реформа'!G23,'Милый дом'!G23,'River Park'!G23) | H23: - | I23: =SUM('Астон.Движение'!I23,'Астон.Реформа'!I23,'Милый дом'!I23,'River Park'!I23)
A24: Налоги с ФОТ (ПТ) | B24: =SUM('Астон.Движение'!B24,'Астон.Реформа'!B24,'Милый дом'!B24,'River Park'!B24) | C24: =SUM('Астон.Движение'!C24,'Астон.Реформа'!C24,'Милый дом'!C24,'River Park'!C24) | D24: =SUM('Астон.Движение'!D24,'Астон.Реформа'!D24,'Милый дом'!D24,'River Park'!D24) | E24: =SUM('Астон.Движение'!E24,'Астон.Реформа'!E24,'Милый дом'!E24,'River Park'!E24) | F24: =SUM('Астон.Движение'!F24,'Астон.Реформа'!F24,'Милый дом'!F24,'River Park'!F24) | G24: =SUM('Астон.Движение'!G24,'Астон.Реформа'!G24,'Милый дом'!G24,'River Park'!G24) | H24: - | I24: =SUM('Астон.Движение'!I24,'Астон.Реформа'!I24,'Милый дом'!I24,'River Park'!I24)
A25: Премми (МОП) | B25: =SUM('Астон.Движение'!B25,'Астон.Реформа'!B25,'Милый дом'!B25,'River Park'!B25) | C25: =SUM('Астон.Движение'!C25,'Астон.Реформа'!C25,'Милый дом'!C25,'River Park'!C25) | D25: =SUM('Астон.Движение'!D25,'Астон.Реформа'!D25,'Милый дом'!D25,'River Park'!D25) | E25: =SUM('Астон.Движение'!E25,'Астон.Реформа'!E25,'Милый дом'!E25,'River Park'!E25) | F25: =SUM('Астон.Движение'!F25,'Астон.Реформа'!F25,'Милый дом'!F25,'River Park'!F25) | G25: =SUM('Астон.Движение'!G25,'Астон.Реформа'!G25,'Милый дом'!G25,'River Park'!G25) | H25: - | I25: =SUM('Астон.Движение'!I25,'Астон.Реформа'!I25,'Милый дом'!I25,'River Park'!I25)
... A33: Расходы к удержанию | B33: =SUM('Астон.Движение'!B33,'Астон.Реформа'!B33,'Милый дом'!B33,'River Park'!B33) | C33: =SUM('Астон.Движение'!C33,'Астон.Реформа'!C33,'Милый дом'!C33,'River Park'!C33) | D33: =SUM('Астон.Движение'!D33,'Астон.Реформа'!D33,'Милый дом'!D33,'River Park'!D33) | E33: =SUM('Астон.Движение'!E33,'Астон.Реформа'!E33,'Милый дом'!E33,'River Park'!E33) | F33: =SUM('Астон.Движение'!F33,'Астон.Реформа'!F33,'Милый дом'!F33,'River Park'!F33) | G33: =SUM('Астон.Движение'!G33,'Астон.Реформа'!G33,'Милый дом'!G33,'River Park'!G33) | H33: - | I33: =SUM('Астон.Движение'!I33,'Астон.Реформа'!I33,'Милый дом'!I33,'River Park'!I33)
A34: Общехозяйственные | B34: =SUM(B35,B36,B37,B38,B39,B40,B41,B42) | C34: =SUM(C35,C36,C37,C38,C39,C40,C41,C42) | D34: =SUM(D35,D36,D37,D38,D39,D40,D41,D42) | E34: =SUM(E35,E36,E37,E38,E39,E40,E41,E42) | F34: =SUM(F35,F36,F37,F38,F39,F40,F41,F42) | G34: =SUM(G35,G36,G37,G38,G39,G40,G41,G42) | H34: - | I34: =SUM(I35,I36,I37,I38,I39,I40,I41,I42)
A35: Аутсорс (направления) | B35: =SUM('Астон.Движение'!B35,'Астон.Реформа'!B35,'Милый дом'!B35,'River Park'!B35) | C35: =SUM('Астон.Движение'!C35,'Астон.Реформа'!C35,'Милый дом'!C35,'River Park'!C35) | D35: =SUM('Астон.Движение'!D35,'Астон.Реформа'!D35,'Милый дом'!D35,'River Park'!D35) | E35: =SUM('Астон.Движение'!E35,'Астон.Реформа'!E35,'Милый дом'!E35,'River Park'!E35) | F35: =SUM('Астон.Движение'!F35,'Астон.Реформа'!F35,'Милый дом'!F35,'River Park'!F35) | G35: =SUM('Астон.Движение'!G35,'Астон.Реформа'!G35,'Милый дом'!G35,'River Park'!G35) | H35: - | I35: =SUM('Астон.Движение'!I35,'Астон.Реформа'!I35,'Милый дом'!I35,'River Park'!I35)
A36: Заработная плата МО АУП | B36: =SUM('Астон.Движение'!B36,'Астон.Реформа'!B36,'Милый дом'!B36,'River Park'!B36) | C36: =SUM('Астон.Движение'!C36,'Астон.Реформа'!C36,'Милый дом'!C36,'River Park'!C36) | D36: =SUM('Астон.Движение'!D36,'Астон.Реформа'!D36,'Милый дом'!D36,'River Park'!D36) | E36: =SUM('Астон.Движение'!E36,'Астон.Реформа'!E36,'Милый дом'!E36,'River Park'!E36) | F36: =SUM('Астон.Движение'!F36,'Астон.Реформа'!F36,'Милый дом'!F36,'River Park'!F36) | G36: =SUM('Астон.Движение'!G36,'Астон.Реформа'!G36,'Милый дом'!G36,'River Park'!G36) | H36: - | I36: =SUM('Астон.Движение'!I36,'Астон.Реформа'!I36,'Милый дом'!I36,'River Park'!I36)
A37: Инструменты: ГСМ | B37: =SUM('Астон.Движение'!B37,'Астон.Реформа'!B37,'Милый дом'!B37,'River Park'!B37) | C37: =SUM('Астон.Движение'!C37,'Астон.Реформа'!C37,'Милый дом'!C37,'River Park'!C37) | D37: =SUM('Астон.Движение'!D37,'Астон.Реформа'!D37,'Милый дом'!D37,'River Park'!D37) | E37: =SUM('Астон.Движение'!E37,'Астон.Реформа'!E37,'Милый дом'!E37,'River Park'!E37) | F37: =SUM('Астон.Движение'!F37,'Астон.Реформа'!F37,'Милый дом'!F37,'River Park'!F37) | G37: =SUM('Астон.Движение'!G37,'Астон.Реформа'!G37,'Милый дом'!G37,'River Park'!G37) | H37: - | I37: =SUM('Астон.Движение'!I37,'Астон.Реформа'!I37,'Милый дом'!I37,'River Park'!I37)
A38: Медосмотры | B38: =SUM('Астон.Движение'!B38,'Астон.Реформа'!B38,'Милый дом'!B38,'River Park'!B38) | C38: =SUM('Астон.Движение'!C38,'Астон.Реформа'!C38,'Милый дом'!C38,'River Park'!C38) | D38: =SUM('Астон.Движение'!D38,'Астон.Реформа'!D38,'Милый дом'!D38,'River Park'!D38) | E38: =SUM('Астон.Движение'!E38,'Астон.Реформа'!E38,'Милый дом'!E38,'River Park'!E38) | F38: =SUM('Астон.Движение'!F38,'Астон.Реформа'!F38,'Милый дом'!F38,'River Park'!F38) | G38: =SUM('Астон.Движение'!G38,'Астон.Реформа'!G38,'Милый дом'!G38,'River Park'!G38) | H38: - | I38: =SUM('Астон.Движение'!I38,'Астон.Реформа'!I38,'Милый дом'!I38,'River Park'!I38)
A39: Налоги с ФОТ (ИП) | B39: =SUM('Астон.Движение'!B39,'Астон.Реформа'!B39,'Милый дом'!B39,'River Park'!B39) | C39: =SUM('Астон.Движение'!C39,'Астон.Реформа'!C39,'Милый дом'!C39,'River Park'!C39) | D39: =SUM('Астон.Движение'!D39,'Астон.Реформа'!D39,'Милый дом'!D39,'River Park'!D39) | E39: =SUM('Астон.Движение'!E39,'Астон.Реформа'!E39,'Милый дом'!E39,'River Park'!E39) | F39: =SUM('Астон.Движение'!F39,'Астон.Реформа'!F39,'Милый дом'!F39,'River Park'!F39) | G39: =SUM('Астон.Движение'!G39,'Астон.Реформа'!G39,'Милый дом'!G39,'River Park'!G39) | H39: - | I39: =SUM('Астон.Движение'!I39,'Астон.Реформа'!I39,'Милый дом'!I39,'River Park'!I39)
A40: Приобритение мебели, бытовой техники | B40: =SUM('Астон.Движение'!B40,'Астон.Реформа'!B40,'Милый дом'!B40,'River Park'!B40) | C40: =SUM('Астон.Движение'!C40,'Астон.Реформа'!C40,'Милый дом'!C40,'River Park'!C40) | D40: =SUM('Астон.Движение'!D40,'Астон.Реформа'!D40,'Милый дом'!D40,'River Park'!D40) | E40: =SUM('Астон.Движение'!E40,'Астон.Реформа'!E40,'Милый дом'!E40,'River Park'!E40) | F40: =SUM('Астон.Движение'!F40,'Астон.Реформа'!F40,'Милый дом'!F40,'River Park'!F40) | G40: =SUM('Астон.Движение'!G40,'Астон.Реформа'!G40,'Милый дом'!G40,'River Park'!G40) | H40: - | I40: =SUM('Астон.Движение'!I40,'Астон.Реформа'!I40,'Милый дом'!I40,'River Park'!I40)
A41: Комиссия за перевод ЗП | B41: =SUM('Астон.Движение'!B41,'Астон.Реформа'!B41,'Милый дом'!B41,'River Park'!B41) | C41: =SUM('Астон.Движение'!C41,'Астон.Реформа'!C41,'Милый дом'!C41,'River Park'!C41) | D41: =SUM('Астон.Движение'!D41,'Астон.Реформа'!D41,'Милый дом'!D41,'River Park'!D41) | E41: =SUM('Астон.Движение'!E41,'Астон.Реформа'!E41,'Милый дом'!E41,'River Park'!E41) | F41: =SUM('Астон.Движение'!F41,'Астон.Реформа'!F41,'Милый дом'!F41,'River Park'!F41) | G41: =SUM('Астон.Движение'!G41,'Астон.Реформа'!G41,'Милый дом'!G41,'River Park'!G41) | H41: - | I41: =SUM('Астон.Движение'!I41,'Астон.Реформа'!I41,'Милый дом'!I41,'River Park'!I41)
A42: Аренда квартиры (включая коммуналку) | B42: =SUM('Астон.Движение'!B42,'Астон.Реформа'!B42,'Милый дом'!B42,'River Park'!B42) | C42: =SUM('Астон.Движение'!C42,'Астон.Реформа'!C42,'Милый дом'!C42,'River Park'!C42) | D42: =SUM('Астон.Движение'!D42,'Астон.Реформа'!D42,'Милый дом'!D42,'River Park'!D42) | E42: =SUM('Астон.Движение'!E42,'Астон.Реформа'!E42,'Милый дом'!E42,'River Park'!E42) | F42: =SUM('Астон.Движение'!F42,'Астон.Реформа'!F42,'Милый дом'!F42,'River Park'!F42) | G42: =SUM('Астон.Движение'!G42,'Астон.Реформа'!G42,'Милый дом'!G42,'River Park'!G42) | H42: - | I42: =SUM('Астон.Движение'!I42,'Астон.Реформа'!I42,'Милый дом'!I42,'River Park'!I42)
A43: Валовая прибыль | B43: =B4-B10 | C43: =C4-C10 | D43: =D4-D10 | E43: =E4-E10 | F43: =F4-F10 | G43: =G4-G10 | H43: - | I43: =I4-I10
A44: Валовая рентабельность | B44: =IFERROR(IF(B4=0,"-",B43/B4),"-") | C44: =IFERROR(IF(C4=0,"-",C43/C4),"-") | D44: =IFERROR(IF(D4=0,"-",D43/D4),"-") | E44: =IFERROR(IF(E4=0,"-",E43/E4),"-") | F44: =IFERROR(IF(F4=0,"-",F43/F4),"-") | G44: =IFERROR(IF(G4=0,"-",G43/G4),"-") | H44: - | I44: =IFERROR(IF(I4=0,"-",I43/I4),"-")
A45: Косвенные расходы | B45: =SUM(B46,B47,B48,B52,B56,B57,B58,B59,B60,B63,B64,B65,B66,B67,B68,B69,B70,B71,B72,B73,B74,B75,B76,B77,B78,B79) | C45: =SUM(C46,C47,C48,C52,C56,C57,C58,C59,C60,C63,C64,C65,C66,C67,C68,C69,C70,C71,C72,C73,C74,C75,C76,C77,C78,C79) | D45: =SUM(D46,D47,D48,D52,D56,D57,D58,D59,D60,D63,D64,D65,D66,D67,D68,D69,D70,D71,D72,D73,D74,D75,D76,D77,D78,D79) | E45: =SUM(E46,E47,E48,E52,E56,E57,E58,E59,E60,E63,E64,E65,E66,E67,E68,E69,E70,E71,E72,E73,E74,E75,E76,E77,E78,E79) | F45: =SUM(F46,F47,F48,F52,F56,F57,F58,F59,F60,F63,F64,F65,F66,F67,F68,F69,F70,F71,F72,F73,F74,F75,F76,F77,F78,F79) | G45: =SUM(G46,G47,G48,G52,G56,G57,G58,G59,G60,G63,G64,G65,G66,G67,G68,G69,G70,G71,G72,G73,G74,G75,G76,G77,G78,G79) | H45: - | I45: =SUM(I46,I47,I48,I52,I56,I57,I58,I59,I60,I63,I64,I65,I66,I67,I68,I69,I70,I71,I72,I73,I74,I75,I76,I77,I78,I79)
A46: Расход БЭК-ОФИС | B46: =SUM('Астон.Движение'!B46,'Астон.Реформа'!B46,'Милый дом'!B46,'River Park'!B46) | C46: =SUM('Астон.Движение'!C46,'Астон.Реформа'!C46,'Милый дом'!C46,'River Park'!C46) | D46: =SUM('Астон.Движение'!D46,'Астон.Реформа'!D46,'Милый дом'!D46,'River Park'!D46) | E46: =SUM('Астон.Движение'!E46,'Астон.Реформа'!E46,'Милый дом'!E46,'River Park'!E46) | F46: =SUM('Астон.Движение'!F46,'Астон.Реформа'!F46,'Милый дом'!F46,'River Park'!F46) | G46: =SUM('Астон.Движение'!G46,'Астон.Реформа'!G46,'Милый дом'!G46,'River Park'!G46) | H46: - | I46: =SUM('Астон.Движение'!I46,'Астон.Реформа'!I46,'Милый дом'!I46,'River Park'!I46)
A47: Расходы на бэк-офис | B47: =SUM('Астон.Движение'!B47,'Астон.Реформа'!B47,'Милый дом'!B47,'River Park'!B47) | C47: =SUM('Астон.Движение'!C47,'Астон.Реформа'!C47,'Милый дом'!C47,'River Park'!C47) | D47: =SUM('Астон.Движение'!D47,'Астон.Реформа'!D47,'Милый дом'!D47,'River Park'!D47) | E47: =SUM('Астон.Движение'!E47,'Астон.Реформа'!E47,'Милый дом'!E47,'River Park'!E47) | F47: =SUM('Астон.Движение'!F47,'Астон.Реформа'!F47,'Милый дом'!F47,'River Park'!F47) | G47: =SUM('Астон.Движение'!G47,'Астон.Реформа'!G47,'Милый дом'!G47,'River Park'!G47) | H47: - | I47: =SUM('Астон.Движение'!I47,'Астон.Реформа'!I47,'Милый дом'!I47,'River Park'!I47)
...

Sheet Астон.Движение
A1: ПланФакт | B1: Создано с помощью сервиса ПланФакт | I1: =HYPERLINK("https://app.planfact.io/?from=Pf_BDR", "Перейти в сервис")
B2: Итого | C2: июнь` 26 | D2: июль` 26 | E2: август` 26 | F2: сентябрь` 26 | G2: октябрь` 26 | H2: ноябрь` 26 | I2: декабрь` 26
A3: Астон.Движение | B3: план | C3: план | D3: план | E3: план | F3: план | G3: план | H3: план | I3: план
A4: Выручка | B4: 656000 | C4: =SUM(C5,C6) | D4: =SUM(D5,D6) | E4: =SUM(E5,E6) | F4: =SUM(F5,F6) | G4: =SUM(G5,G6) | H4: - | I4: =SUM(I5,I6)
A5: Нераспределенный доход | B5: - | C5: - | D5: - | E5: - | F5: - | G5: - | H5: - | I5: -
A6: Выручка | B6: 656000 | C6: =SUM(C7,C8,C9) | D6: =SUM(D7,D8,D9) | E6: =SUM(E7,E8,E9) | F6: =SUM(F7,F8,F9) | G6: =SUM(G7,G8,G9) | H6: - | I6: =SUM(I7,I8,I9)
A7: Реализация услуг Клининг (ОД) | B7: 656000 | C7: 164000 | D7: 164000 | E7: 164000 | F7: 164000 | G7: - | H7: - | I7: -
A8: Реализация услуг Клининг (Доп.услуги) | B8: - | C8: - | D8: - | E8: - | F8: - | G8: - | H8: - | I8: -
A9: Реализация услуг Клининг (снег) | B9: - | C9: - | D9: - | E9: - | F9: - | G9: - | H9: - | I9: -
A10: Прямые расходы | B10: 530680.45 | C10: =SUM(C11,C12,C13,C21,C22,C23,C24,C25,C26,C27,C28,C29,C30,C31,C32,C33,C34) | D10: =SUM(D11,D12,D13,D21,D22,D23,D24,D25,D26,D27,D28,D29,D30,D31,D32,D33,D34) | E10: =SUM(E11,E12,E13,E21,E22,E23,E24,E25,E26,E27,E28,E29,E30,E31,E32,E33,E34) | F10: =SUM(F11,F12,F13,F21,F22,F23,F24,F25,F26,F27,F28,F29,F30,F31,F32,F33,F34) | G10: =SUM(G11,G12,G13,G21,G22,G23,G24,G25,G26,G27,G28,G29,G30,G31,G32,G33,G34) | H10: - | I10: =SUM(I11,I12,I13,I21,I22,I23,I24,I25,I26,I27,I28,I29,I30,I31,I32,I33,I34)
A11: Нераспределенный расход | B11: - | C11: - | D11: - | E11: - | F11: - | G11: - | H11: - | I11: -
A12: Транспортные расходы | B12: 1486 | C12: 1486 | D12: - | E12: - | F12: - | G12: - | H12: - | I12: -
A13: Переменные | B13: 15262 | C13: =SUM(C14,C15,C16,C17,C18,C19,C20) | D13: =SUM(D14,D15,D16,D17,D18,D19,D20) | E13: =SUM(E14,E15,E16,E17,E18,E19,E20) | F13: =SUM(F14,F15,F16,F17,F18,F19,F20) | G13: =SUM(G14,G15,G16,G17,G18,G19,G20) | H13: - | I13: =SUM(I14,I15,I16,I17,I18,I19,I20)
A14: Услуги техниги для уборки снега (ПТ) | B14: - | C14: - | D14: - | E14: - | F14: - | G14: - | H14: - | I14: -
A15: Услуги садовника (ПТ) | B15: - | C15: - | D15: - | E15: - | F15: - | G15: - | H15: - | I15: -
A16: Сыпучие материалы (ПТ) | B16: - | C16: - | D16: - | E16: - | F16: - | G16: - | H16: - | I16: -
A17: Расходные материалы и инстументы (МОП) | B17: 8000 | C17: 2000 | D17: 2000 | E17: 2000 | F17: 2000 | G17: - | H17: - | I17: -
A18: Расходные материалы и инстументы (ПТ) | B18: 7262 | C18: 1262 | D18: 2000 | E18: 2000 | F18: 2000 | G18: - | H18: - | I18: -
A19: Арена оборудования (ПТ) | B19: - | C19: - | D19: - | E19: - | F19: - | G19: - | H19: - | I19: -
A20: Арена оборудования (МОП) | B20: - | C20: - | D20: - | E20: - | F20: - | G20: - | H20: - | I20: -
A21: Заработная плата (МОП) | B21: 200000 | C21: 50000 | D21: 50000 | E21: 50000 | F21: 50000 | G21: - | H21: - | I21: -
A22: Заработная плата (ПТ) | B22: 280000 | C22: 70000 | D22: 70000 | E22: 70000 | F22: 70000 | G22: - | H22: - | I22: -
A23: Налоги с ФОТ (МОП) | B23: - | C23: - | D23: - | E23: - | F23: - | G23: - | H23: - | I23: -
A24: Налоги с ФОТ (ПТ) | B24: - | C24: - | D24: - | E24: - | F24: - | G24: - | H24: - | I24: -
A25: Премми (МОП) | B25: - | C25: - | D25: - | E25: - | F25: - | G25: - | H25: - | I25: -
A26: Премми (ПТ) | B26: - | C26: - | D26: - | E26: - | F26: - | G26: - | H26: - | I26: -
A27: Униформа (МОП) | B27: - | C27: - | D27: - | E27: - | F27: - | G27: - | H27: - | I27: -
A28: Униформа (ПТ) | B28: - | C28: - | D28: - | E28: - | F28: - | G28: - | H28: - | I28: -
A29: Ремонт оборудования (МОП) | B29: - | C29: - | D29: - | E29: - | F29: - | G29: - | H29: - | I29: -
A30: Ремонт оборудования (ПТ) | B30: - | C30: - | D30: - | E30: - | F30: - | G30: - | H30: - | I30: -
A31: Вывоз мусора | B31: - | C31: - | D31: - | E31: - | F31: - | G31: - | H31: - | I31: -
A32: Штрафы, пени, неустойки | B32: - | C32: - | D32: - | E32: - | F32: - | G32: - | H32: - | I32: -
A33: Расходы к удержанию | B33: - | C33: - | D33: - | E33: - | F33: - | G33: - | H33: - | I33: -
A34: Общехозяйственные | B34: 33932.45 | C34: =SUM(C35,C36,C37,C38,C39,C40,C41,C42) | D34: =SUM(D35,D36,D37,D38,D39,D40,D41,D42) | E34: =SUM(E35,E36,E37,E38,E39,E40,E41,E42) | F34: =SUM(F35,F36,F37,F38,F39,F40,F41,F42) | G34: =SUM(G35,G36,G37,G38,G39,G40,G41,G42) | H34: - | I34: =SUM(I35,I36,I37,I38,I39,I40,I41,I42)
A35: Аутсорс (направления) | B35: - | C35: - | D35: - | E35: - | F35: - | G35: - | H35: - | I35: -
A36: Заработная плата МО АУП | B36: - | C36: - | D36: - | E36: - | F36: - | G36: - | H36: - | I36: -
A37: Инструменты: ГСМ | B37: 332.45 | C37: 332.45 | D37: - | E37: - | F37: - | G37: - | H37: - | I37: -
A38: Медосмотры | B38: - | C38: - | D38: - | E38: - | F38: - | G38: - | H38: - | I38: -
A39: Налоги с ФОТ (ИП) | B39: 33600 | C39: 8400 | D39: 8400 | E39: 8400 | F39: 8400 | G39: - | H39: - | I39: -
A40: Приобритение мебели, бытовой техники | B40: - | C40: - | D40: - | E40: - | F40: - | G40: - | H40: - | I40: -
...

Sheet Астон.Реформа
A1: ПланФакт | B1: Создано с помощью сервиса ПланФакт | I1: =HYPERLINK("https://app.planfact.io/?from=Pf_BDR", "Перейти в сервис")
B2: Итого | C2: июнь` 26 | D2: июль` 26 | E2: август` 26 | F2: сентябрь` 26 | G2: октябрь` 26 | H2: ноябрь` 26 | I2: декабрь` 26
A3: Астон.Реформа | B3: план | C3: план | D3: план | E3: план | F3: план | G3: план | H3: план | I3: план
A4: Выручка | B4: 384000 | C4: =SUM(C5,C6) | D4: =SUM(D5,D6) | E4: =SUM(E5,E6) | F4: =SUM(F5,F6) | G4: =SUM(G5,G6) | H4: - | I4: =SUM(I5,I6)
A5: Нераспределенный доход | B5: - | C5: - | D5: - | E5: - | F5: - | G5: - | H5: - | I5: -
A6: Выручка | B6: 384000 | C6: =SUM(C7,C8,C9) | D6: =SUM(D7,D8,D9) | E6: =SUM(E7,E8,E9) | F6: =SUM(F7,F8,F9) | G6: =SUM(G7,G8,G9) | H6: - | I6: =SUM(I7,I8,I9)
A7: Реализация услуг Клининг (ОД) | B7: 384000 | C7: 96000 | D7: 96000 | E7: 96000 | F7: 96000 | G7: - | H7: - | I7: -
A8: Реализация услуг Клининг (Доп.услуги) | B8: - | C8: - | D8: - | E8: - | F8: - | G8: - | H8: - | I8: -
A9: Реализация услуг Клининг (снег) | B9: - | C9: - | D9: - | E9: - | F9: - | G9: - | H9: - | I9: -
A10: Прямые расходы | B10: 350000 | C10: =SUM(C11,C12,C13,C21,C22,C23,C24,C25,C26,C27,C28,C29,C30,C31,C32,C33,C34) | D10: =SUM(D11,D12,D13,D21,D22,D23,D24,D25,D26,D27,D28,D29,D30,D31,D32,D33,D34) | E10: =SUM(E11,E12,E13,E21,E22,E23,E24,E25,E26,E27,E28,E29,E30,E31,E32,E33,E34) | F10: =SUM(F11,F12,F13,F21,F22,F23,F24,F25,F26,F27,F28,F29,F30,F31,F32,F33,F34) | G10: =SUM(G11,G12,G13,G21,G22,G23,G24,G25,G26,G27,G28,G29,G30,G31,G32,G33,G34) | H10: - | I10: =SUM(I11,I12,I13,I21,I22,I23,I24,I25,I26,I27,I28,I29,I30,I31,I32,I33,I34)
A11: Нераспределенный расход | B11: - | C11: - | D11: - | E11: - | F11: - | G11: - | H11: - | I11: -
A12: Транспортные расходы | B12: - | C12: - | D12: - | E12: - | F12: - | G12: - | H12: - | I12: -
A13: Переменные | B13: 16000 | C13: =SUM(C14,C15,C16,C17,C18,C19,C20) | D13: =SUM(D14,D15,D16,D17,D18,D19,D20) | E13: =SUM(E14,E15,E16,E17,E18,E19,E20) | F13: =SUM(F14,F15,F16,F17,F18,F19,F20) | G13: =SUM(G14,G15,G16,G17,G18,G19,G20) | H13: - | I13: =SUM(I14,I15,I16,I17,I18,I19,I20)
A14: Услуги техниги для уборки снега (ПТ) | B14: - | C14: - | D14: - | E14: - | F14: - | G14: - | H14: - | I14: -
A15: Услуги садовника (ПТ) | B15: - | C15: - | D15: - | E15: - | F15: - | G15: - | H15: - | I15: -
A16: Сыпучие материалы (ПТ) | B16: - | C16: - | D16: - | E16: - | F16: - | G16: - | H16: - | I16: -
A17: Расходные материалы и инстументы (МОП) | B17: 8000 | C17: 2000 | D17: 2000 | E17: 2000 | F17: 2000 | G17: - | H17: - | I17: -
A18: Расходные материалы и инстументы (ПТ) | B18: 8000 | C18: 2000 | D18: 2000 | E18: 2000 | F18: 2000 | G18: - | H18: - | I18: -
A19: Арена оборудования (ПТ) | B19: - | C19: - | D19: - | E19: - | F19: - | G19: - | H19: - | I19: -
A20: Арена оборудования (МОП) | B20: - | C20: - | D20: - | E20: - | F20: - | G20: - | H20: - | I20: -
A21: Заработная плата (МОП) | B21: 140000 | C21: 35000 | D21: 35000 | E21: 35000 | F21: 35000 | G21: - | H21: - | I21: -
A22: Заработная плата (ПТ) | B22: 140000 | C22: 35000 | D22: 35000 | E22: 35000 | F22: 35000 | G22: - | H22: - | I22: -
A23: Налоги с ФОТ (МОП) | B23: 42000 | C23: - | D23: 14000 | E23: 14000 | F23: 14000 | G23: - | H23: - | I23: -
A24: Налоги с ФОТ (ПТ) | B24: - | C24: - | D24: - | E24: - | F24: - | G24: - | H24: - | I24: -
A25: Премми (МОП) | B25: - | C25: - | D25: - | E25: - | F25: - | G25: - | H25: - | I25: -
A26: Премми (ПТ) | B26: - | C26: - | D26: - | E26: - | F26: - | G26: - | H26: - | I26: -
A27: Униформа (МОП) | B27: - | C27: - | D27: - | E27: - | F27: - | G27: - | H27: - | I27: -
A28: Униформа (ПТ) | B28: - | C28: - | D28: - | E28: - | F28: - | G28: - | H28: - | I28: -
A29: Ремонт оборудования (МОП) | B29: - | C29: - | D29: - | E29: - | F29: - | G29: - | H29: - | I29: -
A30: Ремонт оборудования (ПТ) | B30: - | C30: - | D30: - | E30: - | F30: - | G30: - | H30: - | I30: -
A31: Вывоз мусора | B31: - | C31: - | D31: - | E31: - | F31: - | G31: - | H31: - | I31: -
A32: Штрафы, пени, неустойки | B32: - | C32: - | D32: - | E32: - | F32: - | G32: - | H32: - | I32: -
A33: Расходы к удержанию | B33: - | C33: - | D33: - | E33: - | F33: - | G33: - | H33: - | I33: -
A34: Общехозяйственные | B34: 12000 | C34: =SUM(C35,C36,C37,C38,C39,C40,C41,C42) | D34: =SUM(D35,D36,D37,D38,D39,D40,D41,D42) | E34: =SUM(E35,E36,E37,E38,E39,E40,E41,E42) | F34: =SUM(F35,F36,F37,F38,F39,F40,F41,F42) | G34: =SUM(G35,G36,G37,G38,G39,G40,G41,G42) | H34: - | I34: =SUM(I35,I36,I37,I38,I39,I40,I41,I42)
A35: Аутсорс (направления) | B35: - | C35: - | D35: - | E35: - | F35: - | G35: - | H35: - | I35: -
A36: Заработная плата МО АУП | B36: - | C36: - | D36: - | E36: - | F36: - | G36: - | H36: - | I36: -
A37: Инструменты: ГСМ | B37: - | C37: - | D37: - | E37: - | F37: - | G37: - | H37: - | I37: -
A38: Медосмотры | B38: - | C38: - | D38: - | E38: - | F38: - | G38: - | H38: - | I38: -
A39: Налоги с ФОТ (ИП) | B39: 12000 | C39: 3000 | D39: 3000 | E39: 3000 | F39: 3000 | G39: - | H39: - | I39: -
A40: Приобритение мебели, бытовой техники | B40: - | C40: - | D40: - | E40: - | F40: - | G40: - | H40: - | I40: -
...

Sheet Милый дом
A1: ПланФакт | B1: Создано с помощью сервиса ПланФакт | I1: =HYPERLINK("https://app.planfact.io/?from=Pf_BDR", "Перейти в сервис")
B2: Итого | C2: июнь` 26 | D2: июль` 26 | E2: август` 26 | F2: сентябрь` 26 | G2: октябрь` 26 | H2: ноябрь` 26 | I2: декабрь` 26
A3: Милый дом | B3: план | C3: план | D3: план | E3: план | F3: план | G3: план | H3: план | I3: план
A4: Выручка | B4: 2451750.6 | C4: =SUM(C5,C6) | D4: =SUM(D5,D6) | E4: =SUM(E5,E6) | F4: =SUM(F5,F6) | G4: =SUM(G5,G6) | H4: - | I4: =SUM(I5,I6)
A5: Нераспределенный доход | B5: - | C5: - | D5: - | E5: - | F5: - | G5: - | H5: - | I5: -
A6: Выручка | B6: 2451750.6 | C6: =SUM(C7,C8,C9) | D6: =SUM(D7,D8,D9) | E6: =SUM(E7,E8,E9) | F6: =SUM(F7,F8,F9) | G6: =SUM(G7,G8,G9) | H6: - | I6: =SUM(I7,I8,I9)
A7: Реализация услуг Клининг (ОД) | B7: 2451750.6 | C7: 373920.6 | D7: 692610 | E7: 692610 | F7: 692610 | G7: - | H7: - | I7: -
A8: Реализация услуг Клининг (Доп.услуги) | B8: - | C8: - | D8: - | E8: - | F8: - | G8: - | H8: - | I8: -
A9: Реализация услуг Клининг (снег) | B9: - | C9: - | D9: - | E9: - | F9: - | G9: - | H9: - | I9: -
A10: Прямые расходы | B10: 1028537.7 | C10: =SUM(C11,C12,C13,C21,C22,C23,C24,C25,C26,C27,C28,C29,C30,C31,C32,C33,C34) | D10: =SUM(D11,D12,D13,D21,D22,D23,D24,D25,D26,D27,D28,D29,D30,D31,D32,D33,D34) | E10: =SUM(E11,E12,E13,E21,E22,E23,E24,E25,E26,E27,E28,E29,E30,E31,E32,E33,E34) | F10: =SUM(F11,F12,F13,F21,F22,F23,F24,F25,F26,F27,F28,F29,F30,F31,F32,F33,F34) | G10: =SUM(G11,G12,G13,G21,G22,G23,G24,G25,G26,G27,G28,G29,G30,G31,G32,G33,G34) | H10: - | I10: =SUM(I11,I12,I13,I21,I22,I23,I24,I25,I26,I27,I28,I29,I30,I31,I32,I33,I34)
A11: Нераспределенный расход | B11: - | C11: - | D11: - | E11: - | F11: - | G11: - | H11: - | I11: -
A12: Транспортные расходы | B12: - | C12: - | D12: - | E12: - | F12: - | G12: - | H12: - | I12: -
A13: Переменные | B13: 170000 | C13: =SUM(C14,C15,C16,C17,C18,C19,C20) | D13: =SUM(D14,D15,D16,D17,D18,D19,D20) | E13: =SUM(E14,E15,E16,E17,E18,E19,E20) | F13: =SUM(F14,F15,F16,F17,F18,F19,F20) | G13: =SUM(G14,G15,G16,G17,G18,G19,G20) | H13: - | I13: =SUM(I14,I15,I16,I17,I18,I19,I20)
A14: Услуги техниги для уборки снега (ПТ) | B14: - | C14: - | D14: - | E14: - | F14: - | G14: - | H14: - | I14: -
A15: Услуги садовника (ПТ) | B15: - | C15: - | D15: - | E15: - | F15: - | G15: - | H15: - | I15: -
A16: Сыпучие материалы (ПТ) | B16: - | C16: - | D16: - | E16: - | F16: - | G16: - | H16: - | I16: -
A17: Расходные материалы и инстументы (МОП) | B17: 120000 | C17: - | D17: 40000 | E17: 40000 | F17: 40000 | G17: - | H17: - | I17: -
A18: Расходные материалы и инстументы (ПТ) | B18: 20000 | C18: 5000 | D18: 5000 | E18: 5000 | F18: 5000 | G18: - | H18: - | I18: -
A19: Арена оборудования (ПТ) | B19: - | C19: - | D19: - | E19: - | F19: - | G19: - | H19: - | I19: -
A20: Арена оборудования (МОП) | B20: 30000 | C20: 30000 | D20: - | E20: - | F20: - | G20: - | H20: - | I20: -
A21: Заработная плата (МОП) | B21: 200000 | C21: 50000 | D21: 50000 | E21: 50000 | F21: 50000 | G21: - | H21: - | I21: -
A22: Заработная плата (ПТ) | B22: 452500 | C22: 62500 | D22: 130000 | E22: 130000 | F22: 130000 | G22: - | H22: - | I22: -
A23: Налоги с ФОТ (МОП) | B23: 45037.68 | C23: 3037.68 | D23: 14000 | E23: 14000 | F23: 14000 | G23: - | H23: - | I23: -
A24: Налоги с ФОТ (ПТ) | B24: - | C24: - | D24: - | E24: - | F24: - | G24: - | H24: - | I24: -
A25: Премми (МОП) | B25: - | C25: - | D25: - | E25: - | F25: - | G25: - | H25: - | I25: -
A26: Премми (ПТ) | B26: - | C26: - | D26: - | E26: - | F26: - | G26: - | H26: - | I26: -
A27: Униформа (МОП) | B27: - | C27: - | D27: - | E27: - | F27: - | G27: - | H27: - | I27: -
A28: Униформа (ПТ) | B28: - | C28: - | D28: - | E28: - | F28: - | G28: - | H28: - | I28: -
A29: Ремонт оборудования (МОП) | B29: - | C29: - | D29: - | E29: - | F29: - | G29: - | H29: - | I29: -
A30: Ремонт оборудования (ПТ) | B30: - | C30: - | D30: - | E30: - | F30: - | G30: - | H30: - | I30: -
A31: Вывоз мусора | B31: - | C31: - | D31: - | E31: - | F31: - | G31: - | H31: - | I31: -
A32: Штрафы, пени, неустойки | B32: - | C32: - | D32: - | E32: - | F32: - | G32: - | H32: - | I32: -
A33: Расходы к удержанию | B33: - | C33: - | D33: - | E33: - | F33: - | G33: - | H33: - | I33: -
A34: Общехозяйственные | B34: 161000 | C34: =SUM(C35,C36,C37,C38,C39,C40,C41,C42) | D34: =SUM(D35,D36,D37,D38,D39,D40,D41,D42) | E34: =SUM(E35,E36,E37,E38,E39,E40,E41,E42) | F34: =SUM(F35,F36,F37,F38,F39,F40,F41,F42) | G34: =SUM(G35,G36,G37,G38,G39,G40,G41,G42) | H34: - | I34: =SUM(I35,I36,I37,I38,I39,I40,I41,I42)
A35: Аутсорс (направления) | B35: - | C35: - | D35: - | E35: - | F35: - | G35: - | H35: - | I35: -
A36: Заработная плата МО АУП | B36: 120000 | C36: 30000 | D36: 30000 | E36: 30000 | F36: 30000 | G36: - | H36: - | I36: -
A37: Инструменты: ГСМ | B37: - | C37: - | D37: - | E37: - | F37: - | G37: - | H37: - | I37: -
A38: Медосмотры | B38: - | C38: - | D38: - | E38: - | F38: - | G38: - | H38: - | I38: -
A39: Налоги с ФОТ (ИП) | B39: 39500 | C39: 3500 | D39: 12000 | E39: 12000 | F39: 12000 | G39: - | H39: - | I39: -
A40: Приобритение мебели, бытовой техники | B40: - | C40: - | D40: - | E40: - | F40: - | G40: - | H40: - | I40: -
...

Sheet River Park
A1: ПланФакт | B1: Создано с помощью сервиса ПланФакт | I1: =HYPERLINK("https://app.planfact.io/?from=Pf_BDR", "Перейти в сервис")
B2: Итого | C2: июнь` 26 | D2: июль` 26 | E2: август` 26 | F2: сентябрь` 26 | G2: октябрь` 26 | H2: ноябрь` 26 | I2: декабрь` 26
A3: River Park | B3: план | C3: план | D3: план | E3: план | F3: план | G3: план | H3: план | I3: план
A4: Выручка | B4: 2539080 | C4: =SUM(C5,C6) | D4: =SUM(D5,D6) | E4: =SUM(E5,E6) | F4: =SUM(F5,F6) | G4: =SUM(G5,G6) | H4: - | I4: =SUM(I5,I6)
A5: Нераспределенный доход | B5: - | C5: - | D5: - | E5: - | F5: - | G5: - | H5: - | I5: -
A6: Выручка | B6: 2539080 | C6: =SUM(C7,C8,C9) | D6: =SUM(D7,D8,D9) | E6: =SUM(E7,E8,E9) | F6: =SUM(F7,F8,F9) | G6: =SUM(G7,G8,G9) | H6: - | I6: =SUM(I7,I8,I9)
A7: Реализация услуг Клининг (ОД) | B7: 2539080 | C7: 846360 | D7: 846360 | E7: 846360 | F7: - | G7: - | H7: - | I7: -
A8: Реализация услуг Клининг (Доп.услуги) | B8: - | C8: - | D8: - | E8: - | F8: - | G8: - | H8: - | I8: -
A9: Реализация услуг Клининг (снег) | B9: - | C9: - | D9: - | E9: - | F9: - | G9: - | H9: - | I9: -
A10: Прямые расходы | B10: 2088109.4 | C10: =SUM(C11,C12,C13,C21,C22,C23,C24,C25,C26,C27,C28,C29,C30,C31,C32,C33,C34) | D10: =SUM(D11,D12,D13,D21,D22,D23,D24,D25,D26,D27,D28,D29,D30,D31,D32,D33,D34) | E10: =SUM(E11,E12,E13,E21,E22,E23,E24,E25,E26,E27,E28,E29,E30,E31,E32,E33,E34) | F10: =SUM(F11,F12,F13,F21,F22,F23,F24,F25,F26,F27,F28,F29,F30,F31,F32,F33,F34) | G10: =SUM(G11,G12,G13,G21,G22,G23,G24,G25,G26,G27,G28,G29,G30,G31,G32,G33,G34) | H10: - | I10: =SUM(I11,I12,I13,I21,I22,I23,I24,I25,I26,I27,I28,I29,I30,I31,I32,I33,I34)
A11: Нераспределенный расход | B11: - | C11: - | D11: - | E11: - | F11: - | G11: - | H11: - | I11: -
A12: Транспортные расходы | B12: 10352 | C12: 10352 | D12: - | E12: - | F12: - | G12: - | H12: - | I12: -
A13: Переменные | B13: 50717.39 | C13: =SUM(C14,C15,C16,C17,C18,C19,C20) | D13: =SUM(D14,D15,D16,D17,D18,D19,D20) | E13: =SUM(E14,E15,E16,E17,E18,E19,E20) | F13: =SUM(F14,F15,F16,F17,F18,F19,F20) | G13: =SUM(G14,G15,G16,G17,G18,G19,G20) | H13: - | I13: =SUM(I14,I15,I16,I17,I18,I19,I20)
A14: Услуги техниги для уборки снега (ПТ) | B14: - | C14: - | D14: - | E14: - | F14: - | G14: - | H14: - | I14: -
A15: Услуги садовника (ПТ) | B15: - | C15: - | D15: - | E15: - | F15: - | G15: - | H15: - | I15: -
A16: Сыпучие материалы (ПТ) | B16: - | C16: - | D16: - | E16: - | F16: - | G16: - | H16: - | I16: -
A17: Расходные материалы и инстументы (МОП) | B17: 32073.9 | C17: 22073.9 | D17: 5000 | E17: 5000 | F17: - | G17: - | H17: - | I17: -
A18: Расходные материалы и инстументы (ПТ) | B18: 18643.49 | C18: 8643.49 | D18: 5000 | E18: 5000 | F18: - | G18: - | H18: - | I18: -
A19: Арена оборудования (ПТ) | B19: - | C19: - | D19: - | E19: - | F19: - | G19: - | H19: - | I19: -
A20: Арена оборудования (МОП) | B20: - | C20: - | D20: - | E20: - | F20: - | G20: - | H20: - | I20: -
A21: Заработная плата (МОП) | B21: 820000 | C21: 260000 | D21: 280000 | E21: 280000 | F21: - | G21: - | H21: - | I21: -
A22: Заработная плата (ПТ) | B22: 810000 | C22: 270000 | D22: 270000 | E22: 270000 | F22: - | G22: - | H22: - | I22: -
A23: Налоги с ФОТ (МОП) | B23: - | C23: - | D23: - | E23: - | F23: - | G23: - | H23: - | I23: -
A24: Налоги с ФОТ (ПТ) | B24: - | C24: - | D24: - | E24: - | F24: - | G24: - | H24: - | I24: -
A25: Премми (МОП) | B25: - | C25: - | D25: - | E25: - | F25: - | G25: - | H25: - | I25: -
A26: Премми (ПТ) | B26: - | C26: - | D26: - | E26: - | F26: - | G26: - | H26: - | I26: -
A27: Униформа (МОП) | B27: - | C27: - | D27: - | E27: - | F27: - | G27: - | H27: - | I27: -
A28: Униформа (ПТ) | B28: - | C28: - | D28: - | E28: - | F28: - | G28: - | H28: - | I28: -
A29: Ремонт оборудования (МОП) | B29: - | C29: - | D29: - | E29: - | F29: - | G29: - | H29: - | I29: -
A30: Ремонт оборудования (ПТ) | B30: 8000 | C30: 2000 | D30: 3000 | E30: 3000 | F30: - | G30: - | H30: - | I30: -
A31: Вывоз мусора | B31: 7920 | C31: 7920 | D31: - | E31: - | F31: - | G31: - | H31: - | I31: -
A32: Штрафы, пени, неустойки | B32: - | C32: - | D32: - | E32: - | F32: - | G32: - | H32: - | I32: -
A33: Расходы к удержанию | B33: - | C33: - | D33: - | E33: - | F33: - | G33: - | H33: - | I33: -
A34: Общехозяйственные | B34: 381120 | C34: =SUM(C35,C36,C37,C38,C39,C40,C41,C42) | D34: =SUM(D35,D36,D37,D38,D39,D40,D41,D42) | E34: =SUM(E35,E36,E37,E38,E39,E40,E41,E42) | F34: =SUM(F35,F36,F37,F38,F39,F40,F41,F42) | G34: =SUM(G35,G36,G37,G38,G39,G40,G41,G42) | H34: - | I34: =SUM(I35,I36,I37,I38,I39,I40,I41,I42)
A35: Аутсорс (направления) | B35: 12500 | C35: 7500 | D35: 2500 | E35: 2500 | F35: - | G35: - | H35: - | I35: -
A36: Заработная плата МО АУП | B36: 195000 | C36: 65000 | D36: 65000 | E36: 65000 | F36: - | G36: - | H36: - | I36: -
A37: Инструменты: ГСМ | B37: 8620 | C37: 2620 | D37: 3000 | E37: 3000 | F37: - | G37: - | H37: - | I37: -
A38: Медосмотры | B38: - | C38: - | D38: - | E38: - | F38: - | G38: - | H38: - | I38: -
A39: Налоги с ФОТ (ИП) | B39: 159000 | C39: 53000 | D39: 53000 | E39: 53000 | F39: - | G39: - | H39: - | I39: -
A40: Приобритение мебели, бытовой техники | B40: - | C40: - | D40: - | E40: - | F40: - | G40: - | H40: - | I40: -
...
