Workbook

Sheet Сводный бюджет компании
A1: ПланФакт | B1: Создано с помощью сервиса ПланФакт | I1: =HYPERLINK("https://app.planfact.io/?from=Pf_BDR", "Перейти в сервис")
B2: Итого | C2: июнь` 26 | D2: июль` 26 | E2: август` 26 | F2: сентябрь` 26 | G2: октябрь` 26 | H2: ноябрь` 26 | I2: декабрь` 26
A3: Сводный бюджет компании | B3: план | C3: план | D3: план | E3: план | F3: план | G3: план | H3: план | I3: план
A4: Выручка | B4: =SUM(B5,B6) | C4: =SUM(C5,C6) | D4: =SUM(D5,D6) | E4: =SUM(E5,E6) | F4: =SUM(F5,F6) | G4: =SUM(G5,G6) | H4: =SUM(H5,H6) | I4: =SUM(I5,I6)
A5: Нераспределенный доход | B5: =SUM('Астон.Движение'!B5,'Астон.Реформа'!B5,'Дом Милый Дом'!B5,'River Park'!B5,'Астрид'!B5,'Живи в Курортном'!B5,'Новое Колпино'!B5,'Таллинский парк'!B5,'Твоя Привелегия'!B5,'Исеть Парк'!B5,'Космонавтов 11'!B5,'Утес'!B5) | C5: =SUM('Астон.Движение'!C5,'Астон.Реформа'!C5,'Дом Милый Дом'!C5,'River Park'!C5,'Астрид'!C5,'Живи в Курортном'!C5,'Новое Колпино'!C5,'Таллинский парк'!C5,'Твоя Привелегия'!C5,'Исеть Парк'!C5,'Космонавтов 11'!C5,'Утес'!C5) | D5: =SUM('Астон.Движение'!D5,'Астон.Реформа'!D5,'Дом Милый Дом'!D5,'River Park'!D5,'Астрид'!D5,'Живи в Курортном'!D5,'Новое Колпино'!D5,'Таллинский парк'!D5,'Твоя Привелегия'!D5,'Исеть Парк'!D5,'Космонавтов 11'!D5,'Утес'!D5) | E5: =SUM('Астон.Движение'!E5,'Астон.Реформа'!E5,'Дом Милый Дом'!E5,'River Park'!E5,'Астрид'!E5,'Живи в Курортном'!E5,'Новое Колпино'!E5,'Таллинский парк'!E5,'Твоя Привелегия'!E5,'Исеть Парк'!E5,'Космонавтов 11'!E5,'Утес'!E5) | F5: =SUM('Астон.Движение'!F5,'Астон.Реформа'!F5,'Дом Милый Дом'!F5,'River Park'!F5,'Астрид'!F5,'Живи в Курортном'!F5,'Новое Колпино'!F5,'Таллинский парк'!F5,'Твоя Привелегия'!F5,'Исеть Парк'!F5,'Космонавтов 11'!F5,'Утес'!F5) | G5: =SUM('Астон.Движение'!G5,'Астон.Реформа'!G5,'Дом Милый Дом'!G5,'River Park'!G5,'Астрид'!G5,'Живи в Курортном'!G5,'Новое Колпино'!G5,'Таллинский парк'!G5,'Твоя Привелегия'!G5,'Исеть Парк'!G5,'Космонавтов 11'!G5,'Утес'!G5) | H5: =SUM('Астон.Движение'!H5,'Астон.Реформа'!H5,'Дом Милый Дом'!H5,'River Park'!H5,'Астрид'!H5,'Живи в Курортном'!H5,'Новое Колпино'!H5,'Таллинский парк'!H5,'Твоя Привелегия'!H5,'Исеть Парк'!H5,'Космонавтов 11'!H5,'Утес'!H5) | I5: =SUM('Астон.Движение'!I5,'Астон.Реформа'!I5,'Дом Милый Дом'!I5,'River Park'!I5,'Астрид'!I5,'Живи в Курортном'!I5,'Новое Колпино'!I5,'Таллинский парк'!I5,'Твоя Привелегия'!I5,'Исеть Парк'!I5,'Космонавтов 11'!I5,'Утес'!I5)
A6: Выручка | B6: =SUM(B7,B8,B9) | C6: =SUM(C7,C8,C9) | D6: =SUM(D7,D8,D9) | E6: =SUM(E7,E8,E9) | F6: =SUM(F7,F8,F9) | G6: =SUM(G7,G8,G9) | H6: =SUM(H7,H8,H9) | I6: =SUM(I7,I8,I9)
A7: Реализация услуг Клининг (ОД) | B7: =SUM('Астон.Движение'!B7,'Астон.Реформа'!B7,'Дом Милый Дом'!B7,'River Park'!B7,'Астрид'!B7,'Живи в Курортном'!B7,'Новое Колпино'!B7,'Таллинский парк'!B7,'Твоя Привелегия'!B7,'Исеть Парк'!B7,'Космонавтов 11'!B7,'Утес'!B7) | C7: =SUM('Астон.Движение'!C7,'Астон.Реформа'!C7,'Дом Милый Дом'!C7,'River Park'!C7,'Астрид'!C7,'Живи в Курортном'!C7,'Новое Колпино'!C7,'Таллинский парк'!C7,'Твоя Привелегия'!C7,'Исеть Парк'!C7,'Космонавтов 11'!C7,'Утес'!C7) | D7: =SUM('Астон.Движение'!D7,'Астон.Реформа'!D7,'Дом Милый Дом'!D7,'River Park'!D7,'Астрид'!D7,'Живи в Курортном'!D7,'Новое Колпино'!D7,'Таллинский парк'!D7,'Твоя Привелегия'!D7,'Исеть Парк'!D7,'Космонавтов 11'!D7,'Утес'!D7) | E7: =SUM('Астон.Движение'!E7,'Астон.Реформа'!E7,'Дом Милый Дом'!E7,'River Park'!E7,'Астрид'!E7,'Живи в Курортном'!E7,'Новое Колпино'!E7,'Таллинский парк'!E7,'Твоя Привелегия'!E7,'Исеть Парк'!E7,'Космонавтов 11'!E7,'Утес'!E7) | F7: =SUM('Астон.Движение'!F7,'Астон.Реформа'!F7,'Дом Милый Дом'!F7,'River Park'!F7,'Астрид'!F7,'Живи в Курортном'!F7,'Новое Колпино'!F7,'Таллинский парк'!F7,'Твоя Привелегия'!F7,'Исеть Парк'!F7,'Космонавтов 11'!F7,'Утес'!F7) | G7: =SUM('Астон.Движение'!G7,'Астон.Реформа'!G7,'Дом Милый Дом'!G7,'River Park'!G7,'Астрид'!G7,'Живи в Курортном'!G7,'Новое Колпино'!G7,'Таллинский парк'!G7,'Твоя Привелегия'!G7,'Исеть Парк'!G7,'Космонавтов 11'!G7,'Утес'!G7) | H7: =SUM('Астон.Движение'!H7,'Астон.Реформа'!H7,'Дом Милый Дом'!H7,'River Park'!H7,'Астрид'!H7,'Живи в Курортном'!H7,'Новое Колпино'!H7,'Таллинский парк'!H7,'Твоя Привелегия'!H7,'Исеть Парк'!H7,'Космонавтов 11'!H7,'Утес'!H7) | I7: =SUM('Астон.Движение'!I7,'Астон.Реформа'!I7,'Дом Милый Дом'!I7,'River Park'!I7,'Астрид'!I7,'Живи в Курортном'!I7,'Новое Колпино'!I7,'Таллинский парк'!I7,'Твоя Привелегия'!I7,'Исеть Парк'!I7,'Космонавтов 11'!I7,'Утес'!I7)
A8: Реализация услуг Клининг (Доп.услуги) | B8: =SUM('Астон.Движение'!B8,'Астон.Реформа'!B8,'Дом Милый Дом'!B8,'River Park'!B8,'Астрид'!B8,'Живи в Курортном'!B8,'Новое Колпино'!B8,'Таллинский парк'!B8,'Твоя Привелегия'!B8,'Исеть Парк'!B8,'Космонавтов 11'!B8,'Утес'!B8) | C8: =SUM('Астон.Движение'!C8,'Астон.Реформа'!C8,'Дом Милый Дом'!C8,'River Park'!C8,'Астрид'!C8,'Живи в Курортном'!C8,'Новое Колпино'!C8,'Таллинский парк'!C8,'Твоя Привелегия'!C8,'Исеть Парк'!C8,'Космонавтов 11'!C8,'Утес'!C8) | D8: =SUM('Астон.Движение'!D8,'Астон.Реформа'!D8,'Дом Милый Дом'!D8,'River Park'!D8,'Астрид'!D8,'Живи в Курортном'!D8,'Новое Колпино'!D8,'Таллинский парк'!D8,'Твоя Привелегия'!D8,'Исеть Парк'!D8,'Космонавтов 11'!D8,'Утес'!D8) | E8: =SUM('Астон.Движение'!E8,'Астон.Реформа'!E8,'Дом Милый Дом'!E8,'River Park'!E8,'Астрид'!E8,'Живи в Курортном'!E8,'Новое Колпино'!E8,'Таллинский парк'!E8,'Твоя Привелегия'!E8,'Исеть Парк'!E8,'Космонавтов 11'!E8,'Утес'!E8) | F8: =SUM('Астон.Движение'!F8,'Астон.Реформа'!F8,'Дом Милый Дом'!F8,'River Park'!F8,'Астрид'!F8,'Живи в Курортном'!F8,'Новое Колпино'!F8,'Таллинский парк'!F8,'Твоя Привелегия'!F8,'Исеть Парк'!F8,'Космонавтов 11'!F8,'Утес'!F8) | G8: =SUM('Астон.Движение'!G8,'Астон.Реформа'!G8,'Дом Милый Дом'!G8,'River Park'!G8,'Астрид'!G8,'Живи в Курортном'!G8,'Новое Колпино'!G8,'Таллинский парк'!G8,'Твоя Привелегия'!G8,'Исеть Парк'!G8,'Космонавтов 11'!G8,'Утес'!G8) | H8: =SUM('Астон.Движение'!H8,'Астон.Реформа'!H8,'Дом Милый Дом'!H8,'River Park'!H8,'Астрид'!H8,'Живи в Курортном'!H8,'Новое Колпино'!H8,'Таллинский парк'!H8,'Твоя Привелегия'!H8,'Исеть Парк'!H8,'Космонавтов 11'!H8,'Утес'!H8) | I8: =SUM('Астон.Движение'!I8,'Астон.Реформа'!I8,'Дом Милый Дом'!I8,'River Park'!I8,'Астрид'!I8,'Живи в Курортном'!I8,'Новое Колпино'!I8,'Таллинский парк'!I8,'Твоя Привелегия'!I8,'Исеть Парк'!I8,'Космонавтов 11'!I8,'Утес'!I8)
A9: Реализация услуг Клининг (снег) | B9: =SUM('Астон.Движение'!B9,'Астон.Реформа'!B9,'Дом Милый Дом'!B9,'River Park'!B9,'Астрид'!B9,'Живи в Курортном'!B9,'Новое Колпино'!B9,'Таллинский парк'!B9,'Твоя Привелегия'!B9,'Исеть Парк'!B9,'Космонавтов 11'!B9,'Утес'!B9) | C9: =SUM('Астон.Движение'!C9,'Астон.Реформа'!C9,'Дом Милый Дом'!C9,'River Park'!C9,'Астрид'!C9,'Живи в Курортном'!C9,'Новое Колпино'!C9,'Таллинский парк'!C9,'Твоя Привелегия'!C9,'Исеть Парк'!C9,'Космонавтов 11'!C9,'Утес'!C9) | D9: =SUM('Астон.Движение'!D9,'Астон.Реформа'!D9,'Дом Милый Дом'!D9,'River Park'!D9,'Астрид'!D9,'Живи в Курортном'!D9,'Новое Колпино'!D9,'Таллинский парк'!D9,'Твоя Привелегия'!D9,'Исеть Парк'!D9,'Космонавтов 11'!D9,'Утес'!D9) | E9: =SUM('Астон.Движение'!E9,'Астон.Реформа'!E9,'Дом Милый Дом'!E9,'River Park'!E9,'Астрид'!E9,'Живи в Курортном'!E9,'Новое Колпино'!E9,'Таллинский парк'!E9,'Твоя Привелегия'!E9,'Исеть Парк'!E9,'Космонавтов 11'!E9,'Утес'!E9) | F9: =SUM('Астон.Движение'!F9,'Астон.Реформа'!F9,'Дом Милый Дом'!F9,'River Park'!F9,'Астрид'!F9,'Живи в Курортном'!F9,'Новое Колпино'!F9,'Таллинский парк'!F9,'Твоя Привелегия'!F9,'Исеть Парк'!F9,'Космонавтов 11'!F9,'Утес'!F9) | G9: =SUM('Астон.Движение'!G9,'Астон.Реформа'!G9,'Дом Милый Дом'!G9,'River Park'!G9,'Астрид'!G9,'Живи в Курортном'!G9,'Новое Колпино'!G9,'Таллинский парк'!G9,'Твоя Привелегия'!G9,'Исеть Парк'!G9,'Космонавтов 11'!G9,'Утес'!G9) | H9: =SUM('Астон.Движение'!H9,'Астон.Реформа'!H9,'Дом Милый Дом'!H9,'River Park'!H9,'Астрид'!H9,'Живи в Курортном'!H9,'Новое Колпино'!H9,'Таллинский парк'!H9,'Твоя Привелегия'!H9,'Исеть Парк'!H9,'Космонавтов 11'!H9,'Утес'!H9) | I9: =SUM('Астон.Движение'!I9,'Астон.Реформа'!I9,'Дом Милый Дом'!I9,'River Park'!I9,'Астрид'!I9,'Живи в Курортном'!I9,'Новое Колпино'!I9,'Таллинский парк'!I9,'Твоя Привелегия'!I9,'Исеть Парк'!I9,'Космонавтов 11'!I9,'Утес'!I9)
A10: Прямые расходы | B10: =SUM(B11,B12,B13,B21,B22,B23,B24,B25,B26,B27,B28,B29,B30,B31,B32,B33,B34) | C10: =SUM(C11,C12,C13,C21,C22,C23,C24,C25,C26,C27,C28,C29,C30,C31,C32,C33,C34) | D10: =SUM(D11,D12,D13,D21,D22,D23,D24,D25,D26,D27,D28,D29,D30,D31,D32,D33,D34) | E10: =SUM(E11,E12,E13,E21,E22,E23,E24,E25,E26,E27,E28,E29,E30,E31,E32,E33,E34) | F10: =SUM(F11,F12,F13,F21,F22,F23,F24,F25,F26,F27,F28,F29,F30,F31,F32,F33,F34) | G10: =SUM(G11,G12,G13,G21,G22,G23,G24,G25,G26,G27,G28,G29,G30,G31,G32,G33,G34) | H10: =SUM(H11,H12,H13,H21,H22,H23,H24,H25,H26,H27,H28,H29,H30,H31,H32,H33,H34) | I10: =SUM(I11,I12,I13,I21,I22,I23,I24,I25,I26,I27,I28,I29,I30,I31,I32,I33,I34)
A11: Нераспределенный расход | B11: =SUM('Астон.Движение'!B11,'Астон.Реформа'!B11,'Дом Милый Дом'!B11,'River Park'!B11,'Астрид'!B11,'Живи в Курортном'!B11,'Новое Колпино'!B11,'Таллинский парк'!B11,'Твоя Привелегия'!B11,'Исеть Парк'!B11,'Космонавтов 11'!B11,'Утес'!B11) | C11: =SUM('Астон.Движение'!C11,'Астон.Реформа'!C11,'Дом Милый Дом'!C11,'River Park'!C11,'Астрид'!C11,'Живи в Курортном'!C11,'Новое Колпино'!C11,'Таллинский парк'!C11,'Твоя Привелегия'!C11,'Исеть Парк'!C11,'Космонавтов 11'!C11,'Утес'!C11) | D11: =SUM('Астон.Движение'!D11,'Астон.Реформа'!D11,'Дом Милый Дом'!D11,'River Park'!D11,'Астрид'!D11,'Живи в Курортном'!D11,'Новое Колпино'!D11,'Таллинский парк'!D11,'Твоя Привелегия'!D11,'Исеть Парк'!D11,'Космонавтов 11'!D11,'Утес'!D11) | E11: =SUM('Астон.Движение'!E11,'Астон.Реформа'!E11,'Дом Милый Дом'!E11,'River Park'!E11,'Астрид'!E11,'Живи в Курортном'!E11,'Новое Колпино'!E11,'Таллинский парк'!E11,'Твоя Привелегия'!E11,'Исеть Парк'!E11,'Космонавтов 11'!E11,'Утес'!E11) | F11: =SUM('Астон.Движение'!F11,'Астон.Реформа'!F11,'Дом Милый Дом'!F11,'River Park'!F11,'Астрид'!F11,'Живи в Курортном'!F11,'Новое Колпино'!F11,'Таллинский парк'!F11,'Твоя Привелегия'!F11,'Исеть Парк'!F11,'Космонавтов 11'!F11,'Утес'!F11) | G11: =SUM('Астон.Движение'!G11,'Астон.Реформа'!G11,'Дом Милый Дом'!G11,'River Park'!G11,'Астрид'!G11,'Живи в Курортном'!G11,'Новое Колпино'!G11,'Таллинский парк'!G11,'Твоя Привелегия'!G11,'Исеть Парк'!G11,'Космонавтов 11'!G11,'Утес'!G11) | H11: =SUM('Астон.Движение'!H11,'Астон.Реформа'!H11,'Дом Милый Дом'!H11,'River Park'!H11,'Астрид'!H11,'Живи в Курортном'!H11,'Новое Колпино'!H11,'Таллинский парк'!H11,'Твоя Привелегия'!H11,'Исеть Парк'!H11,'Космонавтов 11'!H11,'Утес'!H11) | I11: =SUM('Астон.Движение'!I11,'Астон.Реформа'!I11,'Дом Милый Дом'!I11,'River Park'!I11,'Астрид'!I11,'Живи в Курортном'!I11,'Новое Колпино'!I11,'Таллинский парк'!I11,'Твоя Привелегия'!I11,'Исеть Парк'!I11,'Космонавтов 11'!I11,'Утес'!I11)
A12: Транспортные расходы | B12: =SUM('Астон.Движение'!B12,'Астон.Реформа'!B12,'Дом Милый Дом'!B12,'River Park'!B12,'Астрид'!B12,'Живи в Курортном'!B12,'Новое Колпино'!B12,'Таллинский парк'!B12,'Твоя Привелегия'!B12,'Исеть Парк'!B12,'Космонавтов 11'!B12,'Утес'!B12) | C12: =SUM('Астон.Движение'!C12,'Астон.Реформа'!C12,'Дом Милый Дом'!C12,'River Park'!C12,'Астрид'!C12,'Живи в Курортном'!C12,'Новое Колпино'!C12,'Таллинский парк'!C12,'Твоя Привелегия'!C12,'Исеть Парк'!C12,'Космонавтов 11'!C12,'Утес'!C12) | D12: =SUM('Астон.Движение'!D12,'Астон.Реформа'!D12,'Дом Милый Дом'!D12,'River Park'!D12,'Астрид'!D12,'Живи в Курортном'!D12,'Новое Колпино'!D12,'Таллинский парк'!D12,'Твоя Привелегия'!D12,'Исеть Парк'!D12,'Космонавтов 11'!D12,'Утес'!D12) | E12: =SUM('Астон.Движение'!E12,'Астон.Реформа'!E12,'Дом Милый Дом'!E12,'River Park'!E12,'Астрид'!E12,'Живи в Курортном'!E12,'Новое Колпино'!E12,'Таллинский парк'!E12,'Твоя Привелегия'!E12,'Исеть Парк'!E12,'Космонавтов 11'!E12,'Утес'!E12) | F12: =SUM('Астон.Движение'!F12,'Астон.Реформа'!F12,'Дом Милый Дом'!F12,'River Park'!F12,'Астрид'!F12,'Живи в Курортном'!F12,'Новое Колпино'!F12,'Таллинский парк'!F12,'Твоя Привелегия'!F12,'Исеть Парк'!F12,'Космонавтов 11'!F12,'Утес'!F12) | G12: =SUM('Астон.Движение'!G12,'Астон.Реформа'!G12,'Дом Милый Дом'!G12,'River Park'!G12,'Астрид'!G12,'Живи в Курортном'!G12,'Новое Колпино'!G12,'Таллинский парк'!G12,'Твоя Привелегия'!G12,'Исеть Парк'!G12,'Космонавтов 11'!G12,'Утес'!G12) | H12: =SUM('Астон.Движение'!H12,'Астон.Реформа'!H12,'Дом Милый Дом'!H12,'River Park'!H12,'Астрид'!H12,'Живи в Курортном'!H12,'Новое Колпино'!H12,'Таллинский парк'!H12,'Твоя Привелегия'!H12,'Исеть Парк'!H12,'Космонавтов 11'!H12,'Утес'!H12) | I12: =SUM('Астон.Движение'!I12,'Астон.Реформа'!I12,'Дом Милый Дом'!I12,'River Park'!I12,'Астрид'!I12,'Живи в Курортном'!I12,'Новое Колпино'!I12,'Таллинский парк'!I12,'Твоя Привелегия'!I12,'Исеть Парк'!I12,'Космонавтов 11'!I12,'Утес'!I12)
A13: Переменные | B13: =SUM(B14,B15,B16,B17,B18,B19,B20) | C13: =SUM(C14,C15,C16,C17,C18,C19,C20) | D13: =SUM(D14,D15,D16,D17,D18,D19,D20) | E13: =SUM(E14,E15,E16,E17,E18,E19,E20) | F13: =SUM(F14,F15,F16,F17,F18,F19,F20) | G13: =SUM(G14,G15,G16,G17,G18,G19,G20) | H13: =SUM(H14,H15,H16,H17,H18,H19,H20) | I13: =SUM(I14,I15,I16,I17,I18,I19,I20)
A14: Услуги техниги для уборки снега (ПТ) | B14: =SUM('Астон.Движение'!B14,'Астон.Реформа'!B14,'Дом Милый Дом'!B14,'River Park'!B14,'Астрид'!B14,'Живи в Курортном'!B14,'Новое Колпино'!B14,'Таллинский парк'!B14,'Твоя Привелегия'!B14,'Исеть Парк'!B14,'Космонавтов 11'!B14,'Утес'!B14) | C14: =SUM('Астон.Движение'!C14,'Астон.Реформа'!C14,'Дом Милый Дом'!C14,'River Park'!C14,'Астрид'!C14,'Живи в Курортном'!C14,'Новое Колпино'!C14,'Таллинский парк'!C14,'Твоя Привелегия'!C14,'Исеть Парк'!C14,'Космонавтов 11'!C14,'Утес'!C14) | D14: =SUM('Астон.Движение'!D14,'Астон.Реформа'!D14,'Дом Милый Дом'!D14,'River Park'!D14,'Астрид'!D14,'Живи в Курортном'!D14,'Новое Колпино'!D14,'Таллинский парк'!D14,'Твоя Привелегия'!D14,'Исеть Парк'!D14,'Космонавтов 11'!D14,'Утес'!D14) | E14: =SUM('Астон.Движение'!E14,'Астон.Реформа'!E14,'Дом Милый Дом'!E14,'River Park'!E14,'Астрид'!E14,'Живи в Курортном'!E14,'Новое Колпино'!E14,'Таллинский парк'!E14,'Твоя Привелегия'!E14,'Исеть Парк'!E14,'Космонавтов 11'!E14,'Утес'!E14) | F14: =SUM('Астон.Движение'!F14,'Астон.Реформа'!F14,'Дом Милый Дом'!F14,'River Park'!F14,'Астрид'!F14,'Живи в Курортном'!F14,'Новое Колпино'!F14,'Таллинский парк'!F14,'Твоя Привелегия'!F14,'Исеть Парк'!F14,'Космонавтов 11'!F14,'Утес'!F14) | G14: =SUM('Астон.Движение'!G14,'Астон.Реформа'!G14,'Дом Милый Дом'!G14,'River Park'!G14,'Астрид'!G14,'Живи в Курортном'!G14,'Новое Колпино'!G14,'Таллинский парк'!G14,'Твоя Привелегия'!G14,'Исеть Парк'!G14,'Космонавтов 11'!G14,'Утес'!G14) | H14: =SUM('Астон.Движение'!H14,'Астон.Реформа'!H14,'Дом Милый Дом'!H14,'River Park'!H14,'Астрид'!H14,'Живи в Курортном'!H14,'Новое Колпино'!H14,'Таллинский парк'!H14,'Твоя Привелегия'!H14,'Исеть Парк'!H14,'Космонавтов 11'!H14,'Утес'!H14) | I14: =SUM('Астон.Движение'!I14,'Астон.Реформа'!I14,'Дом Милый Дом'!I14,'River Park'!I14,'Астрид'!I14,'Живи в Курортном'!I14,'Новое Колпино'!I14,'Таллинский парк'!I14,'Твоя Привелегия'!I14,'Исеть Парк'!I14,'Космонавтов 11'!I14,'Утес'!I14)
A15: Услуги садовника (ПТ) | B15: =SUM('Астон.Движение'!B15,'Астон.Реформа'!B15,'Дом Милый Дом'!B15,'River Park'!B15,'Астрид'!B15,'Живи в Курортном'!B15,'Новое Колпино'!B15,'Таллинский парк'!B15,'Твоя Привелегия'!B15,'Исеть Парк'!B15,'Космонавтов 11'!B15,'Утес'!B15) | C15: =SUM('Астон.Движение'!C15,'Астон.Реформа'!C15,'Дом Милый Дом'!C15,'River Park'!C15,'Астрид'!C15,'Живи в Курортном'!C15,'Новое Колпино'!C15,'Таллинский парк'!C15,'Твоя Привелегия'!C15,'Исеть Парк'!C15,'Космонавтов 11'!C15,'Утес'!C15) | D15: =SUM('Астон.Движение'!D15,'Астон.Реформа'!D15,'Дом Милый Дом'!D15,'River Park'!D15,'Астрид'!D15,'Живи в Курортном'!D15,'Новое Колпино'!D15,'Таллинский парк'!D15,'Твоя Привелегия'!D15,'Исеть Парк'!D15,'Космонавтов 11'!D15,'Утес'!D15) | E15: =SUM('Астон.Движение'!E15,'Астон.Реформа'!E15,'Дом Милый Дом'!E15,'River Park'!E15,'Астрид'!E15,'Живи в Курортном'!E15,'Новое Колпино'!E15,'Таллинский парк'!E15,'Твоя Привелегия'!E15,'Исеть Парк'!E15,'Космонавтов 11'!E15,'Утес'!E15) | F15: =SUM('Астон.Движение'!F15,'Астон.Реформа'!F15,'Дом Милый Дом'!F15,'River Park'!F15,'Астрид'!F15,'Живи в Курортном'!F15,'Новое Колпино'!F15,'Таллинский парк'!F15,'Твоя Привелегия'!F15,'Исеть Парк'!F15,'Космонавтов 11'!F15,'Утес'!F15) | G15: =SUM('Астон.Движение'!G15,'Астон.Реформа'!G15,'Дом Милый Дом'!G15,'River Park'!G15,'Астрид'!G15,'Живи в Курортном'!G15,'Новое Колпино'!G15,'Таллинский парк'!G15,'Твоя Привелегия'!G15,'Исеть Парк'!G15,'Космонавтов 11'!G15,'Утес'!G15) | H15: =SUM('Астон.Движение'!H15,'Астон.Реформа'!H15,'Дом Милый Дом'!H15,'River Park'!H15,'Астрид'!H15,'Живи в Курортном'!H15,'Новое Колпино'!H15,'Таллинский парк'!H15,'Твоя Привелегия'!H15,'Исеть Парк'!H15,'Космонавтов 11'!H15,'Утес'!H15) | I15: =SUM('Астон.Движение'!I15,'Астон.Реформа'!I15,'Дом Милый Дом'!I15,'River Park'!I15,'Астрид'!I15,'Живи в Курортном'!I15,'Новое Колпино'!I15,'Таллинский парк'!I15,'Твоя Привелегия'!I15,'Исеть Парк'!I15,'Космонавтов 11'!I15,'Утес'!I15)
A16: Сыпучие материалы (ПТ) | B16: =SUM('Астон.Движение'!B16,'Астон.Реформа'!B16,'Дом Милый Дом'!B16,'River Park'!B16,'Астрид'!B16,'Живи в Курортном'!B16,'Новое Колпино'!B16,'Таллинский парк'!B16,'Твоя Привелегия'!B16,'Исеть Парк'!B16,'Космонавтов 11'!B16,'Утес'!B16) | C16: =SUM('Астон.Движение'!C16,'Астон.Реформа'!C16,'Дом Милый Дом'!C16,'River Park'!C16,'Астрид'!C16,'Живи в Курортном'!C16,'Новое Колпино'!C16,'Таллинский парк'!C16,'Твоя Привелегия'!C16,'Исеть Парк'!C16,'Космонавтов 11'!C16,'Утес'!C16) | D16: =SUM('Астон.Движение'!D16,'Астон.Реформа'!D16,'Дом Милый Дом'!D16,'River Park'!D16,'Астрид'!D16,'Живи в Курортном'!D16,'Новое Колпино'!D16,'Таллинский парк'!D16,'Твоя Привелегия'!D16,'Исеть Парк'!D16,'Космонавтов 11'!D16,'Утес'!D16) | E16: =SUM('Астон.Движение'!E16,'Астон.Реформа'!E16,'Дом Милый Дом'!E16,'River Park'!E16,'Астрид'!E16,'Живи в Курортном'!E16,'Новое Колпино'!E16,'Таллинский парк'!E16,'Твоя Привелегия'!E16,'Исеть Парк'!E16,'Космонавтов 11'!E16,'Утес'!E16) | F16: =SUM('Астон.Движение'!F16,'Астон.Реформа'!F16,'Дом Милый Дом'!F16,'River Park'!F16,'Астрид'!F16,'Живи в Курортном'!F16,'Новое Колпино'!F16,'Таллинский парк'!F16,'Твоя Привелегия'!F16,'Исеть Парк'!F16,'Космонавтов 11'!F16,'Утес'!F16) | G16: =SUM('Астон.Движение'!G16,'Астон.Реформа'!G16,'Дом Милый Дом'!G16,'River Park'!G16,'Астрид'!G16,'Живи в Курортном'!G16,'Новое Колпино'!G16,'Таллинский парк'!G16,'Твоя Привелегия'!G16,'Исеть Парк'!G16,'Космонавтов 11'!G16,'Утес'!G16) | H16: =SUM('Астон.Движение'!H16,'Астон.Реформа'!H16,'Дом Милый Дом'!H16,'River Park'!H16,'Астрид'!H16,'Живи в Курортном'!H16,'Новое Колпино'!H16,'Таллинский парк'!H16,'Твоя Привелегия'!H16,'Исеть Парк'!H16,'Космонавтов 11'!H16,'Утес'!H16) | I16: =SUM('Астон.Движение'!I16,'Астон.Реформа'!I16,'Дом Милый Дом'!I16,'River Park'!I16,'Астрид'!I16,'Живи в Курортном'!I16,'Новое Колпино'!I16,'Таллинский парк'!I16,'Твоя Привелегия'!I16,'Исеть Парк'!I16,'Космонавтов 11'!I16,'Утес'!I16)
A17: Расходные материалы и инстументы (МОП) | B17: =SUM('Астон.Движение'!B17,'Астон.Реформа'!B17,'Дом Милый Дом'!B17,'River Park'!B17,'Астрид'!B17,'Живи в Курортном'!B17,'Новое Колпино'!B17,'Таллинский парк'!B17,'Твоя Привелегия'!B17,'Исеть Парк'!B17,'Космонавтов 11'!B17,'Утес'!B17) | C17: =SUM('Астон.Движение'!C17,'Астон.Реформа'!C17,'Дом Милый Дом'!C17,'River Park'!C17,'Астрид'!C17,'Живи в Курортном'!C17,'Новое Колпино'!C17,'Таллинский парк'!C17,'Твоя Привелегия'!C17,'Исеть Парк'!C17,'Космонавтов 11'!C17,'Утес'!C17) | D17: =SUM('Астон.Движение'!D17,'Астон.Реформа'!D17,'Дом Милый Дом'!D17,'River Park'!D17,'Астрид'!D17,'Живи в Курортном'!D17,'Новое Колпино'!D17,'Таллинский парк'!D17,'Твоя Привелегия'!D17,'Исеть Парк'!D17,'Космонавтов 11'!D17,'Утес'!D17) | E17: =SUM('Астон.Движение'!E17,'Астон.Реформа'!E17,'Дом Милый Дом'!E17,'River Park'!E17,'Астрид'!E17,'Живи в Курортном'!E17,'Новое Колпино'!E17,'Таллинский парк'!E17,'Твоя Привелегия'!E17,'Исеть Парк'!E17,'Космонавтов 11'!E17,'Утес'!E17) | F17: =SUM('Астон.Движение'!F17,'Астон.Реформа'!F17,'Дом Милый Дом'!F17,'River Park'!F17,'Астрид'!F17,'Живи в Курортном'!F17,'Новое Колпино'!F17,'Таллинский парк'!F17,'Твоя Привелегия'!F17,'Исеть Парк'!F17,'Космонавтов 11'!F17,'Утес'!F17) | G17: =SUM('Астон.Движение'!G17,'Астон.Реформа'!G17,'Дом Милый Дом'!G17,'River Park'!G17,'Астрид'!G17,'Живи в Курортном'!G17,'Новое Колпино'!G17,'Таллинский парк'!G17,'Твоя Привелегия'!G17,'Исеть Парк'!G17,'Космонавтов 11'!G17,'Утес'!G17) | H17: =SUM('Астон.Движение'!H17,'Астон.Реформа'!H17,'Дом Милый Дом'!H17,'River Park'!H17,'Астрид'!H17,'Живи в Курортном'!H17,'Новое Колпино'!H17,'Таллинский парк'!H17,'Твоя Привелегия'!H17,'Исеть Парк'!H17,'Космонавтов 11'!H17,'Утес'!H17) | I17: =SUM('Астон.Движение'!I17,'Астон.Реформа'!I17,'Дом Милый Дом'!I17,'River Park'!I17,'Астрид'!I17,'Живи в Курортном'!I17,'Новое Колпино'!I17,'Таллинский парк'!I17,'Твоя Привелегия'!I17,'Исеть Парк'!I17,'Космонавтов 11'!I17,'Утес'!I17)
A18: Расходные материалы и инстументы (ПТ) | B18: =SUM('Астон.Движение'!B18,'Астон.Реформа'!B18,'Дом Милый Дом'!B18,'River Park'!B18,'Астрид'!B18,'Живи в Курортном'!B18,'Новое Колпино'!B18,'Таллинский парк'!B18,'Твоя Привелегия'!B18,'Исеть Парк'!B18,'Космонавтов 11'!B18,'Утес'!B18) | C18: =SUM('Астон.Движение'!C18,'Астон.Реформа'!C18,'Дом Милый Дом'!C18,'River Park'!C18,'Астрид'!C18,'Живи в Курортном'!C18,'Новое Колпино'!C18,'Таллинский парк'!C18,'Твоя Привелегия'!C18,'Исеть Парк'!C18,'Космонавтов 11'!C18,'Утес'!C18) | D18: =SUM('Астон.Движение'!D18,'Астон.Реформа'!D18,'Дом Милый Дом'!D18,'River Park'!D18,'Астрид'!D18,'Живи в Курортном'!D18,'Новое Колпино'!D18,'Таллинский парк'!D18,'Твоя Привелегия'!D18,'Исеть Парк'!D18,'Космонавтов 11'!D18,'Утес'!D18) | E18: =SUM('Астон.Движение'!E18,'Астон.Реформа'!E18,'Дом Милый Дом'!E18,'River Park'!E18,'Астрид'!E18,'Живи в Курортном'!E18,'Новое Колпино'!E18,'Таллинский парк'!E18,'Твоя Привелегия'!E18,'Исеть Парк'!E18,'Космонавтов 11'!E18,'Утес'!E18) | F18: =SUM('Астон.Движение'!F18,'Астон.Реформа'!F18,'Дом Милый Дом'!F18,'River Park'!F18,'Астрид'!F18,'Живи в Курортном'!F18,'Новое Колпино'!F18,'Таллинский парк'!F18,'Твоя Привелегия'!F18,'Исеть Парк'!F18,'Космонавтов 11'!F18,'Утес'!F18) | G18: =SUM('Астон.Движение'!G18,'Астон.Реформа'!G18,'Дом Милый Дом'!G18,'River Park'!G18,'Астрид'!G18,'Живи в Курортном'!G18,'Новое Колпино'!G18,'Таллинский парк'!G18,'Твоя Привелегия'!G18,'Исеть Парк'!G18,'Космонавтов 11'!G18,'Утес'!G18) | H18: =SUM('Астон.Движение'!H18,'Астон.Реформа'!H18,'Дом Милый Дом'!H18,'River Park'!H18,'Астрид'!H18,'Живи в Курортном'!H18,'Новое Колпино'!H18,'Таллинский парк'!H18,'Твоя Привелегия'!H18,'Исеть Парк'!H18,'Космонавтов 11'!H18,'Утес'!H18) | I18: =SUM('Астон.Движение'!I18,'Астон.Реформа'!I18,'Дом Милый Дом'!I18,'River Park'!I18,'Астрид'!I18,'Живи в Курортном'!I18,'Новое Колпино'!I18,'Таллинский парк'!I18,'Твоя Привелегия'!I18,'Исеть Парк'!I18,'Космонавтов 11'!I18,'Утес'!I18)
A19: Арена оборудования (ПТ) | B19: =SUM('Астон.Движение'!B19,'Астон.Реформа'!B19,'Дом Милый Дом'!B19,'River Park'!B19,'Астрид'!B19,'Живи в Курортном'!B19,'Новое Колпино'!B19,'Таллинский парк'!B19,'Твоя Привелегия'!B19,'Исеть Парк'!B19,'Космонавтов 11'!B19,'Утес'!B19) | C19: =SUM('Астон.Движение'!C19,'Астон.Реформа'!C19,'Дом Милый Дом'!C19,'River Park'!C19,'Астрид'!C19,'Живи в Курортном'!C19,'Новое Колпино'!C19,'Таллинский парк'!C19,'Твоя Привелегия'!C19,'Исеть Парк'!C19,'Космонавтов 11'!C19,'Утес'!C19) | D19: =SUM('Астон.Движение'!D19,'Астон.Реформа'!D19,'Дом Милый Дом'!D19,'River Park'!D19,'Астрид'!D19,'Живи в Курортном'!D19,'Новое Колпино'!D19,'Таллинский парк'!D19,'Твоя Привелегия'!D19,'Исеть Парк'!D19,'Космонавтов 11'!D19,'Утес'!D19) | E19: =SUM('Астон.Движение'!E19,'Астон.Реформа'!E19,'Дом Милый Дом'!E19,'River Park'!E19,'Астрид'!E19,'Живи в Курортном'!E19,'Новое Колпино'!E19,'Таллинский парк'!E19,'Твоя Привелегия'!E19,'Исеть Парк'!E19,'Космонавтов 11'!E19,'Утес'!E19) | F19: =SUM('Астон.Движение'!F19,'Астон.Реформа'!F19,'Дом Милый Дом'!F19,'River Park'!F19,'Астрид'!F19,'Живи в Курортном'!F19,'Новое Колпино'!F19,'Таллинский парк'!F19,'Твоя Привелегия'!F19,'Исеть Парк'!F19,'Космонавтов 11'!F19,'Утес'!F19) | G19: =SUM('Астон.Движение'!G19,'Астон.Реформа'!G19,'Дом Милый Дом'!G19,'River Park'!G19,'Астрид'!G19,'Живи в Курортном'!G19,'Новое Колпино'!G19,'Таллинский парк'!G19,'Твоя Привелегия'!G19,'Исеть Парк'!G19,'Космонавтов 11'!G19,'Утес'!G19) | H19: =SUM('Астон.Движение'!H19,'Астон.Реформа'!H19,'Дом Милый Дом'!H19,'River Park'!H19,'Астрид'!H19,'Живи в Курортном'!H19,'Новое Колпино'!H19,'Таллинский парк'!H19,'Твоя Привелегия'!H19,'Исеть Парк'!H19,'Космонавтов 11'!H19,'Утес'!H19) | I19: =SUM('Астон.Движение'!I19,'Астон.Реформа'!I19,'Дом Милый Дом'!I19,'River Park'!I19,'Астрид'!I19,'Живи в Курортном'!I19,'Новое Колпино'!I19,'Таллинский парк'!I19,'Твоя Привелегия'!I19,'Исеть Парк'!I19,'Космонавтов 11'!I19,'Утес'!I19)
A20: Арена оборудования (МОП) | B20: =SUM('Астон.Движение'!B20,'Астон.Реформа'!B20,'Дом Милый Дом'!B20,'River Park'!B20,'Астрид'!B20,'Живи в Курортном'!B20,'Новое Колпино'!B20,'Таллинский парк'!B20,'Твоя Привелегия'!B20,'Исеть Парк'!B20,'Космонавтов 11'!B20,'Утес'!B20) | C20: =SUM('Астон.Движение'!C20,'Астон.Реформа'!C20,'Дом Милый Дом'!C20,'River Park'!C20,'Астрид'!C20,'Живи в Курортном'!C20,'Новое Колпино'!C20,'Таллинский парк'!C20,'Твоя Привелегия'!C20,'Исеть Парк'!C20,'Космонавтов 11'!C20,'Утес'!C20) | D20: =SUM('Астон.Движение'!D20,'Астон.Реформа'!D20,'Дом Милый Дом'!D20,'River Park'!D20,'Астрид'!D20,'Живи в Курортном'!D20,'Новое Колпино'!D20,'Таллинский парк'!D20,'Твоя Привелегия'!D20,'Исеть Парк'!D20,'Космонавтов 11'!D20,'Утес'!D20) | E20: =SUM('Астон.Движение'!E20,'Астон.Реформа'!E20,'Дом Милый Дом'!E20,'River Park'!E20,'Астрид'!E20,'Живи в Курортном'!E20,'Новое Колпино'!E20,'Таллинский парк'!E20,'Твоя Привелегия'!E20,'Исеть Парк'!E20,'Космонавтов 11'!E20,'Утес'!E20) | F20: =SUM('Астон.Движение'!F20,'Астон.Реформа'!F20,'Дом Милый Дом'!F20,'River Park'!F20,'Астрид'!F20,'Живи в Курортном'!F20,'Новое Колпино'!F20,'Таллинский парк'!F20,'Твоя Привелегия'!F20,'Исеть Парк'!F20,'Космонавтов 11'!F20,'Утес'!F20) | G20: =SUM('Астон.Движение'!G20,'Астон.Реформа'!G20,'Дом Милый Дом'!G20,'River Park'!G20,'Астрид'!G20,'Живи в Курортном'!G20,'Новое Колпино'!G20,'Таллинский парк'!G20,'Твоя Привелегия'!G20,'Исеть Парк'!G20,'Космонавтов 11'!G20,'Утес'!G20) | H20: =SUM('Астон.Движение'!H20,'Астон.Реформа'!H20,'Дом Милый Дом'!H20,'River Park'!H20,'Астрид'!H20,'Живи в Курортном'!H20,'Новое Колпино'!H20,'Таллинский парк'!H20,'Твоя Привелегия'!H20,'Исеть Парк'!H20,'Космонавтов 11'!H20,'Утес'!H20) | I20: =SUM('Астон.Движение'!I20,'Астон.Реформа'!I20,'Дом Милый Дом'!I20,'River Park'!I20,'Астрид'!I20,'Живи в Курортном'!I20,'Новое Колпино'!I20,'Таллинский парк'!I20,'Твоя Привелегия'!I20,'Исеть Парк'!I20,'Космонавтов 11'!I20,'Утес'!I20)
A21: Заработная плата (МОП) | B21: =SUM('Астон.Движение'!B21,'Астон.Реформа'!B21,'Дом Милый Дом'!B21,'River Park'!B21,'Астрид'!B21,'Живи в Курортном'!B21,'Новое Колпино'!B21,'Таллинский парк'!B21,'Твоя Привелегия'!B21,'Исеть Парк'!B21,'Космонавтов 11'!B21,'Утес'!B21) | C21: =SUM('Астон.Движение'!C21,'Астон.Реформа'!C21,'Дом Милый Дом'!C21,'River Park'!C21,'Астрид'!C21,'Живи в Курортном'!C21,'Новое Колпино'!C21,'Таллинский парк'!C21,'Твоя Привелегия'!C21,'Исеть Парк'!C21,'Космонавтов 11'!C21,'Утес'!C21) | D21: =SUM('Астон.Движение'!D21,'Астон.Реформа'!D21,'Дом Милый Дом'!D21,'River Park'!D21,'Астрид'!D21,'Живи в Курортном'!D21,'Новое Колпино'!D21,'Таллинский парк'!D21,'Твоя Привелегия'!D21,'Исеть Парк'!D21,'Космонавтов 11'!D21,'Утес'!D21) | E21: =SUM('Астон.Движение'!E21,'Астон.Реформа'!E21,'Дом Милый Дом'!E21,'River Park'!E21,'Астрид'!E21,'Живи в Курортном'!E21,'Новое Колпино'!E21,'Таллинский парк'!E21,'Твоя Привелегия'!E21,'Исеть Парк'!E21,'Космонавтов 11'!E21,'Утес'!E21) | F21: =SUM('Астон.Движение'!F21,'Астон.Реформа'!F21,'Дом Милый Дом'!F21,'River Park'!F21,'Астрид'!F21,'Живи в Курортном'!F21,'Новое Колпино'!F21,'Таллинский парк'!F21,'Твоя Привелегия'!F21,'Исеть Парк'!F21,'Космонавтов 11'!F21,'Утес'!F21) | G21: =SUM('Астон.Движение'!G21,'Астон.Реформа'!G21,'Дом Милый Дом'!G21,'River Park'!G21,'Астрид'!G21,'Живи в Курортном'!G21,'Новое Колпино'!G21,'Таллинский парк'!G21,'Твоя Привелегия'!G21,'Исеть Парк'!G21,'Космонавтов 11'!G21,'Утес'!G21) | H21: =SUM('Астон.Движение'!H21,'Астон.Реформа'!H21,'Дом Милый Дом'!H21,'River Park'!H21,'Астрид'!H21,'Живи в Курортном'!H21,'Новое Колпино'!H21,'Таллинский парк'!H21,'Твоя Привелегия'!H21,'Исеть Парк'!H21,'Космонавтов 11'!H21,'Утес'!H21) | I21: =SUM('Астон.Движение'!I21,'Астон.Реформа'!I21,'Дом Милый Дом'!I21,'River Park'!I21,'Астрид'!I21,'Живи в Курортном'!I21,'Новое Колпино'!I21,'Таллинский парк'!I21,'Твоя Привелегия'!I21,'Исеть Парк'!I21,'Космонавтов 11'!I21,'Утес'!I21)
A22: Заработная плата (ПТ) | B22: =SUM('Астон.Движение'!B22,'Астон.Реформа'!B22,'Дом Милый Дом'!B22,'River Park'!B22,'Астрид'!B22,'Живи в Курортном'!B22,'Новое Колпино'!B22,'Таллинский парк'!B22,'Твоя Привелегия'!B22,'Исеть Парк'!B22,'Космонавтов 11'!B22,'Утес'!B22) | C22: =SUM('Астон.Движение'!C22,'Астон.Реформа'!C22,'Дом Милый Дом'!C22,'River Park'!C22,'Астрид'!C22,'Живи в Курортном'!C22,'Новое Колпино'!C22,'Таллинский парк'!C22,'Твоя Привелегия'!C22,'Исеть Парк'!C22,'Космонавтов 11'!C22,'Утес'!C22) | D22: =SUM('Астон.Движение'!D22,'Астон.Реформа'!D22,'Дом Милый Дом'!D22,'River Park'!D22,'Астрид'!D22,'Живи в Курортном'!D22,'Новое Колпино'!D22,'Таллинский парк'!D22,'Твоя Привелегия'!D22,'Исеть Парк'!D22,'Космонавтов 11'!D22,'Утес'!D22) | E22: =SUM('Астон.Движение'!E22,'Астон.Реформа'!E22,'Дом Милый Дом'!E22,'River Park'!E22,'Астрид'!E22,'Живи в Курортном'!E22,'Новое Колпино'!E22,'Таллинский парк'!E22,'Твоя Привелегия'!E22,'Исеть Парк'!E22,'Космонавтов 11'!E22,'Утес'!E22) | F22: =SUM('Астон.Движение'!F22,'Астон.Реформа'!F22,'Дом Милый Дом'!F22,'River Park'!F22,'Астрид'!F22,'Живи в Курортном'!F22,'Новое Колпино'!F22,'Таллинский парк'!F22,'Твоя Привелегия'!F22,'Исеть Парк'!F22,'Космонавтов 11'!F22,'Утес'!F22) | G22: =SUM('Астон.Движение'!G22,'Астон.Реформа'!G22,'Дом Милый Дом'!G22,'River Park'!G22,'Астрид'!G22,'Живи в Курортном'!G22,'Новое Колпино'!G22,'Таллинский парк'!G22,'Твоя Привелегия'!G22,'Исеть Парк'!G22,'Космонавтов 11'!G22,'Утес'!G22) | H22: =SUM('Астон.Движение'!H22,'Астон.Реформа'!H22,'Дом Милый Дом'!H22,'River Park'!H22,'Астрид'!H22,'Живи в Курортном'!H22,'Новое Колпино'!H22,'Таллинский парк'!H22,'Твоя Привелегия'!H22,'Исеть Парк'!H22,'Космонавтов 11'!H22,'Утес'!H22) | I22: =SUM('Астон.Движение'!I22,'Астон.Реформа'!I22,'Дом Милый Дом'!I22,'River Park'!I22,'Астрид'!I22,'Живи в Курортном'!I22,'Новое Колпино'!I22,'Таллинский парк'!I22,'Твоя Привелегия'!I22,'Исеть Парк'!I22,'Космонавтов 11'!I22,'Утес'!I22)
A23: Налоги с ФОТ (МОП) | B23: =SUM('Астон.Движение'!B23,'Астон.Реформа'!B23,'Дом Милый Дом'!B23,'River Park'!B23,'Астрид'!B23,'Живи в Курортном'!B23,'Новое Колпино'!B23,'Таллинский парк'!B23,'Твоя Привелегия'!B23,'Исеть Парк'!B23,'Космонавтов 11'!B23,'Утес'!B23) | C23: =SUM('Астон.Движение'!C23,'Астон.Реформа'!C23,'Дом Милый Дом'!C23,'River Park'!C23,'Астрид'!C23,'Живи в Курортном'!C23,'Новое Колпино'!C23,'Таллинский парк'!C23,'Твоя Привелегия'!C23,'Исеть Парк'!C23,'Космонавтов 11'!C23,'Утес'!C23) | D23: =SUM('Астон.Движение'!D23,'Астон.Реформа'!D23,'Дом Милый Дом'!D23,'River Park'!D23,'Астрид'!D23,'Живи в Курортном'!D23,'Новое Колпино'!D23,'Таллинский парк'!D23,'Твоя Привелегия'!D23,'Исеть Парк'!D23,'Космонавтов 11'!D23,'Утес'!D23) | E23: =SUM('Астон.Движение'!E23,'Астон.Реформа'!E23,'Дом Милый Дом'!E23,'River Park'!E23,'Астрид'!E23,'Живи в Курортном'!E23,'Новое Колпино'!E23,'Таллинский парк'!E23,'Твоя Привелегия'!E23,'Исеть Парк'!E23,'Космонавтов 11'!E23,'Утес'!E23) | F23: =SUM('Астон.Движение'!F23,'Астон.Реформа'!F23,'Дом Милый Дом'!F23,'River Park'!F23,'Астрид'!F23,'Живи в Курортном'!F23,'Новое Колпино'!F23,'Таллинский парк'!F23,'Твоя Привелегия'!F23,'Исеть Парк'!F23,'Космонавтов 11'!F23,'Утес'!F23) | G23: =SUM('Астон.Движение'!G23,'Астон.Реформа'!G23,'Дом Милый Дом'!G23,'River Park'!G23,'Астрид'!G23,'Живи в Курортном'!G23,'Новое Колпино'!G23,'Таллинский парк'!G23,'Твоя Привелегия'!G23,'Исеть Парк'!G23,'Космонавтов 11'!G23,'Утес'!G23) | H23: =SUM('Астон.Движение'!H23,'Астон.Реформа'!H23,'Дом Милый Дом'!H23,'River Park'!H23,'Астрид'!H23,'Живи в Курортном'!H23,'Новое Колпино'!H23,'Таллинский парк'!H23,'Твоя Привелегия'!H23,'Исеть Парк'!H23,'Космонавтов 11'!H23,'Утес'!H23) | I23: =SUM('Астон.Движение'!I23,'Астон.Реформа'!I23,'Дом Милый Дом'!I23,'River Park'!I23,'Астрид'!I23,'Живи в Курортном'!I23,'Новое Колпино'!I23,'Таллинский парк'!I23,'Твоя Привелегия'!I23,'Исеть Парк'!I23,'Космонавтов 11'!I23,'Утес'!I23)
A24: Налоги с ФОТ (ПТ) | B24: =SUM('Астон.Движение'!B24,'Астон.Реформа'!B24,'Дом Милый Дом'!B24,'River Park'!B24,'Астрид'!B24,'Живи в Курортном'!B24,'Новое Колпино'!B24,'Таллинский парк'!B24,'Твоя Привелегия'!B24,'Исеть Парк'!B24,'Космонавтов 11'!B24,'Утес'!B24) | C24: =SUM('Астон.Движение'!C24,'Астон.Реформа'!C24,'Дом Милый Дом'!C24,'River Park'!C24,'Астрид'!C24,'Живи в Курортном'!C24,'Новое Колпино'!C24,'Таллинский парк'!C24,'Твоя Привелегия'!C24,'Исеть Парк'!C24,'Космонавтов 11'!C24,'Утес'!C24) | D24: =SUM('Астон.Движение'!D24,'Астон.Реформа'!D24,'Дом Милый Дом'!D24,'River Park'!D24,'Астрид'!D24,'Живи в Курортном'!D24,'Новое Колпино'!D24,'Таллинский парк'!D24,'Твоя Привелегия'!D24,'Исеть Парк'!D24,'Космонавтов 11'!D24,'Утес'!D24) | E24: =SUM('Астон.Движение'!E24,'Астон.Реформа'!E24,'Дом Милый Дом'!E24,'River Park'!E24,'Астрид'!E24,'Живи в Курортном'!E24,'Новое Колпино'!E24,'Таллинский парк'!E24,'Твоя Привелегия'!E24,'Исеть Парк'!E24,'Космонавтов 11'!E24,'Утес'!E24) | F24: =SUM('Астон.Движение'!F24,'Астон.Реформа'!F24,'Дом Милый Дом'!F24,'River Park'!F24,'Астрид'!F24,'Живи в Курортном'!F24,'Новое Колпино'!F24,'Таллинский парк'!F24,'Твоя Привелегия'!F24,'Исеть Парк'!F24,'Космонавтов 11'!F24,'Утес'!F24) | G24: =SUM('Астон.Движение'!G24,'Астон.Реформа'!G24,'Дом Милый Дом'!G24,'River Park'!G24,'Астрид'!G24,'Живи в Курортном'!G24,'Новое Колпино'!G24,'Таллинский парк'!G24,'Твоя Привелегия'!G24,'Исеть Парк'!G24,'Космонавтов 11'!G24,'Утес'!G24) | H24: =SUM('Астон.Движение'!H24,'Астон.Реформа'!H24,'Дом Милый Дом'!H24,'River Park'!H24,'Астрид'!H24,'Живи в Курортном'!H24,'Новое Колпино'!H24,'Таллинский парк'!H24,'Твоя Привелегия'!H24,'Исеть Парк'!H24,'Космонавтов 11'!H24,'Утес'!H24) | I24: =SUM('Астон.Движение'!I24,'Астон.Реформа'!I24,'Дом Милый Дом'!I24,'River Park'!I24,'Астрид'!I24,'Живи в Курортном'!I24,'Новое Колпино'!I24,'Таллинский парк'!I24,'Твоя Привелегия'!I24,'Исеть Парк'!I24,'Космонавтов 11'!I24,'Утес'!I24)
A25: Премми (МОП) | B25: =SUM('Астон.Движение'!B25,'Астон.Реформа'!B25,'Дом Милый Дом'!B25,'River Park'!B25,'Астрид'!B25,'Живи в Курортном'!B25,'Новое Колпино'!B25,'Таллинский парк'!B25,'Твоя Привелегия'!B25,'Исеть Парк'!B25,'Космонавтов 11'!B25,'Утес'!B25) | C25: =SUM('Астон.Движение'!C25,'Астон.Реформа'!C25,'Дом Милый Дом'!C25,'River Park'!C25,'Астрид'!C25,'Живи в Курортном'!C25,'Новое Колпино'!C25,'Таллинский парк'!C25,'Твоя Привелегия'!C25,'Исеть Парк'!C25,'Космонавтов 11'!C25,'Утес'!C25) | D25: =SUM('Астон.Движение'!D25,'Астон.Реформа'!D25,'Дом Милый Дом'!D25,'River Park'!D25,'Астрид'!D25,'Живи в Курортном'!D25,'Новое Колпино'!D25,'Таллинский парк'!D25,'Твоя Привелегия'!D25,'Исеть Парк'!D25,'Космонавтов 11'!D25,'Утес'!D25) | E25: =SUM('Астон.Движение'!E25,'Астон.Реформа'!E25,'Дом Милый Дом'!E25,'River Park'!E25,'Астрид'!E25,'Живи в Курортном'!E25,'Новое Колпино'!E25,'Таллинский парк'!E25,'Твоя Привелегия'!E25,'Исеть Парк'!E25,'Космонавтов 11'!E25,'Утес'!E25) | F25: =SUM('Астон.Движение'!F25,'Астон.Реформа'!F25,'Дом Милый Дом'!F25,'River Park'!F25,'Астрид'!F25,'Живи в Курортном'!F25,'Новое Колпино'!F25,'Таллинский парк'!F25,'Твоя Привелегия'!F25,'Исеть Парк'!F25,'Космонавтов 11'!F25,'Утес'!F25) | G25: =SUM('Астон.Движение'!G25,'Астон.Реформа'!G25,'Дом Милый Дом'!G25,'River Park'!G25,'Астрид'!G25,'Живи в Курортном'!G25,'Новое Колпино'!G25,'Таллинский парк'!G25,'Твоя Привелегия'!G25,'Исеть Парк'!G25,'Космонавтов 11'!G25,'Утес'!G25) | H25: =SUM('Астон.Движение'!H25,'Астон.Реформа'!H25,'Дом Милый Дом'!H25,'River Park'!H25,'Астрид'!H25,'Живи в Курортном'!H25,'Новое Колпино'!H25,'Таллинский парк'!H25,'Твоя Привелегия'!H25,'Исеть Парк'!H25,'Космонавтов 11'!H25,'Утес'!H25) | I25: =SUM('Астон.Движение'!I25,'Астон.Реформа'!I25,'Дом Милый Дом'!I25,'River Park'!I25,'Астрид'!I25,'Живи в Курортном'!I25,'Новое Колпино'!I25,'Таллинский парк'!I25,'Твоя Привелегия'!I25,'Исеть Парк'!I25,'Космонавтов 11'!I25,'Утес'!I25)
... A33: Расходы к удержанию | B33: =SUM('Астон.Движение'!B33,'Астон.Реформа'!B33,'Дом Милый Дом'!B33,'River Park'!B33,'Астрид'!B33,'Живи в Курортном'!B33,'Новое Колпино'!B33,'Таллинский парк'!B33,'Твоя Привелегия'!B33,'Исеть Парк'!B33,'Космонавтов 11'!B33,'Утес'!B33) | C33: =SUM('Астон.Движение'!C33,'Астон.Реформа'!C33,'Дом Милый Дом'!C33,'River Park'!C33,'Астрид'!C33,'Живи в Курортном'!C33,'Новое Колпино'!C33,'Таллинский парк'!C33,'Твоя Привелегия'!C33,'Исеть Парк'!C33,'Космонавтов 11'!C33,'Утес'!C33) | D33: =SUM('Астон.Движение'!D33,'Астон.Реформа'!D33,'Дом Милый Дом'!D33,'River Park'!D33,'Астрид'!D33,'Живи в Курортном'!D33,'Новое Колпино'!D33,'Таллинский парк'!D33,'Твоя Привелегия'!D33,'Исеть Парк'!D33,'Космонавтов 11'!D33,'Утес'!D33) | E33: =SUM('Астон.Движение'!E33,'Астон.Реформа'!E33,'Дом Милый Дом'!E33,'River Park'!E33,'Астрид'!E33,'Живи в Курортном'!E33,'Новое Колпино'!E33,'Таллинский парк'!E33,'Твоя Привелегия'!E33,'Исеть Парк'!E33,'Космонавтов 11'!E33,'Утес'!E33) | F33: =SUM('Астон.Движение'!F33,'Астон.Реформа'!F33,'Дом Милый Дом'!F33,'River Park'!F33,'Астрид'!F33,'Живи в Курортном'!F33,'Новое Колпино'!F33,'Таллинский парк'!F33,'Твоя Привелегия'!F33,'Исеть Парк'!F33,'Космонавтов 11'!F33,'Утес'!F33) | G33: =SUM('Астон.Движение'!G33,'Астон.Реформа'!G33,'Дом Милый Дом'!G33,'River Park'!G33,'Астрид'!G33,'Живи в Курортном'!G33,'Новое Колпино'!G33,'Таллинский парк'!G33,'Твоя Привелегия'!G33,'Исеть Парк'!G33,'Космонавтов 11'!G33,'Утес'!G33) | H33: =SUM('Астон.Движение'!H33,'Астон.Реформа'!H33,'Дом Милый Дом'!H33,'River Park'!H33,'Астрид'!H33,'Живи в Курортном'!H33,'Новое Колпино'!H33,'Таллинский парк'!H33,'Твоя Привелегия'!H33,'Исеть Парк'!H33,'Космонавтов 11'!H33,'Утес'!H33) | I33: =SUM('Астон.Движение'!I33,'Астон.Реформа'!I33,'Дом Милый Дом'!I33,'River Park'!I33,'Астрид'!I33,'Живи в Курортном'!I33,'Новое Колпино'!I33,'Таллинский парк'!I33,'Твоя Привелегия'!I33,'Исеть Парк'!I33,'Космонавтов 11'!I33,'Утес'!I33)
A34: Общехозяйственные | B34: =SUM(B35,B36,B37,B38,B39,B40,B41,B42) | C34: =SUM(C35,C36,C37,C38,C39,C40,C41,C42) | D34: =SUM(D35,D36,D37,D38,D39,D40,D41,D42) | E34: =SUM(E35,E36,E37,E38,E39,E40,E41,E42) | F34: =SUM(F35,F36,F37,F38,F39,F40,F41,F42) | G34: =SUM(G35,G36,G37,G38,G39,G40,G41,G42) | H34: =SUM(H35,H36,H37,H38,H39,H40,H41,H42) | I34: =SUM(I35,I36,I37,I38,I39,I40,I41,I42)
A35: Аутсорс (направления) | B35: =SUM('Астон.Движение'!B35,'Астон.Реформа'!B35,'Дом Милый Дом'!B35,'River Park'!B35,'Астрид'!B35,'Живи в Курортном'!B35,'Новое Колпино'!B35,'Таллинский парк'!B35,'Твоя Привелегия'!B35,'Исеть Парк'!B35,'Космонавтов 11'!B35,'Утес'!B35) | C35: =SUM('Астон.Движение'!C35,'Астон.Реформа'!C35,'Дом Милый Дом'!C35,'River Park'!C35,'Астрид'!C35,'Живи в Курортном'!C35,'Новое Колпино'!C35,'Таллинский парк'!C35,'Твоя Привелегия'!C35,'Исеть Парк'!C35,'Космонавтов 11'!C35,'Утес'!C35) | D35: =SUM('Астон.Движение'!D35,'Астон.Реформа'!D35,'Дом Милый Дом'!D35,'River Park'!D35,'Астрид'!D35,'Живи в Курортном'!D35,'Новое Колпино'!D35,'Таллинский парк'!D35,'Твоя Привелегия'!D35,'Исеть Парк'!D35,'Космонавтов 11'!D35,'Утес'!D35) | E35: =SUM('Астон.Движение'!E35,'Астон.Реформа'!E35,'Дом Милый Дом'!E35,'River Park'!E35,'Астрид'!E35,'Живи в Курортном'!E35,'Новое Колпино'!E35,'Таллинский парк'!E35,'Твоя Привелегия'!E35,'Исеть Парк'!E35,'Космонавтов 11'!E35,'Утес'!E35) | F35: =SUM('Астон.Движение'!F35,'Астон.Реформа'!F35,'Дом Милый Дом'!F35,'River Park'!F35,'Астрид'!F35,'Живи в Курортном'!F35,'Новое Колпино'!F35,'Таллинский парк'!F35,'Твоя Привелегия'!F35,'Исеть Парк'!F35,'Космонавтов 11'!F35,'Утес'!F35) | G35: =SUM('Астон.Движение'!G35,'Астон.Реформа'!G35,'Дом Милый Дом'!G35,'River Park'!G35,'Астрид'!G35,'Живи в Курортном'!G35,'Новое Колпино'!G35,'Таллинский парк'!G35,'Твоя Привелегия'!G35,'Исеть Парк'!G35,'Космонавтов 11'!G35,'Утес'!G35) | H35: =SUM('Астон.Движение'!H35,'Астон.Реформа'!H35,'Дом Милый Дом'!H35,'River Park'!H35,'Астрид'!H35,'Живи в Курортном'!H35,'Новое Колпино'!H35,'Таллинский парк'!H35,'Твоя Привелегия'!H35,'Исеть Парк'!H35,'Космонавтов 11'!H35,'Утес'!H35) | I35: =SUM('Астон.Движение'!I35,'Астон.Реформа'!I35,'Дом Милый Дом'!I35,'River Park'!I35,'Астрид'!I35,'Живи в Курортном'!I35,'Новое Колпино'!I35,'Таллинский парк'!I35,'Твоя Привелегия'!I35,'Исеть Парк'!I35,'Космонавтов 11'!I35,'Утес'!I35)
A36: Заработная плата МО АУП | B36: =SUM('Астон.Движение'!B36,'Астон.Реформа'!B36,'Дом Милый Дом'!B36,'River Park'!B36,'Астрид'!B36,'Живи в Курортном'!B36,'Новое Колпино'!B36,'Таллинский парк'!B36,'Твоя Привелегия'!B36,'Исеть Парк'!B36,'Космонавтов 11'!B36,'Утес'!B36) | C36: =SUM('Астон.Движение'!C36,'Астон.Реформа'!C36,'Дом Милый Дом'!C36,'River Park'!C36,'Астрид'!C36,'Живи в Курортном'!C36,'Новое Колпино'!C36,'Таллинский парк'!C36,'Твоя Привелегия'!C36,'Исеть Парк'!C36,'Космонавтов 11'!C36,'Утес'!C36) | D36: =SUM('Астон.Движение'!D36,'Астон.Реформа'!D36,'Дом Милый Дом'!D36,'River Park'!D36,'Астрид'!D36,'Живи в Курортном'!D36,'Новое Колпино'!D36,'Таллинский парк'!D36,'Твоя Привелегия'!D36,'Исеть Парк'!D36,'Космонавтов 11'!D36,'Утес'!D36) | E36: =SUM('Астон.Движение'!E36,'Астон.Реформа'!E36,'Дом Милый Дом'!E36,'River Park'!E36,'Астрид'!E36,'Живи в Курортном'!E36,'Новое Колпино'!E36,'Таллинский парк'!E36,'Твоя Привелегия'!E36,'Исеть Парк'!E36,'Космонавтов 11'!E36,'Утес'!E36) | F36: =SUM('Астон.Движение'!F36,'Астон.Реформа'!F36,'Дом Милый Дом'!F36,'River Park'!F36,'Астрид'!F36,'Живи в Курортном'!F36,'Новое Колпино'!F36,'Таллинский парк'!F36,'Твоя Привелегия'!F36,'Исеть Парк'!F36,'Космонавтов 11'!F36,'Утес'!F36) | G36: =SUM('Астон.Движение'!G36,'Астон.Реформа'!G36,'Дом Милый Дом'!G36,'River Park'!G36,'Астрид'!G36,'Живи в Курортном'!G36,'Новое Колпино'!G36,'Таллинский парк'!G36,'Твоя Привелегия'!G36,'Исеть Парк'!G36,'Космонавтов 11'!G36,'Утес'!G36) | H36: =SUM('Астон.Движение'!H36,'Астон.Реформа'!H36,'Дом Милый Дом'!H36,'River Park'!H36,'Астрид'!H36,'Живи в Курортном'!H36,'Новое Колпино'!H36,'Таллинский парк'!H36,'Твоя Привелегия'!H36,'Исеть Парк'!H36,'Космонавтов 11'!H36,'Утес'!H36) | I36: =SUM('Астон.Движение'!I36,'Астон.Реформа'!I36,'Дом Милый Дом'!I36,'River Park'!I36,'Астрид'!I36,'Живи в Курортном'!I36,'Новое Колпино'!I36,'Таллинский парк'!I36,'Твоя Привелегия'!I36,'Исеть Парк'!I36,'Космонавтов 11'!I36,'Утес'!I36)
A37: Инструменты: ГСМ | B37: =SUM('Астон.Движение'!B37,'Астон.Реформа'!B37,'Дом Милый Дом'!B37,'River Park'!B37,'Астрид'!B37,'Живи в Курортном'!B37,'Новое Колпино'!B37,'Таллинский парк'!B37,'Твоя Привелегия'!B37,'Исеть Парк'!B37,'Космонавтов 11'!B37,'Утес'!B37) | C37: =SUM('Астон.Движение'!C37,'Астон.Реформа'!C37,'Дом Милый Дом'!C37,'River Park'!C37,'Астрид'!C37,'Живи в Курортном'!C37,'Новое Колпино'!C37,'Таллинский парк'!C37,'Твоя Привелегия'!C37,'Исеть Парк'!C37,'Космонавтов 11'!C37,'Утес'!C37) | D37: =SUM('Астон.Движение'!D37,'Астон.Реформа'!D37,'Дом Милый Дом'!D37,'River Park'!D37,'Астрид'!D37,'Живи в Курортном'!D37,'Новое Колпино'!D37,'Таллинский парк'!D37,'Твоя Привелегия'!D37,'Исеть Парк'!D37,'Космонавтов 11'!D37,'Утес'!D37) | E37: =SUM('Астон.Движение'!E37,'Астон.Реформа'!E37,'Дом Милый Дом'!E37,'River Park'!E37,'Астрид'!E37,'Живи в Курортном'!E37,'Новое Колпино'!E37,'Таллинский парк'!E37,'Твоя Привелегия'!E37,'Исеть Парк'!E37,'Космонавтов 11'!E37,'Утес'!E37) | F37: =SUM('Астон.Движение'!F37,'Астон.Реформа'!F37,'Дом Милый Дом'!F37,'River Park'!F37,'Астрид'!F37,'Живи в Курортном'!F37,'Новое Колпино'!F37,'Таллинский парк'!F37,'Твоя Привелегия'!F37,'Исеть Парк'!F37,'Космонавтов 11'!F37,'Утес'!F37) | G37: =SUM('Астон.Движение'!G37,'Астон.Реформа'!G37,'Дом Милый Дом'!G37,'River Park'!G37,'Астрид'!G37,'Живи в Курортном'!G37,'Новое Колпино'!G37,'Таллинский парк'!G37,'Твоя Привелегия'!G37,'Исеть Парк'!G37,'Космонавтов 11'!G37,'Утес'!G37) | H37: =SUM('Астон.Движение'!H37,'Астон.Реформа'!H37,'Дом Милый Дом'!H37,'River Park'!H37,'Астрид'!H37,'Живи в Курортном'!H37,'Новое Колпино'!H37,'Таллинский парк'!H37,'Твоя Привелегия'!H37,'Исеть Парк'!H37,'Космонавтов 11'!H37,'Утес'!H37) | I37: =SUM('Астон.Движение'!I37,'Астон.Реформа'!I37,'Дом Милый Дом'!I37,'River Park'!I37,'Астрид'!I37,'Живи в Курортном'!I37,'Новое Колпино'!I37,'Таллинский парк'!I37,'Твоя Привелегия'!I37,'Исеть Парк'!I37,'Космонавтов 11'!I37,'Утес'!I37)
A38: Медосмотры | B38: =SUM('Астон.Движение'!B38,'Астон.Реформа'!B38,'Дом Милый Дом'!B38,'River Park'!B38,'Астрид'!B38,'Живи в Курортном'!B38,'Новое Колпино'!B38,'Таллинский парк'!B38,'Твоя Привелегия'!B38,'Исеть Парк'!B38,'Космонавтов 11'!B38,'Утес'!B38) | C38: =SUM('Астон.Движение'!C38,'Астон.Реформа'!C38,'Дом Милый Дом'!C38,'River Park'!C38,'Астрид'!C38,'Живи в Курортном'!C38,'Новое Колпино'!C38,'Таллинский парк'!C38,'Твоя Привелегия'!C38,'Исеть Парк'!C38,'Космонавтов 11'!C38,'Утес'!C38) | D38: =SUM('Астон.Движение'!D38,'Астон.Реформа'!D38,'Дом Милый Дом'!D38,'River Park'!D38,'Астрид'!D38,'Живи в Курортном'!D38,'Новое Колпино'!D38,'Таллинский парк'!D38,'Твоя Привелегия'!D38,'Исеть Парк'!D38,'Космонавтов 11'!D38,'Утес'!D38) | E38: =SUM('Астон.Движение'!E38,'Астон.Реформа'!E38,'Дом Милый Дом'!E38,'River Park'!E38,'Астрид'!E38,'Живи в Курортном'!E38,'Новое Колпино'!E38,'Таллинский парк'!E38,'Твоя Привелегия'!E38,'Исеть Парк'!E38,'Космонавтов 11'!E38,'Утес'!E38) | F38: =SUM('Астон.Движение'!F38,'Астон.Реформа'!F38,'Дом Милый Дом'!F38,'River Park'!F38,'Астрид'!F38,'Живи в Курортном'!F38,'Новое Колпино'!F38,'Таллинский парк'!F38,'Твоя Привелегия'!F38,'Исеть Парк'!F38,'Космонавтов 11'!F38,'Утес'!F38) | G38: =SUM('Астон.Движение'!G38,'Астон.Реформа'!G38,'Дом Милый Дом'!G38,'River Park'!G38,'Астрид'!G38,'Живи в Курортном'!G38,'Новое Колпино'!G38,'Таллинский парк'!G38,'Твоя Привелегия'!G38,'Исеть Парк'!G38,'Космонавтов 11'!G38,'Утес'!G38) | H38: =SUM('Астон.Движение'!H38,'Астон.Реформа'!H38,'Дом Милый Дом'!H38,'River Park'!H38,'Астрид'!H38,'Живи в Курортном'!H38,'Новое Колпино'!H38,'Таллинский парк'!H38,'Твоя Привелегия'!H38,'Исеть Парк'!H38,'Космонавтов 11'!H38,'Утес'!H38) | I38: =SUM('Астон.Движение'!I38,'Астон.Реформа'!I38,'Дом Милый Дом'!I38,'River Park'!I38,'Астрид'!I38,'Живи в Курортном'!I38,'Новое Колпино'!I38,'Таллинский парк'!I38,'Твоя Привелегия'!I38,'Исеть Парк'!I38,'Космонавтов 11'!I38,'Утес'!I38)
A39: Налоги с ФОТ (ИП) | B39: =SUM('Астон.Движение'!B39,'Астон.Реформа'!B39,'Дом Милый Дом'!B39,'River Park'!B39,'Астрид'!B39,'Живи в Курортном'!B39,'Новое Колпино'!B39,'Таллинский парк'!B39,'Твоя Привелегия'!B39,'Исеть Парк'!B39,'Космонавтов 11'!B39,'Утес'!B39) | C39: =SUM('Астон.Движение'!C39,'Астон.Реформа'!C39,'Дом Милый Дом'!C39,'River Park'!C39,'Астрид'!C39,'Живи в Курортном'!C39,'Новое Колпино'!C39,'Таллинский парк'!C39,'Твоя Привелегия'!C39,'Исеть Парк'!C39,'Космонавтов 11'!C39,'Утес'!C39) | D39: =SUM('Астон.Движение'!D39,'Астон.Реформа'!D39,'Дом Милый Дом'!D39,'River Park'!D39,'Астрид'!D39,'Живи в Курортном'!D39,'Новое Колпино'!D39,'Таллинский парк'!D39,'Твоя Привелегия'!D39,'Исеть Парк'!D39,'Космонавтов 11'!D39,'Утес'!D39) | E39: =SUM('Астон.Движение'!E39,'Астон.Реформа'!E39,'Дом Милый Дом'!E39,'River Park'!E39,'Астрид'!E39,'Живи в Курортном'!E39,'Новое Колпино'!E39,'Таллинский парк'!E39,'Твоя Привелегия'!E39,'Исеть Парк'!E39,'Космонавтов 11'!E39,'Утес'!E39) | F39: =SUM('Астон.Движение'!F39,'Астон.Реформа'!F39,'Дом Милый Дом'!F39,'River Park'!F39,'Астрид'!F39,'Живи в Курортном'!F39,'Новое Колпино'!F39,'Таллинский парк'!F39,'Твоя Привелегия'!F39,'Исеть Парк'!F39,'Космонавтов 11'!F39,'Утес'!F39) | G39: =SUM('Астон.Движение'!G39,'Астон.Реформа'!G39,'Дом Милый Дом'!G39,'River Park'!G39,'Астрид'!G39,'Живи в Курортном'!G39,'Новое Колпино'!G39,'Таллинский парк'!G39,'Твоя Привелегия'!G39,'Исеть Парк'!G39,'Космонавтов 11'!G39,'Утес'!G39) | H39: =SUM('Астон.Движение'!H39,'Астон.Реформа'!H39,'Дом Милый Дом'!H39,'River Park'!H39,'Астрид'!H39,'Живи в Курортном'!H39,'Новое Колпино'!H39,'Таллинский парк'!H39,'Твоя Привелегия'!H39,'Исеть Парк'!H39,'Космонавтов 11'!H39,'Утес'!H39) | I39: =SUM('Астон.Движение'!I39,'Астон.Реформа'!I39,'Дом Милый Дом'!I39,'River Park'!I39,'Астрид'!I39,'Живи в Курортном'!I39,'Новое Колпино'!I39,'Таллинский парк'!I39,'Твоя Привелегия'!I39,'Исеть Парк'!I39,'Космонавтов 11'!I39,'Утес'!I39)
A40: Приобритение мебели, бытовой техники | B40: =SUM('Астон.Движение'!B40,'Астон.Реформа'!B40,'Дом Милый Дом'!B40,'River Park'!B40,'Астрид'!B40,'Живи в Курортном'!B40,'Новое Колпино'!B40,'Таллинский парк'!B40,'Твоя Привелегия'!B40,'Исеть Парк'!B40,'Космонавтов 11'!B40,'Утес'!B40) | C40: =SUM('Астон.Движение'!C40,'Астон.Реформа'!C40,'Дом Милый Дом'!C40,'River Park'!C40,'Астрид'!C40,'Живи в Курортном'!C40,'Новое Колпино'!C40,'Таллинский парк'!C40,'Твоя Привелегия'!C40,'Исеть Парк'!C40,'Космонавтов 11'!C40,'Утес'!C40) | D40: =SUM('Астон.Движение'!D40,'Астон.Реформа'!D40,'Дом Милый Дом'!D40,'River Park'!D40,'Астрид'!D40,'Живи в Курортном'!D40,'Новое Колпино'!D40,'Таллинский парк'!D40,'Твоя Привелегия'!D40,'Исеть Парк'!D40,'Космонавтов 11'!D40,'Утес'!D40) | E40: =SUM('Астон.Движение'!E40,'Астон.Реформа'!E40,'Дом Милый Дом'!E40,'River Park'!E40,'Астрид'!E40,'Живи в Курортном'!E40,'Новое Колпино'!E40,'Таллинский парк'!E40,'Твоя Привелегия'!E40,'Исеть Парк'!E40,'Космонавтов 11'!E40,'Утес'!E40) | F40: =SUM('Астон.Движение'!F40,'Астон.Реформа'!F40,'Дом Милый Дом'!F40,'River Park'!F40,'Астрид'!F40,'Живи в Курортном'!F40,'Новое Колпино'!F40,'Таллинский парк'!F40,'Твоя Привелегия'!F40,'Исеть Парк'!F40,'Космонавтов 11'!F40,'Утес'!F40) | G40: =SUM('Астон.Движение'!G40,'Астон.Реформа'!G40,'Дом Милый Дом'!G40,'River Park'!G40,'Астрид'!G40,'Живи в Курортном'!G40,'Новое Колпино'!G40,'Таллинский парк'!G40,'Твоя Привелегия'!G40,'Исеть Парк'!G40,'Космонавтов 11'!G40,'Утес'!G40) | H40: =SUM('Астон.Движение'!H40,'Астон.Реформа'!H40,'Дом Милый Дом'!H40,'River Park'!H40,'Астрид'!H40,'Живи в Курортном'!H40,'Новое Колпино'!H40,'Таллинский парк'!H40,'Твоя Привелегия'!H40,'Исеть Парк'!H40,'Космонавтов 11'!H40,'Утес'!H40) | I40: =SUM('Астон.Движение'!I40,'Астон.Реформа'!I40,'Дом Милый Дом'!I40,'River Park'!I40,'Астрид'!I40,'Живи в Курортном'!I40,'Новое Колпино'!I40,'Таллинский парк'!I40,'Твоя Привелегия'!I40,'Исеть Парк'!I40,'Космонавтов 11'!I40,'Утес'!I40)
A41: Комиссия за перевод ЗП | B41: =SUM('Астон.Движение'!B41,'Астон.Реформа'!B41,'Дом Милый Дом'!B41,'River Park'!B41,'Астрид'!B41,'Живи в Курортном'!B41,'Новое Колпино'!B41,'Таллинский парк'!B41,'Твоя Привелегия'!B41,'Исеть Парк'!B41,'Космонавтов 11'!B41,'Утес'!B41) | C41: =SUM('Астон.Движение'!C41,'Астон.Реформа'!C41,'Дом Милый Дом'!C41,'River Park'!C41,'Астрид'!C41,'Живи в Курортном'!C41,'Новое Колпино'!C41,'Таллинский парк'!C41,'Твоя Привелегия'!C41,'Исеть Парк'!C41,'Космонавтов 11'!C41,'Утес'!C41) | D41: =SUM('Астон.Движение'!D41,'Астон.Реформа'!D41,'Дом Милый Дом'!D41,'River Park'!D41,'Астрид'!D41,'Живи в Курортном'!D41,'Новое Колпино'!D41,'Таллинский парк'!D41,'Твоя Привелегия'!D41,'Исеть Парк'!D41,'Космонавтов 11'!D41,'Утес'!D41) | E41: =SUM('Астон.Движение'!E41,'Астон.Реформа'!E41,'Дом Милый Дом'!E41,'River Park'!E41,'Астрид'!E41,'Живи в Курортном'!E41,'Новое Колпино'!E41,'Таллинский парк'!E41,'Твоя Привелегия'!E41,'Исеть Парк'!E41,'Космонавтов 11'!E41,'Утес'!E41) | F41: =SUM('Астон.Движение'!F41,'Астон.Реформа'!F41,'Дом Милый Дом'!F41,'River Park'!F41,'Астрид'!F41,'Живи в Курортном'!F41,'Новое Колпино'!F41,'Таллинский парк'!F41,'Твоя Привелегия'!F41,'Исеть Парк'!F41,'Космонавтов 11'!F41,'Утес'!F41) | G41: =SUM('Астон.Движение'!G41,'Астон.Реформа'!G41,'Дом Милый Дом'!G41,'River Park'!G41,'Астрид'!G41,'Живи в Курортном'!G41,'Новое Колпино'!G41,'Таллинский парк'!G41,'Твоя Привелегия'!G41,'Исеть Парк'!G41,'Космонавтов 11'!G41,'Утес'!G41) | H41: =SUM('Астон.Движение'!H41,'Астон.Реформа'!H41,'Дом Милый Дом'!H41,'River Park'!H41,'Астрид'!H41,'Живи в Курортном'!H41,'Новое Колпино'!H41,'Таллинский парк'!H41,'Твоя Привелегия'!H41,'Исеть Парк'!H41,'Космонавтов 11'!H41,'Утес'!H41) | I41: =SUM('Астон.Движение'!I41,'Астон.Реформа'!I41,'Дом Милый Дом'!I41,'River Park'!I41,'Астрид'!I41,'Живи в Курортном'!I41,'Новое Колпино'!I41,'Таллинский парк'!I41,'Твоя Привелегия'!I41,'Исеть Парк'!I41,'Космонавтов 11'!I41,'Утес'!I41)
A42: Аренда квартиры (включая коммуналку) | B42: =SUM('Астон.Движение'!B42,'Астон.Реформа'!B42,'Дом Милый Дом'!B42,'River Park'!B42,'Астрид'!B42,'Живи в Курортном'!B42,'Новое Колпино'!B42,'Таллинский парк'!B42,'Твоя Привелегия'!B42,'Исеть Парк'!B42,'Космонавтов 11'!B42,'Утес'!B42) | C42: =SUM('Астон.Движение'!C42,'Астон.Реформа'!C42,'Дом Милый Дом'!C42,'River Park'!C42,'Астрид'!C42,'Живи в Курортном'!C42,'Новое Колпино'!C42,'Таллинский парк'!C42,'Твоя Привелегия'!C42,'Исеть Парк'!C42,'Космонавтов 11'!C42,'Утес'!C42) | D42: =SUM('Астон.Движение'!D42,'Астон.Реформа'!D42,'Дом Милый Дом'!D42,'River Park'!D42,'Астрид'!D42,'Живи в Курортном'!D42,'Новое Колпино'!D42,'Таллинский парк'!D42,'Твоя Привелегия'!D42,'Исеть Парк'!D42,'Космонавтов 11'!D42,'Утес'!D42) | E42: =SUM('Астон.Движение'!E42,'Астон.Реформа'!E42,'Дом Милый Дом'!E42,'River Park'!E42,'Астрид'!E42,'Живи в Курортном'!E42,'Новое Колпино'!E42,'Таллинский парк'!E42,'Твоя Привелегия'!E42,'Исеть Парк'!E42,'Космонавтов 11'!E42,'Утес'!E42) | F42: =SUM('Астон.Движение'!F42,'Астон.Реформа'!F42,'Дом Милый Дом'!F42,'River Park'!F42,'Астрид'!F42,'Живи в Курортном'!F42,'Новое Колпино'!F42,'Таллинский парк'!F42,'Твоя Привелегия'!F42,'Исеть Парк'!F42,'Космонавтов 11'!F42,'Утес'!F42) | G42: =SUM('Астон.Движение'!G42,'Астон.Реформа'!G42,'Дом Милый Дом'!G42,'River Park'!G42,'Астрид'!G42,'Живи в Курортном'!G42,'Новое Колпино'!G42,'Таллинский парк'!G42,'Твоя Привелегия'!G42,'Исеть Парк'!G42,'Космонавтов 11'!G42,'Утес'!G42) | H42: =SUM('Астон.Движение'!H42,'Астон.Реформа'!H42,'Дом Милый Дом'!H42,'River Park'!H42,'Астрид'!H42,'Живи в Курортном'!H42,'Новое Колпино'!H42,'Таллинский парк'!H42,'Твоя Привелегия'!H42,'Исеть Парк'!H42,'Космонавтов 11'!H42,'Утес'!H42) | I42: =SUM('Астон.Движение'!I42,'Астон.Реформа'!I42,'Дом Милый Дом'!I42,'River Park'!I42,'Астрид'!I42,'Живи в Курортном'!I42,'Новое Колпино'!I42,'Таллинский парк'!I42,'Твоя Привелегия'!I42,'Исеть Парк'!I42,'Космонавтов 11'!I42,'Утес'!I42)
A43: Валовая прибыль | B43: =B4-B10 | C43: =C4-C10 | D43: =D4-D10 | E43: =E4-E10 | F43: =F4-F10 | G43: =G4-G10 | H43: =H4-H10 | I43: =I4-I10
A44: Валовая рентабельность | B44: =IFERROR(IF(B4=0,"-",B43/B4),"-") | C44: =IFERROR(IF(C4=0,"-",C43/C4),"-") | D44: =IFERROR(IF(D4=0,"-",D43/D4),"-") | E44: =IFERROR(IF(E4=0,"-",E43/E4),"-") | F44: =IFERROR(IF(F4=0,"-",F43/F4),"-") | G44: =IFERROR(IF(G4=0,"-",G43/G4),"-") | H44: =IFERROR(IF(H4=0,"-",H43/H4),"-") | I44: =IFERROR(IF(I4=0,"-",I43/I4),"-")
A45: Косвенные расходы | B45: =SUM(B46,B47,B48,B52,B56,B57,B58,B59,B60,B63,B64,B65,B66,B67,B68,B69,B70,B71,B72,B73,B74,B75,B76,B77,B78,B79) | C45: =SUM(C46,C47,C48,C52,C56,C57,C58,C59,C60,C63,C64,C65,C66,C67,C68,C69,C70,C71,C72,C73,C74,C75,C76,C77,C78,C79) | D45: =SUM(D46,D47,D48,D52,D56,D57,D58,D59,D60,D63,D64,D65,D66,D67,D68,D69,D70,D71,D72,D73,D74,D75,D76,D77,D78,D79) | E45: =SUM(E46,E47,E48,E52,E56,E57,E58,E59,E60,E63,E64,E65,E66,E67,E68,E69,E70,E71,E72,E73,E74,E75,E76,E77,E78,E79) | F45: =SUM(F46,F47,F48,F52,F56,F57,F58,F59,F60,F63,F64,F65,F66,F67,F68,F69,F70,F71,F72,F73,F74,F75,F76,F77,F78,F79) | G45: =SUM(G46,G47,G48,G52,G56,G57,G58,G59,G60,G63,G64,G65,G66,G67,G68,G69,G70,G71,G72,G73,G74,G75,G76,G77,G78,G79) | H45: =SUM(H46,H47,H48,H52,H56,H57,H58,H59,H60,H63,H64,H65,H66,H67,H68,H69,H70,H71,H72,H73,H74,H75,H76,H77,H78,H79) | I45: =SUM(I46,I47,I48,I52,I56,I57,I58,I59,I60,I63,I64,I65,I66,I67,I68,I69,I70,I71,I72,I73,I74,I75,I76,I77,I78,I79)
A46: Расход БЭК-ОФИС | B46: =SUM('Астон.Движение'!B46,'Астон.Реформа'!B46,'Дом Милый Дом'!B46,'River Park'!B46,'Астрид'!B46,'Живи в Курортном'!B46,'Новое Колпино'!B46,'Таллинский парк'!B46,'Твоя Привелегия'!B46,'Исеть Парк'!B46,'Космонавтов 11'!B46,'Утес'!B46) | C46: =SUM('Астон.Движение'!C46,'Астон.Реформа'!C46,'Дом Милый Дом'!C46,'River Park'!C46,'Астрид'!C46,'Живи в Курортном'!C46,'Новое Колпино'!C46,'Таллинский парк'!C46,'Твоя Привелегия'!C46,'Исеть Парк'!C46,'Космонавтов 11'!C46,'Утес'!C46) | D46: =SUM('Астон.Движение'!D46,'Астон.Реформа'!D46,'Дом Милый Дом'!D46,'River Park'!D46,'Астрид'!D46,'Живи в Курортном'!D46,'Новое Колпино'!D46,'Таллинский парк'!D46,'Твоя Привелегия'!D46,'Исеть Парк'!D46,'Космонавтов 11'!D46,'Утес'!D46) | E46: =SUM('Астон.Движение'!E46,'Астон.Реформа'!E46,'Дом Милый Дом'!E46,'River Park'!E46,'Астрид'!E46,'Живи в Курортном'!E46,'Новое Колпино'!E46,'Таллинский парк'!E46,'Твоя Привелегия'!E46,'Исеть Парк'!E46,'Космонавтов 11'!E46,'Утес'!E46) | F46: =SUM('Астон.Движение'!F46,'Астон.Реформа'!F46,'Дом Милый Дом'!F46,'River Park'!F46,'Астрид'!F46,'Живи в Курортном'!F46,'Новое Колпино'!F46,'Таллинский парк'!F46,'Твоя Привелегия'!F46,'Исеть Парк'!F46,'Космонавтов 11'!F46,'Утес'!F46) | G46: =SUM('Астон.Движение'!G46,'Астон.Реформа'!G46,'Дом Милый Дом'!G46,'River Park'!G46,'Астрид'!G46,'Живи в Курортном'!G46,'Новое Колпино'!G46,'Таллинский парк'!G46,'Твоя Привелегия'!G46,'Исеть Парк'!G46,'Космонавтов 11'!G46,'Утес'!G46) | H46: =SUM('Астон.Движение'!H46,'Астон.Реформа'!H46,'Дом Милый Дом'!H46,'River Park'!H46,'Астрид'!H46,'Живи в Курортном'!H46,'Новое Колпино'!H46,'Таллинский парк'!H46,'Твоя Привелегия'!H46,'Исеть Парк'!H46,'Космонавтов 11'!H46,'Утес'!H46) | I46: =SUM('Астон.Движение'!I46,'Астон.Реформа'!I46,'Дом Милый Дом'!I46,'River Park'!I46,'Астрид'!I46,'Живи в Курортном'!I46,'Новое Колпино'!I46,'Таллинский парк'!I46,'Твоя Привелегия'!I46,'Исеть Парк'!I46,'Космонавтов 11'!I46,'Утес'!I46)
A47: Расходы на бэк-офис | B47: =SUM('Астон.Движение'!B47,'Астон.Реформа'!B47,'Дом Милый Дом'!B47,'River Park'!B47,'Астрид'!B47,'Живи в Курортном'!B47,'Новое Колпино'!B47,'Таллинский парк'!B47,'Твоя Привелегия'!B47,'Исеть Парк'!B47,'Космонавтов 11'!B47,'Утес'!B47) | C47: =SUM('Астон.Движение'!C47,'Астон.Реформа'!C47,'Дом Милый Дом'!C47,'River Park'!C47,'Астрид'!C47,'Живи в Курортном'!C47,'Новое Колпино'!C47,'Таллинский парк'!C47,'Твоя Привелегия'!C47,'Исеть Парк'!C47,'Космонавтов 11'!C47,'Утес'!C47) | D47: =SUM('Астон.Движение'!D47,'Астон.Реформа'!D47,'Дом Милый Дом'!D47,'River Park'!D47,'Астрид'!D47,'Живи в Курортном'!D47,'Новое Колпино'!D47,'Таллинский парк'!D47,'Твоя Привелегия'!D47,'Исеть Парк'!D47,'Космонавтов 11'!D47,'Утес'!D47) | E47: =SUM('Астон.Движение'!E47,'Астон.Реформа'!E47,'Дом Милый Дом'!E47,'River Park'!E47,'Астрид'!E47,'Живи в Курортном'!E47,'Новое Колпино'!E47,'Таллинский парк'!E47,'Твоя Привелегия'!E47,'Исеть Парк'!E47,'Космонавтов 11'!E47,'Утес'!E47) | F47: =SUM('Астон.Движение'!F47,'Астон.Реформа'!F47,'Дом Милый Дом'!F47,'River Park'!F47,'Астрид'!F47,'Живи в Курортном'!F47,'Новое Колпино'!F47,'Таллинский парк'!F47,'Твоя Привелегия'!F47,'Исеть Парк'!F47,'Космонавтов 11'!F47,'Утес'!F47) | G47: =SUM('Астон.Движение'!G47,'Астон.Реформа'!G47,'Дом Милый Дом'!G47,'River Park'!G47,'Астрид'!G47,'Живи в Курортном'!G47,'Новое Колпино'!G47,'Таллинский парк'!G47,'Твоя Привелегия'!G47,'Исеть Парк'!G47,'Космонавтов 11'!G47,'Утес'!G47) | H47: =SUM('Астон.Движение'!H47,'Астон.Реформа'!H47,'Дом Милый Дом'!H47,'River Park'!H47,'Астрид'!H47,'Живи в Курортном'!H47,'Новое Колпино'!H47,'Таллинский парк'!H47,'Твоя Привелегия'!H47,'Исеть Парк'!H47,'Космонавтов 11'!H47,'Утес'!H47) | I47: =SUM('Астон.Движение'!I47,'Астон.Реформа'!I47,'Дом Милый Дом'!I47,'River Park'!I47,'Астрид'!I47,'Живи в Курортном'!I47,'Новое Колпино'!I47,'Таллинский парк'!I47,'Твоя Привелегия'!I47,'Исеть Парк'!I47,'Космонавтов 11'!I47,'Утес'!I47)
...

Sheet Астон.Движение
A1: ПланФакт | B1: Создано с помощью сервиса ПланФакт | I1: =HYPERLINK("https://app.planfact.io/?from=Pf_BDR", "Перейти в сервис")
